Workbook

Sheet Общая смета
B1: ПРЕДВАРИТЕЛЬНАЯ ОЦЕНКА ТРУДОЗАТРАТ НА P2P ПЛАТФОРМУ
A2: # | B2: Команда | C2: Кол-во | D2: Рейт ($/Ч) | E2: О. Часы | F2: П. Часы | G2: О. Цена | H2: П. Цена
A3: 1 | B3: DevOps | C3: 1 | D3: 60 | E3: ='DevOps'!E3 | F3: ='DevOps'!F3 | G3: ='DevOps'!G3 | H3: ='DevOps'!H3
A4: 2 | B4: Смарт-контракты | C4: 1 | D4: 50 | E4: ='Смарт контракты'!E3 | F4: ='Смарт контракты'!F3 | G4: ='Смарт контракты'!G3 | H4: ='Смарт контракты'!H3
A5: 3 | B5: Бэкенд-разработка | C5: 2 | D5: 42-62 | E5: ='Бэкенд'!E3 | F5: ='Бэкенд'!F3 | G5: ='Бэкенд'!G3 | H5: ='Бэкенд'!H3
A6: 4 | B6: Фронтенд-разработка | C6: 1 | D6: 40 | E6: ='Фронтенд'!E3 | F6: ='Фронтенд'!F3 | G6: ='Фронтенд'!G3 | H6: ='Фронтенд'!H3
A7: 5 | B7: Контроль качества (QA) | C7: 1 | D7: 30 | E7: ='QA'!E3 | F7: ='QA'!F3 | G7: ='QA'!G3 | H7: ='QA'!H3
A8: 6 | B8: UX/UI Аналитик | C8: 1 | D8: 40 | E8: ='Аналитик'!E3 | F8: ='Аналитик'!F3 | G8: ='Аналитик'!G3 | H8: ='Аналитик'!H3
A9: 7 | B9: Менеджмент | C9: 1 | D9: 30 | E9: ='Менеджмент'!E3 | F9: ='Менеджмент'!F3 | G9: ='Менеджмент'!G3 | H9: ='Менеджмент'!H3
A11: СТОИМОСТЬ РАБОТ | E11: =SUM(E3:E9) | F11: =SUM(F3:F9) | G11: =SUM(G3:G9) | H11: =SUM(H3:H9)
A13: Оценка действительна в течение 30 дней (до 01-05-2026). | E13: ПРИБЛ. ЦЕНА: | G13: =G11 | H13: =H11

Sheet DevOps
B1: ПРЕДВАРИТЕЛЬНАЯ ОЦЕНКА ТРУДОЗАТРАТ НА P2P ПЛАТФОРМУ
A2: # | B2: СПИСОК ЗАДАЧ | C2: Рейт ($/Ч) | D2: Фаза | E2: О. Часы | F2: П. Часы | G2: О. Цена | H2: П. Цена
B3: DevOps | C3: 60 | E3: =SUM(E4:E12) | F3: =SUM(F4:F12) | G3: =SUM(G4:G12) | H3: =SUM(H4:H12)
A4: 1.1 | B4: DevOps: Инфраструктура
A5: 1.1.1 | B5: Создание и настройка репозиториев - Backend, Frontend, Contracts — структура, README, права доступа | D5: DEVELOPMENT | E5: 4 | F5: 8 | G5: =E5*$C$3 | H5: =F5*$C$3
A6: 1.1.2 | B6: Настройка CI/CD pipelines - Сборка, линтинг, тесты, деплой для всех репозиториев | D6: DEVELOPMENT | E6: 8 | F6: 16 | G6: =E6*$C$3 | H6: =F6*$C$3
A7: 1.1.3 | B7: Настройка PostgreSQL - Установка, конфигурация, резервное копирование | D7: DEVELOPMENT | E7: 8 | F7: 16 | G7: =E7*$C$3 | H7: =F7*$C$3
A8: 1.1.4 | B8: Настройка Redis - Кэш, очереди, сессии | D8: DEVELOPMENT | E8: 8 | F8: 16 | G8: =E8*$C$3 | H8: =F8*$C$3
A9: 1.1.5 | B9: Настройка HashiCorp Vault - Хранение секретов, ключей шифрования | D9: DEVELOPMENT | E9: 8 | F9: 16 | G9: =E9*$C$3 | H9: =F9*$C$3
A10: 1.1.6 | B10: Настройка Nginx и доменов - Reverse proxy, SSL, rate limiting, DNS | D10: DEVELOPMENT | E10: 16 | F10: 24 | G10: =E10*$C$3 | H10: =F10*$C$3
A11: 1.1.7 | B11: Настройка мониторинга и алертинга - Prometheus, Grafana, PagerDuty/Slack интеграция | D11: DEVELOPMENT | E11: 16 | F11: 24 | G11: =E11*$C$3 | H11: =F11*$C$3
A12: 1.1.8 | B12: Настройка централизованного логирования | D12: DEVELOPMENT | E12: 16 | F12: 16 | G12: =E12*$C$3 | H12: =F12*$C$3

Sheet Смарт контракты
B1: ПРЕДВАРИТЕЛЬНАЯ ОЦЕНКА ТРУДОЗАТРАТ НА P2P ПЛАТФОРМУ
A2: # | B2: СПИСОК ЗАДАЧ | C2: Рейт ($/Ч) | D2: Фаза | E2: О. Часы | F2: П. Часы | G2: О. Цена | H2: П. Цена
B3: Смарт контракты | C3: 50 | E3: =SUM(E4:E10) | F3: =SUM(F4:F10) | G3: =SUM(G4:G10) | H3: =SUM(H4:H10)
A4: 2.1 | B4: Смарт-контракты
A5: 2.1.1 | B5: Разработка EscrowFactory - Создание прокси-контрактов, события, access control | D5: DEVELOPMENT | E5: 8 | F5: 12 | G5: =E5*$C$3 | H5: =F5*$C$3
A6: 2.1.2 | B6: Разработка Escrow Implementation - Логика депозита, релиза, refund, referral link, resolveDispute, интеграция USDT | D6: DEVELOPMENT | E6: 16 | F6: 24 | G6: =E6*$C$3 | H6: =F6*$C$3
A7: 2.1.3 | B7: Написание unit и integration тестов - Покрытие всех функций, happy path, edge cases, gas optimization | D7: DEVELOPMENT | E7: 12 | F7: 20 | G7: =E7*$C$3 | H7: =F7*$C$3
A8: 2.1.4 | B8: Деплой в testnet (Sepolia) - Factory + Implementation, верификация в Etherscan | D8: DEVELOPMENT | E8: 4 | F8: 4 | G8: =E8*$C$3 | H8: =F8*$C$3
A9: 2.1.5 | B9: Деплой в mainnet - Factory + Implementation, настройка мультисиг/Fireblocks | D9: DEVELOPMENT | E9: 16 | F9: 16 | G9: =E9*$C$3 | H9: =F9*$C$3
A10: 2.1.6 | B10: Аудит безопасности - Внешний аудит, исправление найденных проблем | D10: DEVELOPMENT | E10: 8 | F10: 8 | G10: =E10*$C$3 | H10: =F10*$C$3

Sheet Бэкенд
B1: ПРЕДВАРИТЕЛЬНАЯ ОЦЕНКА ТРУДОЗАТРАТ НА P2P ПЛАТФОРМУ
A2: # | B2: СПИСОК ЗАДАЧ | C2: Рейт ($/Ч) | D2: Фаза | E2: О. Часы | F2: П. Часы | G2: О. Цена | H2: П. Цена
B3: Бэкенд | E3: =SUM(E4:E46) | F3: =SUM(F4:F46) | G3: =SUM(G4:G46) | H3: =SUM(H4:H46)
A4: 3.1 | B4: Backend (Monolith): Инициализация NestJS проекта
A5: 3.1.1 | B5: Настройка инфраструктуры - TypeORM (PostgreSQL), Redis, Bull Queue, валидация | C5: 62 | D5: DEVELOPMENT | E5: 16 | F5: 24 | G5: =E5*C5 | H5: =F5*C5
A6: 3.1.2 | B6: Разработка Shared Layer - Database Service, Cache Service, Queue Service, Auth Service | C6: 62 | D6: DEVELOPMENT | E6: 20 | F6: 28 | G6: =E6*C6 | H6: =F6*C6
A7: 3.1.3 | B7: Разработка Blockchain Service - Ethers.js интеграция, RPC, индексатор событий | C7: 62 | D7: DEVELOPMENT | E7: 16 | F7: 24 | G7: =E7*C7 | H7: =F7*C7
A8: 3.1.4 | B8: Разработка Encryption Service - AES-256 для шифрования реквизитов | C8: 62 | D8: DEVELOPMENT | E8: 8 | F8: 16 | G8: =E8*C8 | H8: =F8*C8
A9: 3.2 | B9: Backend (Monolith): User Module
A10: 3.2.1 | B10: Создание сущностей - User (с полями реферальной программы: referrer_id, referrer_wallet, referral_code), Wallet, KycStatus, UserLevel — таблицы, связи, индексы | C10: 42 | D10: DEVELOPMENT | E10: 12 | F10: 20 | G10: =E10*C10 | H10: =F10*C10
A11: 3.2.2 | B11: Разработка API - Регистрация, авторизация (Web3 + JWT), профиль, привязка кошелька | C11: 42 | D11: DEVELOPMENT | E11: 20 | F11: 28 | G11: =E11*C11 | H11: =F11*C11
A12: 3.2.3 | B12: Реализация уровней доступа - Проверка прав, лимиты | C12: 42 | D12: DEVELOPMENT | E12: 16 | F12: 24 | G12: =E12*C12 | H12: =F12*C12
A13: 3.3 | B13: Backend (Monolith): Trading Module
A14: 3.3.1 | B14: Создание сущностей - Order, Deal, EscrowContract — таблицы, связи | C14: 62 | D14: DEVELOPMENT | E14: 8 | F14: 16 | G14: =E14*C14 | H14: =F14*C14
A15: 3.3.2 | B15: Разработка Order API - CRUD ордеров, стакан, фильтрация, WebSocket для real-time | C15: 62 | D15: DEVELOPMENT | E15: 24 | F15: 40 | G15: =E15*C15 | H15: =F15*C15
A16: 3.3.3 | B16: Разработка Deal API - Инициация, деплой эскроу, обработка депозита, подтверждения | C16: 62 | D16: DEVELOPMENT | E16: 24 | F16: 40 | G16: =E16*C16 | H16: =F16*C16
A17: 3.3.4 | B17: Реализация жизненного цикла сделки - Таймауты, авто-отмена, релиз, комиссия | C17: 62 | D17: DEVELOPMENT | E17: 24 | F17: 40 | G17: =E17*C17 | H17: =F17*C17
A18: 3.3.5 | B18: Реализация режима "Яма" - Переговорные сделки, фиксация курса | C18: 62 | D18: DEVELOPMENT | E18: 24 | F18: 40 | G18: =E18*C18 | H18: =F18*C18
A19: 3.4 | B19: Backend (Monolith): Payment Module
A20: 3.4.1 | B20: Создание сущности PaymentDetails - Таблица, шифрование | C20: 62 | D20: DEVELOPMENT | E20: 4 | F20: 8 | G20: =E20*C20 | H20: =F20*C20
A21: 3.4.2 | B21: Разработка API - CRUD реквизитов, передача в сделке после депозита | C21: 62 | D21: DEVELOPMENT | E21: 8 | F21: 8 | G21: =E21*C21 | H21: =F21*C21
A22: 3.5 | B22: Backend (Monolith): Dispute Module
A23: 3.5.1 | B23: Создание сущностей - Dispute — таблицы, статусы | C23: 42 | D23: DEVELOPMENT | E23: 8 | F23: 8 | G23: =E23*C23 | H23: =F23*C23
A24: 3.5.2 | B24: Разработка API - Создание диспута, добавление доказательств, продление блокировки | C24: 42 | D24: DEVELOPMENT | E24: 16 | F24: 24 | G24: =E24*C24 | H24: =F24*C24
A25: 3.5.3 | B25: Разработка Admin API - Список диспутов, просмотр, принятие решения, вызов resolveDispute | C25: 42 | D25: DEVELOPMENT | E25: 16 | F25: 24 | G25: =E25*C25 | H25: =F25*C25
A26: 3.6 | B26: Backend (Monolith): rating Module
A27: 3.6.1 | B27: Создание сущностей - Rating, RatingHistory | C27: 42 | D27: DEVELOPMENT | E27: 8 | F27: 8 | G27: =E27*C27 | H27: =F27*C27
A28: 3.6.2 | B28: Разработка Rating Service - Расчет рейтинга (сделки, отмены, диспуты, объем) | C28: 42 | D28: DEVELOPMENT | E28: 12 | F28: 12 | G28: =E28*C28 | H28: =F28*C28
A29: 3.7 | B29: Backend (Monolith): Analytics Module
A30: 3.7.1 | B30: Подключение стороннего сервиса аналитики - Redash или др | C30: 42 | D30: DEVELOPMENT | E30: 4 | F30: 8 | G30: =E30*C30 | H30: =F30*C30
A31: 3.8 | B31: Backend (Monolith): Referral Module
A32: 3.8.1 | B32: API генерации реферальной ссылки - Уникальный код, URL | C32: 42 | D32: DEVELOPMENT | E32: 4 | F32: 8 | G32: =E32*C32 | H32: =F32*C32
A33: 3.8.2 | B33: API установки кошелька комиссий - Валидация адреса | C33: 42 | D33: DEVELOPMENT | E33: 4 | F33: 8 | G33: =E33*C33 | H33: =F33*C33
A34: 3.8.3 | B34: Привязка при регистрации - Парсинг ?ref=, сохранение referrer_id/wallet | C34: 42 | D34: DEVELOPMENT | E34: 4 | F34: 4 | G34: =E34*C34 | H34: =F34*C34
A35: 3.8.4 | B35: Интеграция со сделками - Получение referrer_wallet при создании сделки, передача в контракт | C35: 42 | D35: DEVELOPMENT | E35: 8 | F35: 16 | G35: =E35*C35 | H35: =F35*C35
A36: 3.8.5 | B36: Создание сущности ReferralReward - Хранение истории выплат | C36: 42 | D36: DEVELOPMENT | E36: 4 | F36: 8 | G36: =E36*C36 | H36: =F36*C36
A37: 3.8.6 | B37: API реферальной статистики - Кол-во рефералов, сделок, сумма выплат, список | C37: 42 | D37: DEVELOPMENT | E37: 8 | F37: 16 | G37: =E37*C37 | H37: =F37*C37
A38: 3.8.7 | B38: Обработка событий выплат - Обновление статистики при выплате из контракта | C38: 42 | D38: DEVELOPMENT | E38: 4 | F38: 12 | G38: =E38*C38 | H38: =F38*C38
A39: 3.9 | B39: Backend (Monolith): Миграции БД и документация
A40: 3.9.1 | B40: Создание миграций - Все таблицы с учетом реферальной программы: users (с полями referrer_id, referrer_wallet, referral_code), wallets, orders, deals, disputes, rating, referral_rewards и др. | C40: 62 | D40: DEVELOPMENT | E40: 16 | F40: 24 | G40: =E40*C40 | H40: =F40*C40
...

Sheet Фронтенд
B1: ПРЕДВАРИТЕЛЬНАЯ ОЦЕНКА ТРУДОЗАТРАТ НА P2P ПЛАТФОРМУ
A2: # | B2: СПИСОК ЗАДАЧ | C2: Рейт ($/Ч) | D2: Фаза | E2: О. Часы | F2: П. Часы | G2: О. Цена | H2: П. Цена
B3: Фронтенд | C3: 40 | E3: =SUM(E4:E35) | F3: =SUM(F4:F35) | G3: =SUM(G4:G35) | H3: =SUM(H4:H35)
A4: 4.1 | B4: Старт проекта
A5: 4.1.1 | B5: инициализация проекта - верстка | D5: DEVELOPMENT | E5: 28 | F5: 36 | G5: =E5*$C$3 | H5: =F5*$C$3
A6: 4.2 | B6: Rewards Module(Frontend): Referral Module
A7: 4.2.1 | B7: Раздел в ЛК - правки верстки | D7: DEVELOPMENT | E7: 8 | F7: 8 | G7: =E7*$C$3 | H7: =F7*$C$3
A8: 4.2.2 | B8: Таблица сделок - Таблица сделок рефералов, пагинация/фильтры | D8: DEVELOPMENT | E8: 8 | F8: 8 | G8: =E8*$C$3 | H8: =F8*$C$3
A9: 4.2.3 | B9: Интеграция API - Интеграция получения ссылки, интеграция сохранения кошелька, Интеграция статистики | D9: DEVELOPMENT | E9: 8 | F9: 16 | G9: =E9*$C$3 | H9: =F9*$C$3
A10: 4.3 | B10: Frontend: Страницы
A11: 4.3.1 | B11: Страница Авторизации - Подключение кошелька, подпись сообщения, JWT | D11: DEVELOPMENT | E11: 8 | F11: 16 | G11: =E11*$C$3 | H11: =F11*$C$3
A12: 4.3.2 | B12: Страница Профиля - Информация, KYC статус, кошельки, реквизиты, рейтинг, рефералы | D12: DEVELOPMENT | E12: 16 | F12: 24 | G12: =E12*$C$3 | H12: =F12*$C$3
A13: 4.3.3 | B13: Страница Стакана (Order Book) - Три колонки (Sell/Pit/Buy), фильтры, WebSocket, карточки ордеров | D13: DEVELOPMENT | E13: 32 | F13: 40 | G13: =E13*$C$3 | H13: =F13*$C$3
A14: 4.3.4 | B14: Страница Создания Ордера и управление объявлениями - Тип (FIXED/PIT), направление, валюта, сумма, цена, банки, реквизиты | D14: DEVELOPMENT | E14: 16 | F14: 24 | G14: =E14*$C$3 | H14: =F14*$C$3
A15: 4.3.5 | B15: Страница Сделки - Информационная панель, шаги, депозит, подтверждения, чат, диспут | D15: DEVELOPMENT | E15: 56 | F15: 64 | G15: =E15*$C$3 | H15: =F15*$C$3
A16: 4.3.6 | B16: Страница "Яма" (Pit) - Чат, предложение курса, принятие, фиксация | D16: DEVELOPMENT | E16: 8 | F16: 8 | G16: =E16*$C$3 | H16: =F16*$C$3
A17: 4.3.7 | B17: Страница Истории Сделок - Список, фильтры, детальная информация | D17: DEVELOPMENT | E17: 4 | F17: 8 | G17: =E17*$C$3 | H17: =F17*$C$3
A18: 4.4 | B18: Frontend: Админ-панель
A19: 4.4.1 | B19: Layout и Dashboard - Сайдбар, навигация, статистика, метрики | D19: DEVELOPMENT | E19: 24 | F19: 40 | G19: =E19*$C$3 | H19: =F19*$C$3
A20: 4.4.2 | B20: Управление пользователями - Список, фильтры, детали профиля, KYC, действия | D20: DEVELOPMENT | E20: 0 | F20: 0 | G20: =E20*$C$3 | H20: =F20*$C$3
A21: 4.4.3 | B21: Управление ордерами и сделками - Просмотр всех ордеров и сделок | D21: DEVELOPMENT | E21: 0 | F21: 0 | G21: =E21*$C$3 | H21: =F21*$C$3
A22: 4.4.4 | B22: Управление диспутами - Список, детали, доказательства, форма решения | D22: DEVELOPMENT | E22: 0 | F22: 0 | G22: =E22*$C$3 | H22: =F22*$C$3
A23: 4.4.5 | B23: Аналитика - Графики, отчеты | D23: DEVELOPMENT | E23: 8 | F23: 8 | G23: =E23*$C$3 | H23: =F23*$C$3
A24: 4.5 | B24: Frontend: Интеграция с API
A25: 4.5.1 | B25: Настройка API клиента - Axios/fetch wrapper, JWT, refresh token | D25: DEVELOPMENT | E25: 0 | F25: 0 | G25: =E25*$C$3 | H25: =F25*$C$3
A26: 4.5.2 | B26: Интеграция User API - Регистрация, профиль, кошельки | D26: DEVELOPMENT | E26: 0 | F26: 0 | G26: =E26*$C$3 | H26: =F26*$C$3
A27: 4.5.3 | B27: Интеграция Order API - CRUD ордеров, стакан | D27: DEVELOPMENT | E27: 0 | F27: 0 | G27: =E27*$C$3 | H27: =F27*$C$3
A28: 4.5.4 | B28: Интеграция Deal API - Жизненный цикл сделки | D28: DEVELOPMENT | E28: 0 | F28: 0 | G28: =E28*$C$3 | H28: =F28*$C$3
A29: 4.5.5 | B29: Интеграция Payment API - Реквизиты | D29: DEVELOPMENT | E29: 0 | F29: 0 | G29: =E29*$C$3 | H29: =F29*$C$3
A30: 4.5.6 | B30: Интеграция Dispute API - Диспуты | D30: DEVELOPMENT | E30: 0 | F30: 0 | G30: =E30*$C$3 | H30: =F30*$C$3
A31: 4.5.7 | B31: Интеграция Referral API - Стакан, уведомления, обработка ошибок | D31: DEVELOPMENT | E31: 0 | F31: 0 | G31: =E31*$C$3 | H31: =F31*$C$3
A32: 4.5.8 | B32: Интеграция WebSocket - Стакан, уведомления, обработка ошибок | D32: DEVELOPMENT | E32: 8 | F32: 16 | G32: =E32*$C$3 | H32: =F32*$C$3
A33: 4.6 | B33: Интеграции
A34: 4.6.1 | B34: KYC Интеграция - Изучение документации КУС | D34: DEVELOPMENT | E34: 8 | F34: 8 | G34: =E34*$C$3 | H34: =F34*$C$3
A35: 4.6.2 | B35: Чат Интеграция - Изучение документации чата | D35: DEVELOPMENT | E35: 8 | F35: 8 | G35: =E35*$C$3 | H35: =F35*$C$3

Sheet QA
B1: ПРЕДВАРИТЕЛЬНАЯ ОЦЕНКА ТРУДОЗАТРАТ НА P2P ПЛАТФОРМУ
A2: # | B2: СПИСОК ЗАДАЧ | C2: Рейт ($/Ч) | D2: Фаза | E2: О. Часы | F2: П. Часы | G2: О. Цена | H2: П. Цена
B3: QA | C3: 30 | E3: =SUM(E4:E7) | F3: =SUM(F4:F7) | G3: =SUM(G4:G7) | H3: =SUM(H4:H7)
A4: 5.1 | B4: Интеграции
A5: 5.1.1 | B5: Интеграционное тестирование - E2E: регистрация, создание ордера, сделка happy path, отмена, диспут, Pit на testnet | D5: DEVELOPMENT | E5: 120 | F5: 120 | G5: =E5*$C$3 | H5: =F5*$C$3
A6: 5.1.2 | B6: Тестирование безопасности - Авторизация, валидация, rate limiting, CORS, шифрование, пентест (опционально) | D6: DEVELOPMENT | E6: 0 | F6: 0 | G6: =E6*$C$3 | H6: =F6*$C$3
A7: 5.1.3 | B7: Багфикс и регрессия - Сбор, приоритизация, исправление P0/P1, регрессионное тестирование | D7: DEVELOPMENT | E7: 0 | F7: 0 | G7: =E7*$C$3 | H7: =F7*$C$3

Sheet Аналитик
B1: ПРЕДВАРИТЕЛЬНАЯ ОЦЕНКА ТРУДОЗАТРАТ НА P2P ПЛАТФОРМУ
A2: # | B2: СПИСОК ЗАДАЧ | C2: Рейт ($/Ч) | D2: Фаза | E2: О. Часы | F2: П. Часы | G2: О. Цена | H2: П. Цена
B3: Аналитик | C3: 40 | E3: =SUM(E4:E5) | F3: =SUM(F4:F5) | G3: =SUM(G4:G5) | H3: =SUM(H4:H5)
A4: 6.1 | B4: Интеграции
A5: 6.1.1 | B5: Сопровождение разработки, доработки UX/UI | D5: DEVELOPMENT | E5: 120 | F5: 120 | G5: =E5*$C$3 | H5: =F5*$C$3

Sheet Менеджмент
B1: ПРЕДВАРИТЕЛЬНАЯ ОЦЕНКА ТРУДОЗАТРАТ НА P2P ПЛАТФОРМУ
A2: # | B2: СПИСОК ЗАДАЧ | C2: Рейт ($/Ч) | D2: Фаза | E2: О. Часы | F2: П. Часы | G2: О. Цена | H2: П. Цена
B3: Менеджмент | C3: 30 | E3: =SUM(E4:E8) | F3: =SUM(F4:F8) | G3: =SUM(G4:G8) | H3: =SUM(H4:H8)
A4: 7.1 | B4: Планирование и проведение Kick-off - Внутреннее планирование, kick-off встреча с клиентом | D4: SPREAD | E4: 8 | F4: 16 | G4: =E4*$C$3 | H4: =F4*$C$3
A5: 7.2 | B5: Корректировка задач, распределение и контроль - Актуализация задач, назначение исполнителей, ежедневный контроль | D5: SPREAD | E5: 56 | F5: 64 | G5: =E5*$C$3 | H5: =F5*$C$3
A6: 7.3 | B6: Управление спринтом - Планирование спринта, стендапы, демо, ретроспектива | D6: SPREAD | E6: 40 | F6: 40 | G6: =E6*$C$3 | H6: =F6*$C$3
A7: 7.4 | B7: Подготовка и обмен отчетами - Формирование отчетов для клиентов, обсуждение | D7: SPREAD | E7: 16 | F7: 16 | G7: =E7*$C$3 | H7: =F7*$C$3
A8: 7.5 | B8: Общение с клиентом - Звонки, ежедневное общение по чатам | D8: SPREAD | E8: 16 | F8: 16 | G8: =E8*$C$3 | H8: =F8*$C$3
