Workbook

Sheet Для клиента
B5: Оценка проекта | D5: ='Sales (Итоги оценки)'!C4 -> P2P платформа
B6: В стоимость входит тестирование, работа менеджера
B7: В течение 3 месяцев мы бесплатно устраняем технические ошибки (техподдержка)
B8: Актуально на: 06.04.2026
B9: Команда проекта, человек | C9: Длительность проекта, часы | D9: Стоимость, $
B10: 8 | C10: 2182 | D10: 92367
B12: Специалисты | C12: Занятость на проекте, недели | D12: Занятость на проекте, часы
B13: Smart contract | C13: 3 | D13: 119
B14: Backend | C14: 10.2 | D14: 407
B15: Backend | C15: 10.9 | D15: 436
B16: Frontend | C16: 12.7 | D16: 509
B17: Project manager | C17: 3.8 | D17: 153
B18: DevOps | C18: 4.4 | D18: 176
B19: Аналитик | C19: 4.8 | D19: 193
B20: QA | C20: 4.8 | D20: 193
B23: DevOps
B24: Вид работ | C24: Задача | D24: Комментарий | E24: Длительность, часы
B25: DevOps | C25: Создание и настройка репозиториев | D25: Backend, Frontend, Contracts — структура, README, права доступа | E25: 10
B26: DevOps | C26: Настройка CI/CD pipelines | D26: Сборка, линтинг, тесты, деплой для всех репозиториев | E26: 20
B27: DevOps | C27: Настройка PostgreSQL | D27: Установка, конфигурация, резервное копирование | E27: 20
B28: DevOps | C28: Настройка Redis | D28: Кэш, очереди, сессии | E28: 20
B29: DevOps | C29: Настройка HashiCorp Vault | D29: Хранение секретов, ключей шифрования | E29: 20
B30: DevOps | C30: Настройка Nginx и доменов | D30: Reverse proxy, SSL, rate limiting, DNS | E30: 32
B31: DevOps | C31: Настройка мониторинга и алертинга | D31: Prometheus, Grafana, PagerDuty/Slack интеграция | E31: 32
B32: DevOps | C32: Настройка централизованного логирования | E32: 26
B34: Smart contract
B35: Вид работ | C35: Задача | D35: Комментарий | E35: Длительность, часы
B36: Smart contract | C36: Разработка EscrowFactory | D36: Создание прокси-контрактов, события, access control | E36: 16
B37: Smart contract | C37: Разработка Escrow Implementation | D37: Логика депозита, релиза, refund, referral link, resolveDispute, интеграция USDT | E37: 32
B38: Smart contract | C38: Написание unit и integration тестов | D38: Покрытие всех функций, happy path, edge cases, gas optimization | E38: 26
B39: Smart contract | C39: Деплой в testnet (Sepolia) | D39: Factory + Implementation, верификация в Etherscan | E39: 7
B40: Smart contract | C40: Деплой в mainnet | D40: Factory + Implementation, настройка мультисиг/Fireblocks | E40: 26
B41: Smart contract | C41: Аудит безопасности | D41: Внешний аудит, исправление найденных проблем | E41: 13
B43: Backend
B44: Вид работ | C44: Задача | D44: Комментарий | E44: Длительность, часы
B45: Backend | C45: Настройка инфраструктуры | D45: TypeORM (PostgreSQL), Redis, Bull Queue, валидация | E45: 32
B46: Backend | C46: Разработка Shared Layer | D46: Database Service, Cache Service, Queue Service, Auth Service | E46: 32
B47: Backend | C47: Разработка Blockchain Service | D47: Ethers.js интеграция, RPC, индексатор событий | E47: 32
B48: Backend | C48: Разработка Encryption Service | D48: AES-256 для шифрования реквизитов | E48: 20
B49: Backend | C49: Создание сущностей | D49: User (с полями реферальной программы: referrer_id, referrer_wallet, referral_code), Wallet, KycStatus, UserLevel — таблицы, связи, индексы | E49: 26
...

Sheet Sales (Итоги оценки)
B1: ⭠ Инструкция к заполнению (нажми "+")
B2: Sales 1. Заполняется Sales менеджером, после оценки проекта и настройки коэфицентов (делает PM). 2. Заполняются только ячейки закрашеные зеленым цветом. 3. Вноситься % реферальный по проекту, если такой есть. (% sales manager заложен в маржу проекта) 4. Вноситься маржа по каждому разработчику в столбце L. | F2: PM 1. Заполняет продолжительность проекта в ячейке С21 в соответсвии с предпологаемой продолжительностью работ на проекте. (Сколько проект будет длиться в фактических неделях) 2. Заполняет название проекта, ячейка С6. И прикладывает ссылки на маеты и тз (ячейки С7 и С8). 3. Схематично, на таймлайне, отрисовывает ход проекта в недельном выражении. Какие работы удит паралельно или последовательно. Учитывая прзаднечные, выходные, и отпуска.
B4: Проект: | C4: P2P платформа | E4: Проектная команда/тип работ: | F4: Продолжительность работ в неделях | G4: Продолжительность работ в днях | H4: Продолжительность работ в часах | I4: Себестоимость | J4: Стоимость работ | K4: Ставка на клиенте | L4: Ставка на руки | M4: Закладываемая маржа на разработчика (%)
B5: Ссылка на макеты | E5: Итого: | F5: =SUM(F6:F19) -> 54.536 | G5: =F5*5 -> 272.68 | H5: =G5*8 -> 2181.44 | I5: =SUM(I6:I19) -> 48875.2 | J5: =SUM(J6:J19) -> 92366.933 | M5: =((C9/(C14/100+1))-SUM(I6:I19))/(C9/(C14/100+1)) -> 0.47085826
B6: Ссылка на ТЗ
E7: ='PM (Расчеты)'!B6 -> Project manager | F7: ='PM (Расчеты)'!I6 -> 3.816 | G7: =F7*5 -> 19.08 | H7: =G7*8 -> 152.64 | I7: ='PM (Расчеты)'!J6 -> 2289.6 | J7: =('PM (Расчеты)'!J6/(1-M7)) -> 4579.2 | K7: ='PM (Расчеты)'!D6/(100%-M7) -> 30 | L7: ='PM (Расчеты)'!D6 -> 15 | M7: 0.5
B8: Стоимость проекта | E8: ='PM (Расчеты)'!B7 -> DevOps | F8: ='PM (Расчеты)'!I7 -> 4.4 | G8: =F8*5 -> 22 | H8: =G8*8 -> 176 | I8: ='PM (Расчеты)'!J7 -> 4400 | J8: =('PM (Расчеты)'!J7/(1-M8)) -> 8800 | K8: ='PM (Расчеты)'!D7/(100%-M8) -> 50 | L8: ='PM (Расчеты)'!D7 -> 25 | M8: 0.5
B9: Стоимость проекта: | C9: =SUM(J6:J19)*(C14/100+1) -> 92366.933 | E9: ='PM (Расчеты)'!B8 -> Smart contract | F9: ='PM (Расчеты)'!I8 -> 2.96 | G9: =F9*5 -> 14.8 | H9: =G9*8 -> 118.4 | I9: ='PM (Расчеты)'!J8 -> 3552 | J9: =('PM (Расчеты)'!J8/(1-M9)) -> 5920 | K9: ='PM (Расчеты)'!D8/(100%-M9) -> 50 | L9: ='PM (Расчеты)'!D8 -> 30 | M9: 0.4
B10: Маржинальность проекта: | C10: =M5 -> 0.47085826 | E10: ='PM (Расчеты)'!B9 -> Backend | F10: ='PM (Расчеты)'!I9 -> 10.16 | G10: =F10*5 -> 50.8 | H10: =G10*8 -> 406.4 | I10: ='PM (Расчеты)'!J9 -> 12598.4 | J10: =('PM (Расчеты)'!J9/(1-M10)) -> 20997.333 | K10: ='PM (Расчеты)'!D9/(100%-M10) -> 51.666667 | L10: ='PM (Расчеты)'!D9 -> 31 | M10: 0.4
E11: ='PM (Расчеты)'!B10 -> Backend | F11: ='PM (Расчеты)'!I10 -> 10.88 | G11: =F11*5 -> 54.4 | H11: =G11*8 -> 435.2 | I11: ='PM (Расчеты)'!J10 -> 9139.2 | J11: =('PM (Расчеты)'!J10/(1-M11)) -> 18278.4 | K11: ='PM (Расчеты)'!D10/(100%-M11) -> 42 | L11: ='PM (Расчеты)'!D10 -> 21 | M11: 0.5
E12: ='PM (Расчеты)'!B11 -> Frontend | F12: ='PM (Расчеты)'!I11 -> 12.72 | G12: =F12*5 -> 63.6 | H12: =G12*8 -> 508.8 | I12: ='PM (Расчеты)'!J11 -> 10176 | J12: =('PM (Расчеты)'!J11/(1-M12)) -> 20352 | K12: ='PM (Расчеты)'!D11/(100%-M12) -> 40 | L12: ='PM (Расчеты)'!D11 -> 20 | M12: 0.5
B13: % Sales | C13: Включен в маржу | E13: ='PM (Расчеты)'!B12 -> QA | F13: ='PM (Расчеты)'!I12 -> 4.8 | G13: =F13*5 -> 24 | H13: =G13*8 -> 192 | I13: ='PM (Расчеты)'!J12 -> 2880 | J13: =('PM (Расчеты)'!J12/(1-M13)) -> 5760 | K13: ='PM (Расчеты)'!D12/(100%-M13) -> 30 | L13: ='PM (Расчеты)'!D12 -> 15 | M13: 0.5
B14: % другое | C14: 0 | E14: Аналитик | F14: ='PM (Расчеты)'!I13 -> 4.8 | G14: =F14*5 -> 24 | H14: =G14*8 -> 192 | I14: ='PM (Расчеты)'!J13 -> 3840 | J14: =('PM (Расчеты)'!J13/(1-M14)) -> 7680 | K14: ='PM (Расчеты)'!D13/(100%-M14) -> 40 | L14: ='PM (Расчеты)'!D13 -> 20 | M14: 0.5
B16: Продолжительность раб. часов/дней/недель:
B17: Часов | C17: =H5 -> 2181.44
B18: Дней | C18: =C19*5 -> 5
B19: Недель | C19: 1
E21: Хронология проекта (необходимо учесть выходные, праздничные и отпуск) | F21: 1 неделя | G21: 5 недель | H21: 6 недель | I21: 7 недель | J21: 8 недель | M21: 9 недель
E22: Работы по дизайну:
E23: Работы по фронтенду:
E24: Работы по бекенду:
E25: Работы по смарт контрактам
E26: Работы менеджера:
E27: Работы тестировщика:

Sheet Оценка
B2: Инструкция к заполнению: 1. Задачи оцениваются в днях/полу днях. 2. Для каждого типа работ указывает этот тип работ в столбце B. 3. Для каждого типа работ на проекте проставляем кто будет выполнять эту работу в столбце А (специалист 1,2 и т.д.) 4. Если задача занимает больше 5 дней. Ее необходимо разделить на более мелкие подзадачи 5. Задачи по фронтенду должны сразу включать в себя работы по интеграции с бэкендом 6. При нажатии на "+" - раскрывается разбивка по выбранным специалистам. Сколько на каждого выделено время на проекте. Можно использовать для разбивки работ для команды. 7. Во вкладке "Чек лист Задач" - можно ознакомиться с типовыми задачами. О которых можно было забыть. Оценка производится в полу днях, а не в часах, в связи с тем, что между задачами происходит переключение. Меняется фокус и скорость работы. Человек не робот, не работает максимально эффективно над каждой задачей. Такой подход снижает нагрузку на команду и повышает точность планирования, так как легче учитывать погрешности в рамках дня, а не точного количества часов, которые могут варьироваться из-за перерывов или непредвиденных факторов.
A3: ⭠ Инструкция к заполнению (нажми "+")
B4: Дни минимум | C4: Дни максимум | D4: Недель с коф. | F4: Дни минимум | G4: Дни максимум | H4: Недель с коф.
A5: 1 | B5: =SUMPRODUCT(($A12:$A1002 = 1) * (F12:F1002) * IF(LEN('Оценка'!$E$12:$E1002) = 0, 1, IF('Оценка'!$E$12:$E1002 = 0, 1, 'Оценка'!$E$12:$E1002))) -> 10.5 | C5: =SUMPRODUCT(($A12:$A1002 = 1) * (G12:G1002) * IF(LEN('Оценка'!$E$12:$E1002) = 0, 1, IF('Оценка'!$E$12:$E1002 = 0, 1, 'Оценка'!$E$12:$E1002))) -> 17 | D5: ='PM (Расчеты)'!I7 -> 4.4 | E5: 7 | F5: =SUMPRODUCT(($A12:$A1002 = 7) * ('Оценка'!F12:F1002) * IF(LEN('Оценка'!$E$12:$E1002) = 0, 1, IF('Оценка'!$E$12:$E1002 = 0, 1, 'Оценка'!$E$12:$E1002))) -> 15 | G5: =SUMPRODUCT(($A12:$A1002 = 7) * ('Оценка'!G12:G1002) * IF(LEN('Оценка'!$E$12:$E1002) = 0, 1, IF('Оценка'!$E$12:$E1002 = 0, 1, 'Оценка'!$E$12:$E1002))) -> 15 | H5: ='PM (Расчеты)'!I13 -> 4.8
A6: 2 | B6: =SUMPRODUCT(($A12:$A1002 = 2) * ('Оценка'!F12:F1002) * IF(LEN('Оценка'!$E$12:$E1002) = 0, 1, IF('Оценка'!$E$12:$E1002 = 0, 1, 'Оценка'!$E$12:$E1002))) -> 8 | C6: =SUMPRODUCT(($A12:$A1002 = 2) * ('Оценка'!G12:G1002) * IF(LEN('Оценка'!$E$12:$E1002) = 0, 1, IF('Оценка'!$E$12:$E1002 = 0, 1, 'Оценка'!$E$12:$E1002))) -> 10.5 | D6: ='PM (Расчеты)'!I8 -> 2.96 | E6: 8 | F6: =SUMPRODUCT(($A12:$A1002 = 8) * ('Оценка'!F12:F1002) * IF(LEN('Оценка'!$E$12:$E1002) = 0, 1, IF('Оценка'!$E$12:$E1002 = 0, 1, 'Оценка'!$E$12:$E1002))) -> 0 | G6: =SUMPRODUCT(($A12:$A1002 = 8) * ('Оценка'!G12:G1002) * IF(LEN('Оценка'!$E$12:$E1002) = 0, 1, IF('Оценка'!$E$12:$E1002 = 0, 1, 'Оценка'!$E$12:$E1002))) -> 0 | H6: ='PM (Расчеты)'!I14 -> 0
A7: 3 | B7: =SUMPRODUCT(($A12:$A1002 = 3) * ('Оценка'!F12:F1002) * IF(LEN('Оценка'!$E$12:$E1002) = 0, 1, IF('Оценка'!$E$12:$E1002 = 0, 1, 'Оценка'!$E$12:$E1002))) -> 24.5 | C7: =SUMPRODUCT(($A12:$A1002 = 3) * ('Оценка'!G12:G1002) * IF(LEN('Оценка'!$E$12:$E1002) = 0, 1, IF('Оценка'!$E$12:$E1002 = 0, 1, 'Оценка'!$E$12:$E1002))) -> 39 | D7: ='PM (Расчеты)'!I9 -> 10.16 | E7: 9 | F7: =SUMPRODUCT(($A12:$A1002 = 9) * ('Оценка'!F12:F1002) * IF(LEN('Оценка'!$E$12:$E1002) = 0, 1, IF('Оценка'!$E$12:$E1002 = 0, 1, 'Оценка'!$E$12:$E1002))) -> 0 | G7: =SUMPRODUCT(($A12:$A1002 = 9) * ('Оценка'!G12:G1002) * IF(LEN('Оценка'!$E$12:$E1002) = 0, 1, IF('Оценка'!$E$12:$E1002 = 0, 1, 'Оценка'!$E$12:$E1002))) -> 0 | H7: ='PM (Расчеты)'!I15 -> 0
A8: 4 | B8: =SUMPRODUCT(($A12:$A1002 = 4) * ('Оценка'!F12:F1002) * IF(LEN('Оценка'!$E$12:$E1002) = 0, 1, IF('Оценка'!$E$12:$E1002 = 0, 1, 'Оценка'!$E$12:$E1002))) -> 26.5 | C8: =SUMPRODUCT(($A12:$A1002 = 4) * ('Оценка'!G12:G1002) * IF(LEN('Оценка'!$E$12:$E1002) = 0, 1, IF('Оценка'!$E$12:$E1002 = 0, 1, 'Оценка'!$E$12:$E1002))) -> 41.5 | D8: па | E8: 10 | F8: =SUMPRODUCT(($A12:$A1002 = 10) * ('Оценка'!F12:F1002) * IF(LEN('Оценка'!$E$12:$E1002) = 0, 1, IF('Оценка'!$E$12:$E1002 = 0, 1, 'Оценка'!$E$12:$E1002))) -> 0 | G8: =SUMPRODUCT(($A12:$A1002 = 10) * ('Оценка'!G12:G1002) * IF(LEN('Оценка'!$E$12:$E1002) = 0, 1, IF('Оценка'!$E$12:$E1002 = 0, 1, 'Оценка'!$E$12:$E1002))) -> 0 | H8: ='PM (Расчеты)'!I16 -> 0
A9: 5 | B9: =SUMPRODUCT(($A12:$A1002 = 5) * ('Оценка'!F12:F1002) * IF(LEN('Оценка'!$E$12:$E1002) = 0, 1, IF('Оценка'!$E$12:$E1002 = 0, 1, 'Оценка'!$E$12:$E1002))) -> 35 | C9: =SUMPRODUCT(($A12:$A1002 = 5) * ('Оценка'!G12:G1002) * IF(LEN('Оценка'!$E$12:$E1002) = 0, 1, IF('Оценка'!$E$12:$E1002 = 0, 1, 'Оценка'!$E$12:$E1002))) -> 44.5 | D9: ='PM (Расчеты)'!I11 -> 12.72 | E9: 11 | F9: =SUMPRODUCT(($A12:$A1002 = 11) * ('Оценка'!F12:F1002) * IF(LEN('Оценка'!$E$12:$E1002) = 0, 1, IF('Оценка'!$E$12:$E1002 = 0, 1, 'Оценка'!$E$12:$E1002))) -> 0 | G9: =SUMPRODUCT(($A12:$A1002 = 11) * ('Оценка'!G12:G1002) * IF(LEN('Оценка'!$E$12:$E1002) = 0, 1, IF('Оценка'!$E$12:$E1002 = 0, 1, 'Оценка'!$E$12:$E1002))) -> 0 | H9: ='PM (Расчеты)'!I17 -> 0
A10: 6 | B10: =SUMPRODUCT(($A12:$A1002 = 6) * ('Оценка'!F12:F1002) * IF(LEN('Оценка'!$E$12:$E1002) = 0, 1, IF('Оценка'!$E$12:$E1002 = 0, 1, 'Оценка'!$E$12:$E1002))) -> 15 | C10: =SUMPRODUCT(($A12:$A1002 = 6) * ('Оценка'!G12:G1002) * IF(LEN('Оценка'!$E$12:$E1002) = 0, 1, IF('Оценка'!$E$12:$E1002 = 0, 1, 'Оценка'!$E$12:$E1002))) -> 15 | D10: ='PM (Расчеты)'!I12 -> 4.8 | E10: 12 | F10: =SUMPRODUCT(($A12:$A1002 = 12) * ('Оценка'!F12:F1002) * IF(LEN('Оценка'!$E$12:$E1002) = 0, 1, IF('Оценка'!$E$12:$E1002 = 0, 1, 'Оценка'!$E$12:$E1002))) -> 0 | G10: =SUMPRODUCT(($A12:$A1002 = 12) * ('Оценка'!G12:G1002) * IF(LEN('Оценка'!$E$12:$E1002) = 0, 1, IF('Оценка'!$E$12:$E1002 = 0, 1, 'Оценка'!$E$12:$E1002))) -> 0 | H10: ='PM (Расчеты)'!I18 -> 0
A11: Распределение работ | B11: Вид работ | C11: Задача | D11: Комментарий | F11: Минимальная оценка дни (первичные данные) | G11: Максимальная оценка дни (первичные данные) | H11: Итоговые значения с учетом коэффициентов
C12: DevOps: Инфраструктура | H12: =IF(OR(ISBLANK('Оценка'!F12), ISBLANK('Оценка'!G12)), "", (AVERAGE( ( ('Оценка'!F12 + 4*AVERAGE('Оценка'!F12:G12) + 'Оценка'!G12)/6 - 2*(('Оценка'!G12 - 'Оценка'!F12)/6) )/5 , ( ('Оценка'!F12 + 4*AVERAGE('Оценка'!F12:G12) + 'Оценка'!G12)/6 + 2*(('Оценка'!G12 - 'Оценка'!F12)/6) )/5 ) * ( ( ('PM (Расчеты)'!$C$22/8 + 'PM (Расчеты)'!$C$23/40) + 'PM (Расчеты)'!$C$21/100 + 'PM (Расчеты)'!$C$25/100 + 'PM (Расчеты)'!$C$26/100 ) + 1 ))*5)
A13: 1 | B13: DevOps | C13: Создание и настройка репозиториев | D13: Backend, Frontend, Contracts — структура, README, права доступа | F13: 0.5 | G13: 1 | H13: =IF(OR(ISBLANK('Оценка'!F13), ISBLANK('Оценка'!G13)), "", (AVERAGE( ( ('Оценка'!F13 + 4*AVERAGE('Оценка'!F13:G13) + 'Оценка'!G13)/6 - 2*(('Оценка'!G13 - 'Оценка'!F13)/6) )/5 , ( ('Оценка'!F13 + 4*AVERAGE('Оценка'!F13:G13) + 'Оценка'!G13)/6 + 2*(('Оценка'!G13 - 'Оценка'!F13)/6) )/5 ) * ( ( ('PM (Расчеты)'!$C$22/8 + 'PM (Расчеты)'!$C$23/40) + 'PM (Расчеты)'!$C$21/100 + 'PM (Расчеты)'!$C$25/100 + 'PM (Расчеты)'!$C$26/100 ) + 1 ))*5) -> 1.2
A14: 1 | B14: DevOps | C14: Настройка CI/CD pipelines | D14: Сборка, линтинг, тесты, деплой для всех репозиториев | F14: 1 | G14: 2 | H14: =IF(OR(ISBLANK('Оценка'!F14), ISBLANK('Оценка'!G14)), "", (AVERAGE( ( ('Оценка'!F14 + 4*AVERAGE('Оценка'!F14:G14) + 'Оценка'!G14)/6 - 2*(('Оценка'!G14 - 'Оценка'!F14)/6) )/5 , ( ('Оценка'!F14 + 4*AVERAGE('Оценка'!F14:G14) + 'Оценка'!G14)/6 + 2*(('Оценка'!G14 - 'Оценка'!F14)/6) )/5 ) * ( ( ('PM (Расчеты)'!$C$22/8 + 'PM (Расчеты)'!$C$23/40) + 'PM (Расчеты)'!$C$21/100 + 'PM (Расчеты)'!$C$25/100 + 'PM (Расчеты)'!$C$26/100 ) + 1 ))*5) -> 2.4
A15: 1 | B15: DevOps | C15: Настройка PostgreSQL | D15: Установка, конфигурация, резервное копирование | F15: 1 | G15: 2 | H15: =IF(OR(ISBLANK('Оценка'!F15), ISBLANK('Оценка'!G15)), "", (AVERAGE( ( ('Оценка'!F15 + 4*AVERAGE('Оценка'!F15:G15) + 'Оценка'!G15)/6 - 2*(('Оценка'!G15 - 'Оценка'!F15)/6) )/5 , ( ('Оценка'!F15 + 4*AVERAGE('Оценка'!F15:G15) + 'Оценка'!G15)/6 + 2*(('Оценка'!G15 - 'Оценка'!F15)/6) )/5 ) * ( ( ('PM (Расчеты)'!$C$22/8 + 'PM (Расчеты)'!$C$23/40) + 'PM (Расчеты)'!$C$21/100 + 'PM (Расчеты)'!$C$25/100 + 'PM (Расчеты)'!$C$26/100 ) + 1 ))*5) -> 2.4
A16: 1 | B16: DevOps | C16: Настройка Redis | D16: Кэш, очереди, сессии | F16: 1 | G16: 2 | H16: =IF(OR(ISBLANK('Оценка'!F16), ISBLANK('Оценка'!G16)), "", (AVERAGE( ( ('Оценка'!F16 + 4*AVERAGE('Оценка'!F16:G16) + 'Оценка'!G16)/6 - 2*(('Оценка'!G16 - 'Оценка'!F16)/6) )/5 , ( ('Оценка'!F16 + 4*AVERAGE('Оценка'!F16:G16) + 'Оценка'!G16)/6 + 2*(('Оценка'!G16 - 'Оценка'!F16)/6) )/5 ) * ( ( ('PM (Расчеты)'!$C$22/8 + 'PM (Расчеты)'!$C$23/40) + 'PM (Расчеты)'!$C$21/100 + 'PM (Расчеты)'!$C$25/100 + 'PM (Расчеты)'!$C$26/100 ) + 1 ))*5) -> 2.4
A17: 1 | B17: DevOps | C17: Настройка HashiCorp Vault | D17: Хранение секретов, ключей шифрования | F17: 1 | G17: 2 | H17: =IF(OR(ISBLANK('Оценка'!F17), ISBLANK('Оценка'!G17)), "", (AVERAGE( ( ('Оценка'!F17 + 4*AVERAGE('Оценка'!F17:G17) + 'Оценка'!G17)/6 - 2*(('Оценка'!G17 - 'Оценка'!F17)/6) )/5 , ( ('Оценка'!F17 + 4*AVERAGE('Оценка'!F17:G17) + 'Оценка'!G17)/6 + 2*(('Оценка'!G17 - 'Оценка'!F17)/6) )/5 ) * ( ( ('PM (Расчеты)'!$C$22/8 + 'PM (Расчеты)'!$C$23/40) + 'PM (Расчеты)'!$C$21/100 + 'PM (Расчеты)'!$C$25/100 + 'PM (Расчеты)'!$C$26/100 ) + 1 ))*5) -> 2.4
A18: 1 | B18: DevOps | C18: Настройка Nginx и доменов | D18: Reverse proxy, SSL, rate limiting, DNS | F18: 2 | G18: 3 | H18: =IF(OR(ISBLANK('Оценка'!F18), ISBLANK('Оценка'!G18)), "", (AVERAGE( ( ('Оценка'!F18 + 4*AVERAGE('Оценка'!F18:G18) + 'Оценка'!G18)/6 - 2*(('Оценка'!G18 - 'Оценка'!F18)/6) )/5 , ( ('Оценка'!F18 + 4*AVERAGE('Оценка'!F18:G18) + 'Оценка'!G18)/6 + 2*(('Оценка'!G18 - 'Оценка'!F18)/6) )/5 ) * ( ( ('PM (Расчеты)'!$C$22/8 + 'PM (Расчеты)'!$C$23/40) + 'PM (Расчеты)'!$C$21/100 + 'PM (Расчеты)'!$C$25/100 + 'PM (Расчеты)'!$C$26/100 ) + 1 ))*5) -> 4
A19: 1 | B19: DevOps | C19: Настройка мониторинга и алертинга | D19: Prometheus, Grafana, PagerDuty/Slack интеграция | F19: 2 | G19: 3 | H19: =IF(OR(ISBLANK('Оценка'!F19), ISBLANK('Оценка'!G19)), "", (AVERAGE( ( ('Оценка'!F19 + 4*AVERAGE('Оценка'!F19:G19) + 'Оценка'!G19)/6 - 2*(('Оценка'!G19 - 'Оценка'!F19)/6) )/5 , ( ('Оценка'!F19 + 4*AVERAGE('Оценка'!F19:G19) + 'Оценка'!G19)/6 + 2*(('Оценка'!G19 - 'Оценка'!F19)/6) )/5 ) * ( ( ('PM (Расчеты)'!$C$22/8 + 'PM (Расчеты)'!$C$23/40) + 'PM (Расчеты)'!$C$21/100 + 'PM (Расчеты)'!$C$25/100 + 'PM (Расчеты)'!$C$26/100 ) + 1 ))*5) -> 4
A20: 1 | B20: DevOps | C20: Настройка централизованного логирования | F20: 2 | G20: 2 | H20: =IF(OR(ISBLANK('Оценка'!F20), ISBLANK('Оценка'!G20)), "", (AVERAGE( ( ('Оценка'!F20 + 4*AVERAGE('Оценка'!F20:G20) + 'Оценка'!G20)/6 - 2*(('Оценка'!G20 - 'Оценка'!F20)/6) )/5 , ( ('Оценка'!F20 + 4*AVERAGE('Оценка'!F20:G20) + 'Оценка'!G20)/6 + 2*(('Оценка'!G20 - 'Оценка'!F20)/6) )/5 ) * ( ( ('PM (Расчеты)'!$C$22/8 + 'PM (Расчеты)'!$C$23/40) + 'PM (Расчеты)'!$C$21/100 + 'PM (Расчеты)'!$C$25/100 + 'PM (Расчеты)'!$C$26/100 ) + 1 ))*5) -> 3.2
C21: Смарт-контракты | H21: =IF(OR(ISBLANK('Оценка'!F21), ISBLANK('Оценка'!G21)), "", (AVERAGE( ( ('Оценка'!F21 + 4*AVERAGE('Оценка'!F21:G21) + 'Оценка'!G21)/6 - 2*(('Оценка'!G21 - 'Оценка'!F21)/6) )/5 , ( ('Оценка'!F21 + 4*AVERAGE('Оценка'!F21:G21) + 'Оценка'!G21)/6 + 2*(('Оценка'!G21 - 'Оценка'!F21)/6) )/5 ) * ( ( ('PM (Расчеты)'!$C$22/8 + 'PM (Расчеты)'!$C$23/40) + 'PM (Расчеты)'!$C$21/100 + 'PM (Расчеты)'!$C$25/100 + 'PM (Расчеты)'!$C$26/100 ) + 1 ))*5)
A22: 2 | B22: Smart contract | C22: Разработка EscrowFactory | D22: Создание прокси-контрактов, события, access control | F22: 1 | G22: 1.5 | H22: =IF(OR(ISBLANK('Оценка'!F22), ISBLANK('Оценка'!G22)), "", (AVERAGE( ( ('Оценка'!F22 + 4*AVERAGE('Оценка'!F22:G22) + 'Оценка'!G22)/6 - 2*(('Оценка'!G22 - 'Оценка'!F22)/6) )/5 , ( ('Оценка'!F22 + 4*AVERAGE('Оценка'!F22:G22) + 'Оценка'!G22)/6 + 2*(('Оценка'!G22 - 'Оценка'!F22)/6) )/5 ) * ( ( ('PM (Расчеты)'!$C$22/8 + 'PM (Расчеты)'!$C$23/40) + 'PM (Расчеты)'!$C$21/100 + 'PM (Расчеты)'!$C$25/100 + 'PM (Расчеты)'!$C$26/100 ) + 1 ))*5) -> 2
A23: 2 | B23: Smart contract | C23: Разработка Escrow Implementation | D23: Логика депозита, релиза, refund, referral link, resolveDispute, интеграция USDT | F23: 2 | G23: 3 | H23: =IF(OR(ISBLANK('Оценка'!F23), ISBLANK('Оценка'!G23)), "", (AVERAGE( ( ('Оценка'!F23 + 4*AVERAGE('Оценка'!F23:G23) + 'Оценка'!G23)/6 - 2*(('Оценка'!G23 - 'Оценка'!F23)/6) )/5 , ( ('Оценка'!F23 + 4*AVERAGE('Оценка'!F23:G23) + 'Оценка'!G23)/6 + 2*(('Оценка'!G23 - 'Оценка'!F23)/6) )/5 ) * ( ( ('PM (Расчеты)'!$C$22/8 + 'PM (Расчеты)'!$C$23/40) + 'PM (Расчеты)'!$C$21/100 + 'PM (Расчеты)'!$C$25/100 + 'PM (Расчеты)'!$C$26/100 ) + 1 ))*5) -> 4
A24: 2 | B24: Smart contract | C24: Написание unit и integration тестов | D24: Покрытие всех функций, happy path, edge cases, gas optimization | F24: 1.5 | G24: 2.5 | H24: =IF(OR(ISBLANK('Оценка'!F24), ISBLANK('Оценка'!G24)), "", (AVERAGE( ( ('Оценка'!F24 + 4*AVERAGE('Оценка'!F24:G24) + 'Оценка'!G24)/6 - 2*(('Оценка'!G24 - 'Оценка'!F24)/6) )/5 , ( ('Оценка'!F24 + 4*AVERAGE('Оценка'!F24:G24) + 'Оценка'!G24)/6 + 2*(('Оценка'!G24 - 'Оценка'!F24)/6) )/5 ) * ( ( ('PM (Расчеты)'!$C$22/8 + 'PM (Расчеты)'!$C$23/40) + 'PM (Расчеты)'!$C$21/100 + 'PM (Расчеты)'!$C$25/100 + 'PM (Расчеты)'!$C$26/100 ) + 1 ))*5) -> 3.2
A25: 2 | B25: Smart contract | C25: Деплой в testnet (Sepolia) | D25: Factory + Implementation, верификация в Etherscan | F25: 0.5 | G25: 0.5 | H25: =IF(OR(ISBLANK('Оценка'!F25), ISBLANK('Оценка'!G25)), "", (AVERAGE( ( ('Оценка'!F25 + 4*AVERAGE('Оценка'!F25:G25) + 'Оценка'!G25)/6 - 2*(('Оценка'!G25 - 'Оценка'!F25)/6) )/5 , ( ('Оценка'!F25 + 4*AVERAGE('Оценка'!F25:G25) + 'Оценка'!G25)/6 + 2*(('Оценка'!G25 - 'Оценка'!F25)/6) )/5 ) * ( ( ('PM (Расчеты)'!$C$22/8 + 'PM (Расчеты)'!$C$23/40) + 'PM (Расчеты)'!$C$21/100 + 'PM (Расчеты)'!$C$25/100 + 'PM (Расчеты)'!$C$26/100 ) + 1 ))*5) -> 0.8
A26: 2 | B26: Smart contract | C26: Деплой в mainnet | D26: Factory + Implementation, настройка мультисиг/Fireblocks | F26: 2 | G26: 2 | H26: =IF(OR(ISBLANK('Оценка'!F26), ISBLANK('Оценка'!G26)), "", (AVERAGE( ( ('Оценка'!F26 + 4*AVERAGE('Оценка'!F26:G26) + 'Оценка'!G26)/6 - 2*(('Оценка'!G26 - 'Оценка'!F26)/6) )/5 , ( ('Оценка'!F26 + 4*AVERAGE('Оценка'!F26:G26) + 'Оценка'!G26)/6 + 2*(('Оценка'!G26 - 'Оценка'!F26)/6) )/5 ) * ( ( ('PM (Расчеты)'!$C$22/8 + 'PM (Расчеты)'!$C$23/40) + 'PM (Расчеты)'!$C$21/100 + 'PM (Расчеты)'!$C$25/100 + 'PM (Расчеты)'!$C$26/100 ) + 1 ))*5) -> 3.2
A27: 2 | B27: Smart contract | C27: Аудит безопасности | D27: Внешний аудит, исправление найденных проблем | F27: 1 | G27: 1 | H27: =IF(OR(ISBLANK('Оценка'!F27), ISBLANK('Оценка'!G27)), "", (AVERAGE( ( ('Оценка'!F27 + 4*AVERAGE('Оценка'!F27:G27) + 'Оценка'!G27)/6 - 2*(('Оценка'!G27 - 'Оценка'!F27)/6) )/5 , ( ('Оценка'!F27 + 4*AVERAGE('Оценка'!F27:G27) + 'Оценка'!G27)/6 + 2*(('Оценка'!G27 - 'Оценка'!F27)/6) )/5 ) * ( ( ('PM (Расчеты)'!$C$22/8 + 'PM (Расчеты)'!$C$23/40) + 'PM (Расчеты)'!$C$21/100 + 'PM (Расчеты)'!$C$25/100 + 'PM (Расчеты)'!$C$26/100 ) + 1 ))*5) -> 1.6
C28: Backend (Monolith): Инициализация NestJS проекта | H28: =IF(OR(ISBLANK('Оценка'!F28), ISBLANK('Оценка'!G28)), "", (AVERAGE( ( ('Оценка'!F28 + 4*AVERAGE('Оценка'!F28:G28) + 'Оценка'!G28)/6 - 2*(('Оценка'!G28 - 'Оценка'!F28)/6) )/5 , ( ('Оценка'!F28 + 4*AVERAGE('Оценка'!F28:G28) + 'Оценка'!G28)/6 + 2*(('Оценка'!G28 - 'Оценка'!F28)/6) )/5 ) * ( ( ('PM (Расчеты)'!$C$22/8 + 'PM (Расчеты)'!$C$23/40) + 'PM (Расчеты)'!$C$21/100 + 'PM (Расчеты)'!$C$25/100 + 'PM (Расчеты)'!$C$26/100 ) + 1 ))*5)
A29: 3 | B29: Backend | C29: Настройка инфраструктуры | D29: TypeORM (PostgreSQL), Redis, Bull Queue, валидация | F29: 2 | G29: 3 | H29: =IF(OR(ISBLANK('Оценка'!F29), ISBLANK('Оценка'!G29)), "", (AVERAGE( ( ('Оценка'!F29 + 4*AVERAGE('Оценка'!F29:G29) + 'Оценка'!G29)/6 - 2*(('Оценка'!G29 - 'Оценка'!F29)/6) )/5 , ( ('Оценка'!F29 + 4*AVERAGE('Оценка'!F29:G29) + 'Оценка'!G29)/6 + 2*(('Оценка'!G29 - 'Оценка'!F29)/6) )/5 ) * ( ( ('PM (Расчеты)'!$C$22/8 + 'PM (Расчеты)'!$C$23/40) + 'PM (Расчеты)'!$C$21/100 + 'PM (Расчеты)'!$C$25/100 + 'PM (Расчеты)'!$C$26/100 ) + 1 ))*5) -> 4
A30: 3 | B30: Backend | C30: Разработка Shared Layer | D30: Database Service, Cache Service, Queue Service, Auth Service | F30: 2 | G30: 3 | H30: =IF(OR(ISBLANK('Оценка'!F30), ISBLANK('Оценка'!G30)), "", (AVERAGE( ( ('Оценка'!F30 + 4*AVERAGE('Оценка'!F30:G30) + 'Оценка'!G30)/6 - 2*(('Оценка'!G30 - 'Оценка'!F30)/6) )/5 , ( ('Оценка'!F30 + 4*AVERAGE('Оценка'!F30:G30) + 'Оценка'!G30)/6 + 2*(('Оценка'!G30 - 'Оценка'!F30)/6) )/5 ) * ( ( ('PM (Расчеты)'!$C$22/8 + 'PM (Расчеты)'!$C$23/40) + 'PM (Расчеты)'!$C$21/100 + 'PM (Расчеты)'!$C$25/100 + 'PM (Расчеты)'!$C$26/100 ) + 1 ))*5) -> 4
A31: 4 | B31: Backend | C31: Разработка Blockchain Service | D31: Ethers.js интеграция, RPC, индексатор событий | F31: 2 | G31: 3 | H31: =IF(OR(ISBLANK('Оценка'!F31), ISBLANK('Оценка'!G31)), "", (AVERAGE( ( ('Оценка'!F31 + 4*AVERAGE('Оценка'!F31:G31) + 'Оценка'!G31)/6 - 2*(('Оценка'!G31 - 'Оценка'!F31)/6) )/5 , ( ('Оценка'!F31 + 4*AVERAGE('Оценка'!F31:G31) + 'Оценка'!G31)/6 + 2*(('Оценка'!G31 - 'Оценка'!F31)/6) )/5 ) * ( ( ('PM (Расчеты)'!$C$22/8 + 'PM (Расчеты)'!$C$23/40) + 'PM (Расчеты)'!$C$21/100 + 'PM (Расчеты)'!$C$25/100 + 'PM (Расчеты)'!$C$26/100 ) + 1 ))*5) -> 4
A32: 3 | B32: Backend | C32: Разработка Encryption Service | D32: AES-256 для шифрования реквизитов | F32: 1 | G32: 2 | H32: =IF(OR(ISBLANK('Оценка'!F32), ISBLANK('Оценка'!G32)), "", (AVERAGE( ( ('Оценка'!F32 + 4*AVERAGE('Оценка'!F32:G32) + 'Оценка'!G32)/6 - 2*(('Оценка'!G32 - 'Оценка'!F32)/6) )/5 , ( ('Оценка'!F32 + 4*AVERAGE('Оценка'!F32:G32) + 'Оценка'!G32)/6 + 2*(('Оценка'!G32 - 'Оценка'!F32)/6) )/5 ) * ( ( ('PM (Расчеты)'!$C$22/8 + 'PM (Расчеты)'!$C$23/40) + 'PM (Расчеты)'!$C$21/100 + 'PM (Расчеты)'!$C$25/100 + 'PM (Расчеты)'!$C$26/100 ) + 1 ))*5) -> 2.4
C33: Backend (Monolith): User Module | H33: =IF(OR(ISBLANK('Оценка'!F33), ISBLANK('Оценка'!G33)), "", (AVERAGE( ( ('Оценка'!F33 + 4*AVERAGE('Оценка'!F33:G33) + 'Оценка'!G33)/6 - 2*(('Оценка'!G33 - 'Оценка'!F33)/6) )/5 , ( ('Оценка'!F33 + 4*AVERAGE('Оценка'!F33:G33) + 'Оценка'!G33)/6 + 2*(('Оценка'!G33 - 'Оценка'!F33)/6) )/5 ) * ( ( ('PM (Расчеты)'!$C$22/8 + 'PM (Расчеты)'!$C$23/40) + 'PM (Расчеты)'!$C$21/100 + 'PM (Расчеты)'!$C$25/100 + 'PM (Расчеты)'!$C$26/100 ) + 1 ))*5)
A34: 4 | B34: Backend | C34: Создание сущностей | D34: User (с полями реферальной программы: referrer_id, referrer_wallet, referral_code), Wallet, KycStatus, UserLevel — таблицы, связи, индексы | F34: 1.5 | G34: 2.5 | H34: =IF(OR(ISBLANK('Оценка'!F34), ISBLANK('Оценка'!G34)), "", (AVERAGE( ( ('Оценка'!F34 + 4*AVERAGE('Оценка'!F34:G34) + 'Оценка'!G34)/6 - 2*(('Оценка'!G34 - 'Оценка'!F34)/6) )/5 , ( ('Оценка'!F34 + 4*AVERAGE('Оценка'!F34:G34) + 'Оценка'!G34)/6 + 2*(('Оценка'!G34 - 'Оценка'!F34)/6) )/5 ) * ( ( ('PM (Расчеты)'!$C$22/8 + 'PM (Расчеты)'!$C$23/40) + 'PM (Расчеты)'!$C$21/100 + 'PM (Расчеты)'!$C$25/100 + 'PM (Расчеты)'!$C$26/100 ) + 1 ))*5) -> 3.2
A35: 4 | B35: Backend | C35: Разработка API | D35: Регистрация, авторизация (Web3 + JWT), профиль, привязка кошелька | F35: 2.5 | G35: 3.5 | H35: =IF(OR(ISBLANK('Оценка'!F35), ISBLANK('Оценка'!G35)), "", (AVERAGE( ( ('Оценка'!F35 + 4*AVERAGE('Оценка'!F35:G35) + 'Оценка'!G35)/6 - 2*(('Оценка'!G35 - 'Оценка'!F35)/6) )/5 , ( ('Оценка'!F35 + 4*AVERAGE('Оценка'!F35:G35) + 'Оценка'!G35)/6 + 2*(('Оценка'!G35 - 'Оценка'!F35)/6) )/5 ) * ( ( ('PM (Расчеты)'!$C$22/8 + 'PM (Расчеты)'!$C$23/40) + 'PM (Расчеты)'!$C$21/100 + 'PM (Расчеты)'!$C$25/100 + 'PM (Расчеты)'!$C$26/100 ) + 1 ))*5) -> 4.8
A36: 4 | B36: Backend | C36: Реализация уровней доступа | D36: Проверка прав, лимиты | F36: 2 | G36: 3 | H36: =IF(OR(ISBLANK('Оценка'!F36), ISBLANK('Оценка'!G36)), "", (AVERAGE( ( ('Оценка'!F36 + 4*AVERAGE('Оценка'!F36:G36) + 'Оценка'!G36)/6 - 2*(('Оценка'!G36 - 'Оценка'!F36)/6) )/5 , ( ('Оценка'!F36 + 4*AVERAGE('Оценка'!F36:G36) + 'Оценка'!G36)/6 + 2*(('Оценка'!G36 - 'Оценка'!F36)/6) )/5 ) * ( ( ('PM (Расчеты)'!$C$22/8 + 'PM (Расчеты)'!$C$23/40) + 'PM (Расчеты)'!$C$21/100 + 'PM (Расчеты)'!$C$25/100 + 'PM (Расчеты)'!$C$26/100 ) + 1 ))*5) -> 4
C37: Backend (Monolith): Trading Module | H37: =IF(OR(ISBLANK('Оценка'!F37), ISBLANK('Оценка'!G37)), "", (AVERAGE( ( ('Оценка'!F37 + 4*AVERAGE('Оценка'!F37:G37) + 'Оценка'!G37)/6 - 2*(('Оценка'!G37 - 'Оценка'!F37)/6) )/5 , ( ('Оценка'!F37 + 4*AVERAGE('Оценка'!F37:G37) + 'Оценка'!G37)/6 + 2*(('Оценка'!G37 - 'Оценка'!F37)/6) )/5 ) * ( ( ('PM (Расчеты)'!$C$22/8 + 'PM (Расчеты)'!$C$23/40) + 'PM (Расчеты)'!$C$21/100 + 'PM (Расчеты)'!$C$25/100 + 'PM (Расчеты)'!$C$26/100 ) + 1 ))*5)
A38: 3 | B38: Backend | C38: Создание сущностей | D38: Order, Deal, EscrowContract — таблицы, связи | F38: 1 | G38: 2 | H38: =IF(OR(ISBLANK('Оценка'!F38), ISBLANK('Оценка'!G38)), "", (AVERAGE( ( ('Оценка'!F38 + 4*AVERAGE('Оценка'!F38:G38) + 'Оценка'!G38)/6 - 2*(('Оценка'!G38 - 'Оценка'!F38)/6) )/5 , ( ('Оценка'!F38 + 4*AVERAGE('Оценка'!F38:G38) + 'Оценка'!G38)/6 + 2*(('Оценка'!G38 - 'Оценка'!F38)/6) )/5 ) * ( ( ('PM (Расчеты)'!$C$22/8 + 'PM (Расчеты)'!$C$23/40) + 'PM (Расчеты)'!$C$21/100 + 'PM (Расчеты)'!$C$25/100 + 'PM (Расчеты)'!$C$26/100 ) + 1 ))*5) -> 2.4
A39: 3 | B39: Backend | C39: Разработка Order API | D39: CRUD ордеров, стакан, фильтрация, WebSocket для real-time | F39: 3 | G39: 4.5 | H39: =IF(OR(ISBLANK('Оценка'!F39), ISBLANK('Оценка'!G39)), "", (AVERAGE( ( ('Оценка'!F39 + 4*AVERAGE('Оценка'!F39:G39) + 'Оценка'!G39)/6 - 2*(('Оценка'!G39 - 'Оценка'!F39)/6) )/5 , ( ('Оценка'!F39 + 4*AVERAGE('Оценка'!F39:G39) + 'Оценка'!G39)/6 + 2*(('Оценка'!G39 - 'Оценка'!F39)/6) )/5 ) * ( ( ('PM (Расчеты)'!$C$22/8 + 'PM (Расчеты)'!$C$23/40) + 'PM (Расчеты)'!$C$21/100 + 'PM (Расчеты)'!$C$25/100 + 'PM (Расчеты)'!$C$26/100 ) + 1 ))*5) -> 6
A40: 3 | B40: Backend | C40: Разработка Deal API | D40: Инициация, деплой эскроу, обработка депозита, подтверждения | F40: 3 | G40: 4.5 | H40: =IF(OR(ISBLANK('Оценка'!F40), ISBLANK('Оценка'!G40)), "", (AVERAGE( ( ('Оценка'!F40 + 4*AVERAGE('Оценка'!F40:G40) + 'Оценка'!G40)/6 - 2*(('Оценка'!G40 - 'Оценка'!F40)/6) )/5 , ( ('Оценка'!F40 + 4*AVERAGE('Оценка'!F40:G40) + 'Оценка'!G40)/6 + 2*(('Оценка'!G40 - 'Оценка'!F40)/6) )/5 ) * ( ( ('PM (Расчеты)'!$C$22/8 + 'PM (Расчеты)'!$C$23/40) + 'PM (Расчеты)'!$C$21/100 + 'PM (Расчеты)'!$C$25/100 + 'PM (Расчеты)'!$C$26/100 ) + 1 ))*5) -> 6
A41: 3 | B41: Backend | C41: Реализация жизненного цикла сделки | D41: Таймауты, авто-отмена, релиз, комиссия | F41: 3 | G41: 5 | H41: =IF(OR(ISBLANK('Оценка'!F41), ISBLANK('Оценка'!G41)), "", (AVERAGE( ( ('Оценка'!F41 + 4*AVERAGE('Оценка'!F41:G41) + 'Оценка'!G41)/6 - 2*(('Оценка'!G41 - 'Оценка'!F41)/6) )/5 , ( ('Оценка'!F41 + 4*AVERAGE('Оценка'!F41:G41) + 'Оценка'!G41)/6 + 2*(('Оценка'!G41 - 'Оценка'!F41)/6) )/5 ) * ( ( ('PM (Расчеты)'!$C$22/8 + 'PM (Расчеты)'!$C$23/40) + 'PM (Расчеты)'!$C$21/100 + 'PM (Расчеты)'!$C$25/100 + 'PM (Расчеты)'!$C$26/100 ) + 1 ))*5) -> 6.4
...

Sheet PM (Расчеты)
A1: ⭠ Инструкция к заполнению (нажми "+") | D1: - ячейки, которые необходимо заполнить
A2: 1. В столбце А, начиная с строки 5, вносятся ФИО или тип работ, соответсвующий выбранному типу работ в вкладке "Оценка". 2. В столбце Н, начиная с строки 5, вносятся ставки на руки специалистов на проетке. 3. В столбце С, начиная с строки 15, выбираются коэффиценты необходимые на проекте. 4. Восле занесения всех данных и окончательной оценки, в ячейке С8, сумарно сколько рабочих недель планируетс реализовывать проект (в недели 5 дней по 8 часов в дне).
B4: Проектная команда/тип работ: | C4: Виды работ | D4: Часовая ставка: | E4: Ставка на клиенте | G4: Проектная команда/тип работ: | H4: Виды работ | I4: Продолжительность работ в неделях | J4: Себестоимость
B5: Manual QA | C5: Manual QA | D5: 0 | E5: ='Sales (Итоги оценки)'!K6 | G5: Тестировщик | H5: Тестировщик | I5: =SUM(I7:I18)*C24/100 -> 0 | J5: =I5*5*8*D5 -> 0
B6: Project manager | C6: Project manager | D6: 15 | E6: ='Sales (Итоги оценки)'!K7 -> 30 | G6: Менеджер | H6: Менеджер | I6: =MAX(I7:I18)*(C27/100) -> 3.816 | J6: =I6*5*8*D6 -> 2289.6
B7: DevOps | C7: 1 | D7: 25 | E7: ='Sales (Итоги оценки)'!K8 -> 50 | G7: =B7 -> DevOps | H7: 1 | I7: =AVERAGE((('Оценка'!B5 + 4*AVERAGE('Оценка'!B5:C5) + 'Оценка'!C5)/6 - 2*(('Оценка'!C5 - 'Оценка'!B5)/6))/5 , (('Оценка'!B5 + 4*AVERAGE('Оценка'!B5:C5) + 'Оценка'!C5)/6 + 2*(('Оценка'!C5 - 'Оценка'!B5)/6))/5)*(((($C$22/8+$C$23/40)+$C$21/100+$C$25/100+$C$26/100)+1 )) -> 4.4 | J7: =I7*5*8*D7 -> 4400
B8: Smart contract | C8: 2 | D8: 30 | E8: ='Sales (Итоги оценки)'!K9 -> 50 | G8: =B8 -> Smart contract | H8: 2 | I8: =AVERAGE((('Оценка'!B6 + 4*AVERAGE('Оценка'!B6:C6) + 'Оценка'!C6)/6 - 2*(('Оценка'!C6 - 'Оценка'!B6)/6))/5 , (('Оценка'!B6 + 4*AVERAGE('Оценка'!B6:C6) + 'Оценка'!C6)/6 + 2*(('Оценка'!C6 - 'Оценка'!B6)/6))/5)*(((($C$22/8+$C$23/40)+$C$21/100+$C$25/100+$C$26/100)+1 )) -> 2.96 | J8: =I8*5*8*D8 -> 3552
B9: Backend | C9: 3 | D9: 31 | E9: ='Sales (Итоги оценки)'!K10 -> 51.666667 | G9: =B9 -> Backend | H9: 3 | I9: =AVERAGE((('Оценка'!B7 + 4*AVERAGE('Оценка'!B7:C7) + 'Оценка'!C7)/6 - 2*(('Оценка'!C7 - 'Оценка'!B7)/6))/5 , (('Оценка'!B7 + 4*AVERAGE('Оценка'!B7:C7) + 'Оценка'!C7)/6 + 2*(('Оценка'!C7 - 'Оценка'!B7)/6))/5)*(((($C$22/8+$C$23/40)+$C$21/100+$C$25/100+$C$26/100)+1 )) -> 10.16 | J9: =I9*5*8*D9 -> 12598.4
B10: Backend | C10: 4 | D10: 21 | E10: ='Sales (Итоги оценки)'!K11 -> 42 | G10: =B10 -> Backend | H10: 4 | I10: =AVERAGE((('Оценка'!B8 + 4*AVERAGE('Оценка'!B8:C8) + 'Оценка'!C8)/6 - 2*(('Оценка'!C8 - 'Оценка'!B8)/6))/5 , (('Оценка'!B8 + 4*AVERAGE('Оценка'!B8:C8) + 'Оценка'!C8)/6 + 2*(('Оценка'!C8 - 'Оценка'!B8)/6))/5)*(((($C$22/8+$C$23/40)+$C$21/100+$C$25/100+$C$26/100)+1 )) -> 10.88 | J10: =I10*5*8*D10 -> 9139.2
B11: Frontend | C11: 5 | D11: 20 | E11: ='Sales (Итоги оценки)'!K12 -> 40 | G11: =B11 -> Frontend | H11: 5 | I11: =AVERAGE((('Оценка'!B9 + 4*AVERAGE('Оценка'!B9:C9) + 'Оценка'!C9)/6 - 2*(('Оценка'!C9 - 'Оценка'!B9)/6))/5 , (('Оценка'!B9 + 4*AVERAGE('Оценка'!B9:C9) + 'Оценка'!C9)/6 + 2*(('Оценка'!C9 - 'Оценка'!B9)/6))/5)*(((($C$22/8+$C$23/40)+$C$21/100+$C$25/100+$C$26/100)+1 )) -> 12.72 | J11: =I11*5*8*D11 -> 10176
B12: QA | C12: 6 | D12: 15 | E12: ='Sales (Итоги оценки)'!K13 -> 30 | G12: =B12 -> QA | H12: 6 | I12: =AVERAGE((('Оценка'!B10 + 4*AVERAGE('Оценка'!B10:C10) + 'Оценка'!C10)/6 - 2*(('Оценка'!C10 - 'Оценка'!B10)/6))/5 , (('Оценка'!B10 + 4*AVERAGE('Оценка'!B10:C10) + 'Оценка'!C10)/6 + 2*(('Оценка'!C10 - 'Оценка'!B10)/6))/5)*(((($C$22/8+$C$23/40)+$C$21/100+$C$25/100+$C$26/100)+1 )) -> 4.8 | J12: =I12*5*8*D12 -> 2880
B13: UX/UI дизайнер | C13: 7 | D13: 20 | E13: ='Sales (Итоги оценки)'!K14 -> 40 | G13: =B13 -> UX/UI дизайнер | H13: 7 | I13: =AVERAGE((('Оценка'!F5 + 4*AVERAGE('Оценка'!F5:G5) + 'Оценка'!G5)/6 - 2*(('Оценка'!G5 - 'Оценка'!F5)/6))/5 , (('Оценка'!F5 + 4*AVERAGE('Оценка'!F5:G5) + 'Оценка'!G5)/6 + 2*(('Оценка'!G5 - 'Оценка'!F5)/6))/5)*(((($C$22/8+$C$23/40)+$C$21/100+$C$25/100+$C$26/100)+1 )) -> 4.8 | J13: =I13*5*8*D13 -> 3840
G14: =B14 | H14: 8 | I14: =AVERAGE((('Оценка'!F6 + 4*AVERAGE('Оценка'!F6:G6) + 'Оценка'!G6)/6 - 2*(('Оценка'!G6 - 'Оценка'!F6)/6))/5 , (('Оценка'!F6 + 4*AVERAGE('Оценка'!F6:G6) + 'Оценка'!G6)/6 + 2*(('Оценка'!G6 - 'Оценка'!F6)/6))/5)*(((($C$22/8+$C$23/40)+$C$21/100+$C$25/100+$C$26/100)+1 )) -> 0 | J14: =I14*5*8*D14 -> 0
G15: =B15 | H15: 9 | I15: =AVERAGE((('Оценка'!F7 + 4*AVERAGE('Оценка'!F7:G7) + 'Оценка'!G7)/6 - 2*(('Оценка'!G7 - 'Оценка'!F7)/6))/5 , (('Оценка'!F7 + 4*AVERAGE('Оценка'!F7:G7) + 'Оценка'!G7)/6 + 2*(('Оценка'!G7 - 'Оценка'!F7)/6))/5)*(((($C$22/8+$C$23/40)+$C$21/100+$C$25/100+$C$26/100)+1 )) -> 0 | J15: =I15*5*8*D15 -> 0
G16: =B16 | H16: 10 | I16: =AVERAGE((('Оценка'!F8 + 4*AVERAGE('Оценка'!F8:G8) + 'Оценка'!G8)/6 - 2*(('Оценка'!G8 - 'Оценка'!F8)/6))/5 , (('Оценка'!F8 + 4*AVERAGE('Оценка'!F8:G8) + 'Оценка'!G8)/6 + 2*(('Оценка'!G8 - 'Оценка'!F8)/6))/5)*(((($C$22/8+$C$23/40)+$C$21/100+$C$25/100+$C$26/100)+1 )) -> 0 | J16: =I16*5*8*D16 -> 0
G17: =B17 | H17: 11 | I17: =AVERAGE((('Оценка'!F9 + 4*AVERAGE('Оценка'!F9:G9) + 'Оценка'!G9)/6 - 2*(('Оценка'!G9 - 'Оценка'!F9)/6))/5 , (('Оценка'!F9 + 4*AVERAGE('Оценка'!F9:G9) + 'Оценка'!G9)/6 + 2*(('Оценка'!G9 - 'Оценка'!F9)/6))/5)*(((($C$22/8+$C$23/40)+$C$21/100+$C$25/100+$C$26/100)+1 )) -> 0 | J17: =I17*5*8*D17 -> 0
G18: =B18 | H18: 12 | I18: =AVERAGE((('Оценка'!F10 + 4*AVERAGE('Оценка'!F10:G10) + 'Оценка'!G10)/6 - 2*(('Оценка'!G10 - 'Оценка'!F10)/6))/5 , (('Оценка'!F10 + 4*AVERAGE('Оценка'!F10:G10) + 'Оценка'!G10)/6 + 2*(('Оценка'!G10 - 'Оценка'!F10)/6))/5)*(((($C$22/8+$C$23/40)+$C$21/100+$C$25/100+$C$26/100)+1 )) -> 0 | J18: =I18*5*8*D18 -> 0
C20: Коэффициенты | D20: Недель | G20: Себестоимость
B21: Проверка и отладка задач (%) | C21: 20 | D21: =(SUM(I7:I18)/((((C22/8+C23/40)+C21/100+C25/100+C26/100)+1 ))*$C$21/100) -> 6.34 | G21: Себестоимость проекта: | H21: =(D5*I5+D6*I6+D7*I7+D8*I8+D9*I9+D10*I10+D11*I11+D12*I12+D13*I13+D14*I14+D15*I15+D16*I16+D17*I17+D18*I18)*5*8 -> 48875.2
B22: Код ревью (Количество часов на разработчика в день). В норме 1 час. | C22: 1 | D22: =(SUM(I7:I18)/((((C22/8+C23/40)+C21/100+C25/100+C26/100)+1 ))*C22/8) -> 3.9625
B23: Коммуникации (3 часа в неделю на каждого) | C23: 3 | D23: =(SUM(I7:I18)/((((C22/8+C23/40)+C21/100+C25/100+C26/100)+1 ))*C23/40) -> 2.3775
B24: Тестировщик | C24: 0 | D24: =SUM(I7:I18)/((((C22/8+C23/40)+C21/100+C25/100+C26/100)+1 ))*C24/100 -> 0
B25: Буфер на риски | C25: 20 | D25: =SUM(I6:I18)/((((C22/8+C23/40)+C21/100+C25/100+C26/100)+1 ))*C25/100 -> 6.817
B26: DevOps | C26: 0 | D26: =SUM(I7:I18)/((((C22/8+C23/40)+C21/100+C25/100+C26/100)+1 ))*C26/100 -> 0
B27: Менеджер | C27: 30 | D27: =MAX(I7:I18)*C27/100 -> 3.816

Sheet Для Битрикса 
A1: Название | B1: Описание | C1: Это важная задача | D1: Разрешить ответственному менять сроки задачи | E1: Пропустить выходные и праздничные дни | F1: Проконтролировать задачу после завершения | G1: Проект | H1: Задано время на завершение задачи | I1: Время на выполнение задачи в секундах | J1: Теги | K1: Начать задачу с | L1: Завершить задачу
A2: ='Оценка'!C13 -> Создание и настройка репозиториев | B2: ='Оценка'!D12 | C2: =IF(A2<>"", 0, "") -> 0 | D2: =IF(A2<>"", 0, "") -> 0 | E2: =IF(A2<>"", 1, "") -> 1 | F2: =IF(A2<>"", 1, "") -> 1 | G2: =IF(A2<>"", 'Sales (Итоги оценки)'!$C$4, "") -> P2P платформа | H2: =IF(A2<>"", 1, "") -> 1 | I2: =IF(OR(ISBLANK('Оценка'!F12), ISBLANK('Оценка'!G12)), "", (AVERAGE( ( ('Оценка'!F12 + 4*AVERAGE('Оценка'!F12:G12) + 'Оценка'!G12)/6 - 2*(('Оценка'!G12 - 'Оценка'!F12)/6) )/5 , ( ('Оценка'!F12 + 4*AVERAGE('Оценка'!F12:G12) + 'Оценка'!G12)/6 + 2*(('Оценка'!G12 - 'Оценка'!F12)/6) )/5 ) * ( ( ('PM (Расчеты)'!$C$22/8 + 'PM (Расчеты)'!$C$23/40) + 'PM (Расчеты)'!$C$21/100 + 'PM (Расчеты)'!$C$25/100 + 'PM (Расчеты)'!$C$26/100 ) + 1 ))) * 8 * 60 * 60 -> 0 | J2: ='Оценка'!B12 | K2: =IF(A2<>"", TODAY() , "") -> 46121 | L2: =IF(A2<>"", TODAY() + (I2 /60/60) , "") -> 46121
A3: =#REF! -> #REF! | B3: ='Оценка'!D13 -> Backend, Frontend, Contracts — структура, README, права доступа | C3: =IF(A3<>"", 0, "") -> #REF! | D3: =IF(A3<>"", 0, "") -> #REF! | E3: =IF(A3<>"", 1, "") -> #REF! | F3: =IF(A3<>"", 1, "") -> #REF! | G3: =IF(A3<>"", 'Sales (Итоги оценки)'!$C$4, "") -> #REF! | H3: =IF(A3<>"", 1, "") -> #REF! | I3: =IF(OR(ISBLANK('Оценка'!F13), ISBLANK('Оценка'!G13)), "", (AVERAGE( ( ('Оценка'!F13 + 4*AVERAGE('Оценка'!F13:G13) + 'Оценка'!G13)/6 - 2*(('Оценка'!G13 - 'Оценка'!F13)/6) )/5 , ( ('Оценка'!F13 + 4*AVERAGE('Оценка'!F13:G13) + 'Оценка'!G13)/6 + 2*(('Оценка'!G13 - 'Оценка'!F13)/6) )/5 ) * ( ( ('PM (Расчеты)'!$C$22/8 + 'PM (Расчеты)'!$C$23/40) + 'PM (Расчеты)'!$C$21/100 + 'PM (Расчеты)'!$C$25/100 + 'PM (Расчеты)'!$C$26/100 ) + 1 ))) * 8 * 60 * 60 -> 6912 | J3: ='Оценка'!B13 -> DevOps | K3: =IF(A3<>"", TODAY() , "") -> #REF! | L3: =IF(A3<>"", TODAY() + (I3 /60/60) , "") -> #REF!
A4: ='Оценка'!C14 -> Настройка CI/CD pipelines | B4: ='Оценка'!D14 -> Сборка, линтинг, тесты, деплой для всех репозиториев | C4: =IF(A4<>"", 0, "") -> 0 | D4: =IF(A4<>"", 0, "") -> 0 | E4: =IF(A4<>"", 1, "") -> 1 | F4: =IF(A4<>"", 1, "") -> 1 | G4: =IF(A4<>"", 'Sales (Итоги оценки)'!$C$4, "") -> P2P платформа | H4: =IF(A4<>"", 1, "") -> 1 | I4: =IF(OR(ISBLANK('Оценка'!F14), ISBLANK('Оценка'!G14)), "", (AVERAGE( ( ('Оценка'!F14 + 4*AVERAGE('Оценка'!F14:G14) + 'Оценка'!G14)/6 - 2*(('Оценка'!G14 - 'Оценка'!F14)/6) )/5 , ( ('Оценка'!F14 + 4*AVERAGE('Оценка'!F14:G14) + 'Оценка'!G14)/6 + 2*(('Оценка'!G14 - 'Оценка'!F14)/6) )/5 ) * ( ( ('PM (Расчеты)'!$C$22/8 + 'PM (Расчеты)'!$C$23/40) + 'PM (Расчеты)'!$C$21/100 + 'PM (Расчеты)'!$C$25/100 + 'PM (Расчеты)'!$C$26/100 ) + 1 ))) * 8 * 60 * 60 -> 13824 | J4: ='Оценка'!B14 -> DevOps | K4: =IF(A4<>"", TODAY() , "") -> 46121 | L4: =IF(A4<>"", TODAY() + (I4 /60/60) , "") -> 46124.84
A5: ='Оценка'!C15 -> Настройка PostgreSQL | B5: ='Оценка'!D15 -> Установка, конфигурация, резервное копирование | C5: =IF(A5<>"", 0, "") -> 0 | D5: =IF(A5<>"", 0, "") -> 0 | E5: =IF(A5<>"", 1, "") -> 1 | F5: =IF(A5<>"", 1, "") -> 1 | G5: =IF(A5<>"", 'Sales (Итоги оценки)'!$C$4, "") -> P2P платформа | H5: =IF(A5<>"", 1, "") -> 1 | I5: =IF(OR(ISBLANK('Оценка'!F15), ISBLANK('Оценка'!G15)), "", (AVERAGE( ( ('Оценка'!F15 + 4*AVERAGE('Оценка'!F15:G15) + 'Оценка'!G15)/6 - 2*(('Оценка'!G15 - 'Оценка'!F15)/6) )/5 , ( ('Оценка'!F15 + 4*AVERAGE('Оценка'!F15:G15) + 'Оценка'!G15)/6 + 2*(('Оценка'!G15 - 'Оценка'!F15)/6) )/5 ) * ( ( ('PM (Расчеты)'!$C$22/8 + 'PM (Расчеты)'!$C$23/40) + 'PM (Расчеты)'!$C$21/100 + 'PM (Расчеты)'!$C$25/100 + 'PM (Расчеты)'!$C$26/100 ) + 1 ))) * 8 * 60 * 60 -> 13824 | J5: ='Оценка'!B15 -> DevOps | K5: =IF(A5<>"", TODAY() , "") -> 46121 | L5: =IF(A5<>"", TODAY() + (I5 /60/60) , "") -> 46124.84
A6: ='Оценка'!C16 -> Настройка Redis | B6: ='Оценка'!D16 -> Кэш, очереди, сессии | C6: =IF(A6<>"", 0, "") -> 0 | D6: =IF(A6<>"", 0, "") -> 0 | E6: =IF(A6<>"", 1, "") -> 1 | F6: =IF(A6<>"", 1, "") -> 1 | G6: =IF(A6<>"", 'Sales (Итоги оценки)'!$C$4, "") -> P2P платформа | H6: =IF(A6<>"", 1, "") -> 1 | I6: =IF(OR(ISBLANK('Оценка'!F16), ISBLANK('Оценка'!G16)), "", (AVERAGE( ( ('Оценка'!F16 + 4*AVERAGE('Оценка'!F16:G16) + 'Оценка'!G16)/6 - 2*(('Оценка'!G16 - 'Оценка'!F16)/6) )/5 , ( ('Оценка'!F16 + 4*AVERAGE('Оценка'!F16:G16) + 'Оценка'!G16)/6 + 2*(('Оценка'!G16 - 'Оценка'!F16)/6) )/5 ) * ( ( ('PM (Расчеты)'!$C$22/8 + 'PM (Расчеты)'!$C$23/40) + 'PM (Расчеты)'!$C$21/100 + 'PM (Расчеты)'!$C$25/100 + 'PM (Расчеты)'!$C$26/100 ) + 1 ))) * 8 * 60 * 60 -> 13824 | J6: ='Оценка'!B16 -> DevOps | K6: =IF(A6<>"", TODAY() , "") -> 46121 | L6: =IF(A6<>"", TODAY() + (I6 /60/60) , "") -> 46124.84
A7: ='Оценка'!C17 -> Настройка HashiCorp Vault | B7: ='Оценка'!D17 -> Хранение секретов, ключей шифрования | C7: =IF(A7<>"", 0, "") -> 0 | D7: =IF(A7<>"", 0, "") -> 0 | E7: =IF(A7<>"", 1, "") -> 1 | F7: =IF(A7<>"", 1, "") -> 1 | G7: =IF(A7<>"", 'Sales (Итоги оценки)'!$C$4, "") -> P2P платформа | H7: =IF(A7<>"", 1, "") -> 1 | I7: =IF(OR(ISBLANK('Оценка'!F17), ISBLANK('Оценка'!G17)), "", (AVERAGE( ( ('Оценка'!F17 + 4*AVERAGE('Оценка'!F17:G17) + 'Оценка'!G17)/6 - 2*(('Оценка'!G17 - 'Оценка'!F17)/6) )/5 , ( ('Оценка'!F17 + 4*AVERAGE('Оценка'!F17:G17) + 'Оценка'!G17)/6 + 2*(('Оценка'!G17 - 'Оценка'!F17)/6) )/5 ) * ( ( ('PM (Расчеты)'!$C$22/8 + 'PM (Расчеты)'!$C$23/40) + 'PM (Расчеты)'!$C$21/100 + 'PM (Расчеты)'!$C$25/100 + 'PM (Расчеты)'!$C$26/100 ) + 1 ))) * 8 * 60 * 60 -> 13824 | J7: ='Оценка'!B17 -> DevOps | K7: =IF(A7<>"", TODAY() , "") -> 46121 | L7: =IF(A7<>"", TODAY() + (I7 /60/60) , "") -> 46124.84
A8: ='Оценка'!C18 -> Настройка Nginx и доменов | B8: ='Оценка'!D18 -> Reverse proxy, SSL, rate limiting, DNS | C8: =IF(A8<>"", 0, "") -> 0 | D8: =IF(A8<>"", 0, "") -> 0 | E8: =IF(A8<>"", 1, "") -> 1 | F8: =IF(A8<>"", 1, "") -> 1 | G8: =IF(A8<>"", 'Sales (Итоги оценки)'!$C$4, "") -> P2P платформа | H8: =IF(A8<>"", 1, "") -> 1 | I8: =IF(OR(ISBLANK('Оценка'!F18), ISBLANK('Оценка'!G18)), "", (AVERAGE( ( ('Оценка'!F18 + 4*AVERAGE('Оценка'!F18:G18) + 'Оценка'!G18)/6 - 2*(('Оценка'!G18 - 'Оценка'!F18)/6) )/5 , ( ('Оценка'!F18 + 4*AVERAGE('Оценка'!F18:G18) + 'Оценка'!G18)/6 + 2*(('Оценка'!G18 - 'Оценка'!F18)/6) )/5 ) * ( ( ('PM (Расчеты)'!$C$22/8 + 'PM (Расчеты)'!$C$23/40) + 'PM (Расчеты)'!$C$21/100 + 'PM (Расчеты)'!$C$25/100 + 'PM (Расчеты)'!$C$26/100 ) + 1 ))) * 8 * 60 * 60 -> 23040 | J8: ='Оценка'!B18 -> DevOps | K8: =IF(A8<>"", TODAY() , "") -> 46121 | L8: =IF(A8<>"", TODAY() + (I8 /60/60) , "") -> 46127.4
A9: ='Оценка'!C19 -> Настройка мониторинга и алертинга | B9: ='Оценка'!D19 -> Prometheus, Grafana, PagerDuty/Slack интеграция | C9: =IF(A9<>"", 0, "") -> 0 | D9: =IF(A9<>"", 0, "") -> 0 | E9: =IF(A9<>"", 1, "") -> 1 | F9: =IF(A9<>"", 1, "") -> 1 | G9: =IF(A9<>"", 'Sales (Итоги оценки)'!$C$4, "") -> P2P платформа | H9: =IF(A9<>"", 1, "") -> 1 | I9: =IF(OR(ISBLANK('Оценка'!F19), ISBLANK('Оценка'!G19)), "", (AVERAGE( ( ('Оценка'!F19 + 4*AVERAGE('Оценка'!F19:G19) + 'Оценка'!G19)/6 - 2*(('Оценка'!G19 - 'Оценка'!F19)/6) )/5 , ( ('Оценка'!F19 + 4*AVERAGE('Оценка'!F19:G19) + 'Оценка'!G19)/6 + 2*(('Оценка'!G19 - 'Оценка'!F19)/6) )/5 ) * ( ( ('PM (Расчеты)'!$C$22/8 + 'PM (Расчеты)'!$C$23/40) + 'PM (Расчеты)'!$C$21/100 + 'PM (Расчеты)'!$C$25/100 + 'PM (Расчеты)'!$C$26/100 ) + 1 ))) * 8 * 60 * 60 -> 23040 | J9: ='Оценка'!B19 -> DevOps | K9: =IF(A9<>"", TODAY() , "") -> 46121 | L9: =IF(A9<>"", TODAY() + (I9 /60/60) , "") -> 46127.4
A10: ='Оценка'!C20 -> Настройка централизованного логирования | B10: ='Оценка'!D20 | C10: =IF(A10<>"", 0, "") -> 0 | D10: =IF(A10<>"", 0, "") -> 0 | E10: =IF(A10<>"", 1, "") -> 1 | F10: =IF(A10<>"", 1, "") -> 1 | G10: =IF(A10<>"", 'Sales (Итоги оценки)'!$C$4, "") -> P2P платформа | H10: =IF(A10<>"", 1, "") -> 1 | I10: =IF(OR(ISBLANK('Оценка'!F20), ISBLANK('Оценка'!G20)), "", (AVERAGE( ( ('Оценка'!F20 + 4*AVERAGE('Оценка'!F20:G20) + 'Оценка'!G20)/6 - 2*(('Оценка'!G20 - 'Оценка'!F20)/6) )/5 , ( ('Оценка'!F20 + 4*AVERAGE('Оценка'!F20:G20) + 'Оценка'!G20)/6 + 2*(('Оценка'!G20 - 'Оценка'!F20)/6) )/5 ) * ( ( ('PM (Расчеты)'!$C$22/8 + 'PM (Расчеты)'!$C$23/40) + 'PM (Расчеты)'!$C$21/100 + 'PM (Расчеты)'!$C$25/100 + 'PM (Расчеты)'!$C$26/100 ) + 1 ))) * 8 * 60 * 60 -> 18432 | J10: ='Оценка'!B20 -> DevOps | K10: =IF(A10<>"", TODAY() , "") -> 46121 | L10: =IF(A10<>"", TODAY() + (I10 /60/60) , "") -> 46126.12
A11: ='Оценка'!C25 -> Деплой в testnet (Sepolia) | B11: ='Оценка'!D25 -> Factory + Implementation, верификация в Etherscan | C11: =IF(A11<>"", 0, "") -> 0 | D11: =IF(A11<>"", 0, "") -> 0 | E11: =IF(A11<>"", 1, "") -> 1 | F11: =IF(A11<>"", 1, "") -> 1 | G11: =IF(A11<>"", 'Sales (Итоги оценки)'!$C$4, "") -> P2P платформа | H11: =IF(A11<>"", 1, "") -> 1 | I11: =IF(OR(ISBLANK('Оценка'!F21), ISBLANK('Оценка'!G21)), "", (AVERAGE( ( ('Оценка'!F21 + 4*AVERAGE('Оценка'!F21:G21) + 'Оценка'!G21)/6 - 2*(('Оценка'!G21 - 'Оценка'!F21)/6) )/5 , ( ('Оценка'!F21 + 4*AVERAGE('Оценка'!F21:G21) + 'Оценка'!G21)/6 + 2*(('Оценка'!G21 - 'Оценка'!F21)/6) )/5 ) * ( ( ('PM (Расчеты)'!$C$22/8 + 'PM (Расчеты)'!$C$23/40) + 'PM (Расчеты)'!$C$21/100 + 'PM (Расчеты)'!$C$25/100 + 'PM (Расчеты)'!$C$26/100 ) + 1 ))) * 8 * 60 * 60 -> 0 | J11: ='Оценка'!B25 -> Smart contract | K11: =IF(A11<>"", TODAY() , "") -> 46121 | L11: =IF(A11<>"", TODAY() + (I11 /60/60) , "") -> 46121
A12: ='Оценка'!C26 -> Деплой в mainnet | B12: ='Оценка'!D26 -> Factory + Implementation, настройка мультисиг/Fireblocks | C12: =IF(A12<>"", 0, "") -> 0 | D12: =IF(A12<>"", 0, "") -> 0 | E12: =IF(A12<>"", 1, "") -> 1 | F12: =IF(A12<>"", 1, "") -> 1 | G12: =IF(A12<>"", 'Sales (Итоги оценки)'!$C$4, "") -> P2P платформа | H12: =IF(A12<>"", 1, "") -> 1 | I12: =IF(OR(ISBLANK('Оценка'!F22), ISBLANK('Оценка'!G22)), "", (AVERAGE( ( ('Оценка'!F22 + 4*AVERAGE('Оценка'!F22:G22) + 'Оценка'!G22)/6 - 2*(('Оценка'!G22 - 'Оценка'!F22)/6) )/5 , ( ('Оценка'!F22 + 4*AVERAGE('Оценка'!F22:G22) + 'Оценка'!G22)/6 + 2*(('Оценка'!G22 - 'Оценка'!F22)/6) )/5 ) * ( ( ('PM (Расчеты)'!$C$22/8 + 'PM (Расчеты)'!$C$23/40) + 'PM (Расчеты)'!$C$21/100 + 'PM (Расчеты)'!$C$25/100 + 'PM (Расчеты)'!$C$26/100 ) + 1 ))) * 8 * 60 * 60 -> 11520 | J12: ='Оценка'!B26 -> Smart contract | K12: =IF(A12<>"", TODAY() , "") -> 46121 | L12: =IF(A12<>"", TODAY() + (I12 /60/60) , "") -> 46124.2
A13: ='Оценка'!C27 -> Аудит безопасности | B13: ='Оценка'!D27 -> Внешний аудит, исправление найденных проблем | C13: =IF(A13<>"", 0, "") -> 0 | D13: =IF(A13<>"", 0, "") -> 0 | E13: =IF(A13<>"", 1, "") -> 1 | F13: =IF(A13<>"", 1, "") -> 1 | G13: =IF(A13<>"", 'Sales (Итоги оценки)'!$C$4, "") -> P2P платформа | H13: =IF(A13<>"", 1, "") -> 1 | I13: =IF(OR(ISBLANK('Оценка'!F23), ISBLANK('Оценка'!G23)), "", (AVERAGE( ( ('Оценка'!F23 + 4*AVERAGE('Оценка'!F23:G23) + 'Оценка'!G23)/6 - 2*(('Оценка'!G23 - 'Оценка'!F23)/6) )/5 , ( ('Оценка'!F23 + 4*AVERAGE('Оценка'!F23:G23) + 'Оценка'!G23)/6 + 2*(('Оценка'!G23 - 'Оценка'!F23)/6) )/5 ) * ( ( ('PM (Расчеты)'!$C$22/8 + 'PM (Расчеты)'!$C$23/40) + 'PM (Расчеты)'!$C$21/100 + 'PM (Расчеты)'!$C$25/100 + 'PM (Расчеты)'!$C$26/100 ) + 1 ))) * 8 * 60 * 60 -> 23040 | J13: ='Оценка'!B27 -> Smart contract | K13: =IF(A13<>"", TODAY() , "") -> 46121 | L13: =IF(A13<>"", TODAY() + (I13 /60/60) , "") -> 46127.4
A14: ='Оценка'!C28 -> Backend (Monolith): Инициализация NestJS проекта | B14: ='Оценка'!D28 | C14: =IF(A14<>"", 0, "") -> 0 | D14: =IF(A14<>"", 0, "") -> 0 | E14: =IF(A14<>"", 1, "") -> 1 | F14: =IF(A14<>"", 1, "") -> 1 | G14: =IF(A14<>"", 'Sales (Итоги оценки)'!$C$4, "") -> P2P платформа | H14: =IF(A14<>"", 1, "") -> 1 | I14: =IF(OR(ISBLANK('Оценка'!F24), ISBLANK('Оценка'!G24)), "", (AVERAGE( ( ('Оценка'!F24 + 4*AVERAGE('Оценка'!F24:G24) + 'Оценка'!G24)/6 - 2*(('Оценка'!G24 - 'Оценка'!F24)/6) )/5 , ( ('Оценка'!F24 + 4*AVERAGE('Оценка'!F24:G24) + 'Оценка'!G24)/6 + 2*(('Оценка'!G24 - 'Оценка'!F24)/6) )/5 ) * ( ( ('PM (Расчеты)'!$C$22/8 + 'PM (Расчеты)'!$C$23/40) + 'PM (Расчеты)'!$C$21/100 + 'PM (Расчеты)'!$C$25/100 + 'PM (Расчеты)'!$C$26/100 ) + 1 ))) * 8 * 60 * 60 -> 18432 | J14: ='Оценка'!B28 | K14: =IF(A14<>"", TODAY() , "") -> 46121 | L14: =IF(A14<>"", TODAY() + (I14 /60/60) , "") -> 46126.12
A15: ='Оценка'!C29 -> Настройка инфраструктуры | B15: ='Оценка'!D29 -> TypeORM (PostgreSQL), Redis, Bull Queue, валидация | C15: =IF(A15<>"", 0, "") -> 0 | D15: =IF(A15<>"", 0, "") -> 0 | E15: =IF(A15<>"", 1, "") -> 1 | F15: =IF(A15<>"", 1, "") -> 1 | G15: =IF(A15<>"", 'Sales (Итоги оценки)'!$C$4, "") -> P2P платформа | H15: =IF(A15<>"", 1, "") -> 1 | I15: =IF(OR(ISBLANK('Оценка'!F25), ISBLANK('Оценка'!G25)), "", (AVERAGE( ( ('Оценка'!F25 + 4*AVERAGE('Оценка'!F25:G25) + 'Оценка'!G25)/6 - 2*(('Оценка'!G25 - 'Оценка'!F25)/6) )/5 , ( ('Оценка'!F25 + 4*AVERAGE('Оценка'!F25:G25) + 'Оценка'!G25)/6 + 2*(('Оценка'!G25 - 'Оценка'!F25)/6) )/5 ) * ( ( ('PM (Расчеты)'!$C$22/8 + 'PM (Расчеты)'!$C$23/40) + 'PM (Расчеты)'!$C$21/100 + 'PM (Расчеты)'!$C$25/100 + 'PM (Расчеты)'!$C$26/100 ) + 1 ))) * 8 * 60 * 60 -> 4608 | J15: ='Оценка'!B29 -> Backend | K15: =IF(A15<>"", TODAY() , "") -> 46121 | L15: =IF(A15<>"", TODAY() + (I15 /60/60) , "") -> 46122.28
A16: ='Оценка'!C30 -> Разработка Shared Layer | B16: ='Оценка'!D30 -> Database Service, Cache Service, Queue Service, Auth Service | C16: =IF(A16<>"", 0, "") -> 0 | D16: =IF(A16<>"", 0, "") -> 0 | E16: =IF(A16<>"", 1, "") -> 1 | F16: =IF(A16<>"", 1, "") -> 1 | G16: =IF(A16<>"", 'Sales (Итоги оценки)'!$C$4, "") -> P2P платформа | H16: =IF(A16<>"", 1, "") -> 1 | I16: =IF(OR(ISBLANK('Оценка'!F26), ISBLANK('Оценка'!G26)), "", (AVERAGE( ( ('Оценка'!F26 + 4*AVERAGE('Оценка'!F26:G26) + 'Оценка'!G26)/6 - 2*(('Оценка'!G26 - 'Оценка'!F26)/6) )/5 , ( ('Оценка'!F26 + 4*AVERAGE('Оценка'!F26:G26) + 'Оценка'!G26)/6 + 2*(('Оценка'!G26 - 'Оценка'!F26)/6) )/5 ) * ( ( ('PM (Расчеты)'!$C$22/8 + 'PM (Расчеты)'!$C$23/40) + 'PM (Расчеты)'!$C$21/100 + 'PM (Расчеты)'!$C$25/100 + 'PM (Расчеты)'!$C$26/100 ) + 1 ))) * 8 * 60 * 60 -> 18432 | J16: ='Оценка'!B30 -> Backend | K16: =IF(A16<>"", TODAY() , "") -> 46121 | L16: =IF(A16<>"", TODAY() + (I16 /60/60) , "") -> 46126.12
A17: ='Оценка'!C31 -> Разработка Blockchain Service | B17: ='Оценка'!D31 -> Ethers.js интеграция, RPC, индексатор событий | C17: =IF(A17<>"", 0, "") -> 0 | D17: =IF(A17<>"", 0, "") -> 0 | E17: =IF(A17<>"", 1, "") -> 1 | F17: =IF(A17<>"", 1, "") -> 1 | G17: =IF(A17<>"", 'Sales (Итоги оценки)'!$C$4, "") -> P2P платформа | H17: =IF(A17<>"", 1, "") -> 1 | I17: =IF(OR(ISBLANK('Оценка'!F27), ISBLANK('Оценка'!G27)), "", (AVERAGE( ( ('Оценка'!F27 + 4*AVERAGE('Оценка'!F27:G27) + 'Оценка'!G27)/6 - 2*(('Оценка'!G27 - 'Оценка'!F27)/6) )/5 , ( ('Оценка'!F27 + 4*AVERAGE('Оценка'!F27:G27) + 'Оценка'!G27)/6 + 2*(('Оценка'!G27 - 'Оценка'!F27)/6) )/5 ) * ( ( ('PM (Расчеты)'!$C$22/8 + 'PM (Расчеты)'!$C$23/40) + 'PM (Расчеты)'!$C$21/100 + 'PM (Расчеты)'!$C$25/100 + 'PM (Расчеты)'!$C$26/100 ) + 1 ))) * 8 * 60 * 60 -> 9216 | J17: ='Оценка'!B31 -> Backend | K17: =IF(A17<>"", TODAY() , "") -> 46121 | L17: =IF(A17<>"", TODAY() + (I17 /60/60) , "") -> 46123.56
A18: ='Оценка'!C32 -> Разработка Encryption Service | B18: ='Оценка'!D32 -> AES-256 для шифрования реквизитов | C18: =IF(A18<>"", 0, "") -> 0 | D18: =IF(A18<>"", 0, "") -> 0 | E18: =IF(A18<>"", 1, "") -> 1 | F18: =IF(A18<>"", 1, "") -> 1 | G18: =IF(A18<>"", 'Sales (Итоги оценки)'!$C$4, "") -> P2P платформа | H18: =IF(A18<>"", 1, "") -> 1 | I18: =IF(OR(ISBLANK('Оценка'!F28), ISBLANK('Оценка'!G28)), "", (AVERAGE( ( ('Оценка'!F28 + 4*AVERAGE('Оценка'!F28:G28) + 'Оценка'!G28)/6 - 2*(('Оценка'!G28 - 'Оценка'!F28)/6) )/5 , ( ('Оценка'!F28 + 4*AVERAGE('Оценка'!F28:G28) + 'Оценка'!G28)/6 + 2*(('Оценка'!G28 - 'Оценка'!F28)/6) )/5 ) * ( ( ('PM (Расчеты)'!$C$22/8 + 'PM (Расчеты)'!$C$23/40) + 'PM (Расчеты)'!$C$21/100 + 'PM (Расчеты)'!$C$25/100 + 'PM (Расчеты)'!$C$26/100 ) + 1 ))) * 8 * 60 * 60 -> 0 | J18: ='Оценка'!B32 -> Backend | K18: =IF(A18<>"", TODAY() , "") -> 46121 | L18: =IF(A18<>"", TODAY() + (I18 /60/60) , "") -> 46121
A19: ='Оценка'!C33 -> Backend (Monolith): User Module | B19: ='Оценка'!D33 | C19: =IF(A19<>"", 0, "") -> 0 | D19: =IF(A19<>"", 0, "") -> 0 | E19: =IF(A19<>"", 1, "") -> 1 | F19: =IF(A19<>"", 1, "") -> 1 | G19: =IF(A19<>"", 'Sales (Итоги оценки)'!$C$4, "") -> P2P платформа | H19: =IF(A19<>"", 1, "") -> 1 | I19: =IF(OR(ISBLANK('Оценка'!F29), ISBLANK('Оценка'!G29)), "", (AVERAGE( ( ('Оценка'!F29 + 4*AVERAGE('Оценка'!F29:G29) + 'Оценка'!G29)/6 - 2*(('Оценка'!G29 - 'Оценка'!F29)/6) )/5 , ( ('Оценка'!F29 + 4*AVERAGE('Оценка'!F29:G29) + 'Оценка'!G29)/6 + 2*(('Оценка'!G29 - 'Оценка'!F29)/6) )/5 ) * ( ( ('PM (Расчеты)'!$C$22/8 + 'PM (Расчеты)'!$C$23/40) + 'PM (Расчеты)'!$C$21/100 + 'PM (Расчеты)'!$C$25/100 + 'PM (Расчеты)'!$C$26/100 ) + 1 ))) * 8 * 60 * 60 -> 23040 | J19: ='Оценка'!B33 | K19: =IF(A19<>"", TODAY() , "") -> 46121 | L19: =IF(A19<>"", TODAY() + (I19 /60/60) , "") -> 46127.4
A20: ='Оценка'!C34 -> Создание сущностей | B20: ='Оценка'!D34 -> User (с полями реферальной программы: referrer_id, referrer_wallet, referral_code), Wallet, KycStatus, UserLevel — таблицы, связи, индексы | C20: =IF(A20<>"", 0, "") -> 0 | D20: =IF(A20<>"", 0, "") -> 0 | E20: =IF(A20<>"", 1, "") -> 1 | F20: =IF(A20<>"", 1, "") -> 1 | G20: =IF(A20<>"", 'Sales (Итоги оценки)'!$C$4, "") -> P2P платформа | H20: =IF(A20<>"", 1, "") -> 1 | I20: =IF(OR(ISBLANK('Оценка'!F30), ISBLANK('Оценка'!G30)), "", (AVERAGE( ( ('Оценка'!F30 + 4*AVERAGE('Оценка'!F30:G30) + 'Оценка'!G30)/6 - 2*(('Оценка'!G30 - 'Оценка'!F30)/6) )/5 , ( ('Оценка'!F30 + 4*AVERAGE('Оценка'!F30:G30) + 'Оценка'!G30)/6 + 2*(('Оценка'!G30 - 'Оценка'!F30)/6) )/5 ) * ( ( ('PM (Расчеты)'!$C$22/8 + 'PM (Расчеты)'!$C$23/40) + 'PM (Расчеты)'!$C$21/100 + 'PM (Расчеты)'!$C$25/100 + 'PM (Расчеты)'!$C$26/100 ) + 1 ))) * 8 * 60 * 60 -> 23040 | J20: ='Оценка'!B34 -> Backend | K20: =IF(A20<>"", TODAY() , "") -> 46121 | L20: =IF(A20<>"", TODAY() + (I20 /60/60) , "") -> 46127.4
A21: ='Оценка'!C35 -> Разработка API | B21: ='Оценка'!D35 -> Регистрация, авторизация (Web3 + JWT), профиль, привязка кошелька | C21: =IF(A21<>"", 0, "") -> 0 | D21: =IF(A21<>"", 0, "") -> 0 | E21: =IF(A21<>"", 1, "") -> 1 | F21: =IF(A21<>"", 1, "") -> 1 | G21: =IF(A21<>"", 'Sales (Итоги оценки)'!$C$4, "") -> P2P платформа | H21: =IF(A21<>"", 1, "") -> 1 | I21: =IF(OR(ISBLANK('Оценка'!F31), ISBLANK('Оценка'!G31)), "", (AVERAGE( ( ('Оценка'!F31 + 4*AVERAGE('Оценка'!F31:G31) + 'Оценка'!G31)/6 - 2*(('Оценка'!G31 - 'Оценка'!F31)/6) )/5 , ( ('Оценка'!F31 + 4*AVERAGE('Оценка'!F31:G31) + 'Оценка'!G31)/6 + 2*(('Оценка'!G31 - 'Оценка'!F31)/6) )/5 ) * ( ( ('PM (Расчеты)'!$C$22/8 + 'PM (Расчеты)'!$C$23/40) + 'PM (Расчеты)'!$C$21/100 + 'PM (Расчеты)'!$C$25/100 + 'PM (Расчеты)'!$C$26/100 ) + 1 ))) * 8 * 60 * 60 -> 23040 | J21: ='Оценка'!B35 -> Backend | K21: =IF(A21<>"", TODAY() , "") -> 46121 | L21: =IF(A21<>"", TODAY() + (I21 /60/60) , "") -> 46127.4
A22: ='Оценка'!C36 -> Реализация уровней доступа | B22: ='Оценка'!D36 -> Проверка прав, лимиты | C22: =IF(A22<>"", 0, "") -> 0 | D22: =IF(A22<>"", 0, "") -> 0 | E22: =IF(A22<>"", 1, "") -> 1 | F22: =IF(A22<>"", 1, "") -> 1 | G22: =IF(A22<>"", 'Sales (Итоги оценки)'!$C$4, "") -> P2P платформа | H22: =IF(A22<>"", 1, "") -> 1 | I22: =IF(OR(ISBLANK('Оценка'!F32), ISBLANK('Оценка'!G32)), "", (AVERAGE( ( ('Оценка'!F32 + 4*AVERAGE('Оценка'!F32:G32) + 'Оценка'!G32)/6 - 2*(('Оценка'!G32 - 'Оценка'!F32)/6) )/5 , ( ('Оценка'!F32 + 4*AVERAGE('Оценка'!F32:G32) + 'Оценка'!G32)/6 + 2*(('Оценка'!G32 - 'Оценка'!F32)/6) )/5 ) * ( ( ('PM (Расчеты)'!$C$22/8 + 'PM (Расчеты)'!$C$23/40) + 'PM (Расчеты)'!$C$21/100 + 'PM (Расчеты)'!$C$25/100 + 'PM (Расчеты)'!$C$26/100 ) + 1 ))) * 8 * 60 * 60 -> 13824 | J22: ='Оценка'!B36 -> Backend | K22: =IF(A22<>"", TODAY() , "") -> 46121 | L22: =IF(A22<>"", TODAY() + (I22 /60/60) , "") -> 46124.84
... A40: ='Оценка'!C54 -> Подключение стороннего сервиса аналитики | B40: ='Оценка'!D54 -> Redash или др | C40: =IF(A40<>"", 0, "") -> 0 | D40: =IF(A40<>"", 0, "") -> 0 | E40: =IF(A40<>"", 1, "") -> 1 | F40: =IF(A40<>"", 1, "") -> 1 | G40: =IF(A40<>"", 'Sales (Итоги оценки)'!$C$4, "") -> P2P платформа | H40: =IF(A40<>"", 1, "") -> 1 | I40: =IF(OR(ISBLANK('Оценка'!F50), ISBLANK('Оценка'!G50)), "", (AVERAGE( ( ('Оценка'!F50 + 4*AVERAGE('Оценка'!F50:G50) + 'Оценка'!G50)/6 - 2*(('Оценка'!G50 - 'Оценка'!F50)/6) )/5 , ( ('Оценка'!F50 + 4*AVERAGE('Оценка'!F50:G50) + 'Оценка'!G50)/6 + 2*(('Оценка'!G50 - 'Оценка'!F50)/6) )/5 ) * ( ( ('PM (Расчеты)'!$C$22/8 + 'PM (Расчеты)'!$C$23/40) + 'PM (Расчеты)'!$C$21/100 + 'PM (Расчеты)'!$C$25/100 + 'PM (Расчеты)'!$C$26/100 ) + 1 ))) * 8 * 60 * 60 -> 0 | J40: ='Оценка'!B54 -> Backend | K40: =IF(A40<>"", TODAY() , "") -> 46121 | L40: =IF(A40<>"", TODAY() + (I40 /60/60) , "") -> 46121
A41: =#REF! -> #REF! | B41: =#REF! -> #REF! | C41: =IF(A41<>"", 0, "") -> #REF! | D41: =IF(A41<>"", 0, "") -> #REF! | E41: =IF(A41<>"", 1, "") -> #REF! | F41: =IF(A41<>"", 1, "") -> #REF! | G41: =IF(A41<>"", 'Sales (Итоги оценки)'!$C$4, "") -> #REF! | H41: =IF(A41<>"", 1, "") -> #REF! | I41: =IF(OR(ISBLANK('Оценка'!F51), ISBLANK('Оценка'!G51)), "", (AVERAGE( ( ('Оценка'!F51 + 4*AVERAGE('Оценка'!F51:G51) + 'Оценка'!G51)/6 - 2*(('Оценка'!G51 - 'Оценка'!F51)/6) )/5 , ( ('Оценка'!F51 + 4*AVERAGE('Оценка'!F51:G51) + 'Оценка'!G51)/6 + 2*(('Оценка'!G51 - 'Оценка'!F51)/6) )/5 ) * ( ( ('PM (Расчеты)'!$C$22/8 + 'PM (Расчеты)'!$C$23/40) + 'PM (Расчеты)'!$C$21/100 + 'PM (Расчеты)'!$C$25/100 + 'PM (Расчеты)'!$C$26/100 ) + 1 ))) * 8 * 60 * 60 -> 9216 | J41: =#REF! -> #REF! | K41: =IF(A41<>"", TODAY() , "") -> #REF! | L41: =IF(A41<>"", TODAY() + (I41 /60/60) , "") -> #REF!
A42: =#REF! -> #REF! | B42: =#REF! -> #REF! | C42: =IF(A42<>"", 0, "") -> #REF! | D42: =IF(A42<>"", 0, "") -> #REF! | E42: =IF(A42<>"", 1, "") -> #REF! | F42: =IF(A42<>"", 1, "") -> #REF! | G42: =IF(A42<>"", 'Sales (Итоги оценки)'!$C$4, "") -> #REF! | H42: =IF(A42<>"", 1, "") -> #REF! | I42: =IF(OR(ISBLANK('Оценка'!F52), ISBLANK('Оценка'!G52)), "", (AVERAGE( ( ('Оценка'!F52 + 4*AVERAGE('Оценка'!F52:G52) + 'Оценка'!G52)/6 - 2*(('Оценка'!G52 - 'Оценка'!F52)/6) )/5 , ( ('Оценка'!F52 + 4*AVERAGE('Оценка'!F52:G52) + 'Оценка'!G52)/6 + 2*(('Оценка'!G52 - 'Оценка'!F52)/6) )/5 ) * ( ( ('PM (Расчеты)'!$C$22/8 + 'PM (Расчеты)'!$C$23/40) + 'PM (Расчеты)'!$C$21/100 + 'PM (Расчеты)'!$C$25/100 + 'PM (Расчеты)'!$C$26/100 ) + 1 ))) * 8 * 60 * 60 -> 13824 | J42: =#REF! -> #REF! | K42: =IF(A42<>"", TODAY() , "") -> #REF! | L42: =IF(A42<>"", TODAY() + (I42 /60/60) , "") -> #REF!
