Workbook

Sheet Общая смета
B1: ПРЕДВАРИТЕЛЬНАЯ ОЦЕНКА ТРУДОЗАТРАТ НА АГРЕГАТОР DEX В ТЕЛЕГРАМЕ
A2: ФАЗИРОВАНИЕ | D2: DISCOVERY | H2: DEVELOPMENT | L2: DELIVERY
A3: # | B3: Команда * | C3: Раз. | D3: О. Часы | E3: П. Часы | F3: О. Цена | G3: П. Цена | H3: О. Часы | I3: П. Часы | J3: О. Цена | K3: П. Цена | L3: О. Часы | M3: П. Часы | N3: О. Цена | O3: П. Цена
A4: 1 | B4: Анализ | C4: 1 | D4: =ROUNDUP( SUMIF('Анализ'!$D$4:'Анализ'!$D9, "DISCOVERY", 'Анализ'!E$4:'Анализ'!E9) + (SUMIF('Анализ'!$D$4:'Анализ'!$D9, "SPREAD", 'Анализ'!E$4:'Анализ'!E9) * ($D$14 / ($D$14+$H$14+$L$14))) + (SUMIF('Анализ'!$D$4:'Анализ'!$D9, "DIS & DEV", 'Анализ'!E$4:'Анализ'!E9) * ($D$14 / ($D$14+$H$14))),0) -> 78 | E4: =ROUNDUP( SUMIF('Анализ'!$D$4:'Анализ'!$D9, "DISCOVERY", 'Анализ'!F$4:'Анализ'!F9) + (SUMIF('Анализ'!$D$4:'Анализ'!$D9, "SPREAD", 'Анализ'!F$4:'Анализ'!F9) * ($D$14 / ($D$14+$H$14+$L$14))) + (SUMIF('Анализ'!$D$4:'Анализ'!$D9, "DIS & DEV", 'Анализ'!F$4:'Анализ'!F9) * ($D$14 / ($D$14+$H$14))),0) -> 95 | F4: =ROUNDUP( SUMIF('Анализ'!$D$4:'Анализ'!$D9, "DISCOVERY", 'Анализ'!G$4:'Анализ'!G9) + (SUMIF('Анализ'!$D$4:'Анализ'!$D9, "SPREAD", 'Анализ'!G$4:'Анализ'!G9) * ($D$14 / ($D$14+$H$14+$L$14))) + (SUMIF('Анализ'!$D$4:'Анализ'!$D9, "DIS & DEV", 'Анализ'!G$4:'Анализ'!G9) * ($D$14 / ($D$14+$H$14))),0) -> 3237 | G4: =ROUNDUP( SUMIF('Анализ'!$D$4:'Анализ'!$D9, "DISCOVERY", 'Анализ'!H$4:'Анализ'!H9) + (SUMIF('Анализ'!$D$4:'Анализ'!$D9, "SPREAD", 'Анализ'!H$4:'Анализ'!H9) * ($D$14 / ($D$14+$H$14+$L$14))) + (SUMIF('Анализ'!$D$4:'Анализ'!$D9, "DIS & DEV", 'Анализ'!H$4:'Анализ'!H9) * ($D$14 / ($D$14+$H$14))),0) -> 3962 | H4: =ROUNDUP( SUMIF('Анализ'!$D$4:'Анализ'!$D9, "DEVELOPMENT", 'Анализ'!E$4:'Анализ'!E9) + (SUMIF('Анализ'!$D$4:'Анализ'!$D9, "SPREAD", 'Анализ'!E$4:'Анализ'!E9) * ($H$14 / ($D$14+$H$14+$L$14))) + (SUMIF('Анализ'!$D$4:'Анализ'!$D9, "DIS & DEV", 'Анализ'!E$4:'Анализ'!E9) * ($H$14 / ($D$14+$H$14))) + (SUMIF('Анализ'!$D$4:'Анализ'!$D9, "DEV & DEL", 'Анализ'!E$4:'Анализ'!E9) * ($H$14 / ($L$14+$H$14))),0) -> 38 | I4: =ROUNDUP( SUMIF('Анализ'!$D$4:'Анализ'!$D9, "DEVELOPMENT", 'Анализ'!F$4:'Анализ'!F9) + (SUMIF('Анализ'!$D$4:'Анализ'!$D9, "SPREAD", 'Анализ'!F$4:'Анализ'!F9) * ($H$14 / ($D$14+$H$14+$L$14))) + (SUMIF('Анализ'!$D$4:'Анализ'!$D9, "DIS & DEV", 'Анализ'!F$4:'Анализ'!F9) * ($H$14 / ($D$14+$H$14))) + (SUMIF('Анализ'!$D$4:'Анализ'!$D9, "DEV & DEL", 'Анализ'!F$4:'Анализ'!F9) * ($H$14 / ($L$14+$H$14))),0) -> 50 | J4: =ROUNDUP( SUMIF('Анализ'!$D$4:'Анализ'!$D9, "DEVELOPMENT", 'Анализ'!G$4:'Анализ'!G9) + (SUMIF('Анализ'!$D$4:'Анализ'!$D9, "SPREAD", 'Анализ'!G$4:'Анализ'!G9) * ($H$14 / ($D$14+$H$14+$L$14))) + (SUMIF('Анализ'!$D$4:'Анализ'!$D9, "DIS & DEV", 'Анализ'!G$4:'Анализ'!G9) * ($H$14 / ($D$14+$H$14))) + (SUMIF('Анализ'!$D$4:'Анализ'!$D9, "DEV & DEL", 'Анализ'!G$4:'Анализ'!G9) * ($H$14 / ($L$14+$H$14))),0) -> 1588 | K4: =ROUNDUP( SUMIF('Анализ'!$D$4:'Анализ'!$D9, "DEVELOPMENT", 'Анализ'!H$4:'Анализ'!H9) + (SUMIF('Анализ'!$D$4:'Анализ'!$D9, "SPREAD", 'Анализ'!H$4:'Анализ'!H9) * ($H$14 / ($D$14+$H$14+$L$14))) + (SUMIF('Анализ'!$D$4:'Анализ'!$D9, "DIS & DEV", 'Анализ'!H$4:'Анализ'!H9) * ($H$14 / ($D$14+$H$14))) + (SUMIF('Анализ'!$D$4:'Анализ'!$D9, "DEV & DEL", 'Анализ'!H$4:'Анализ'!H9) * ($H$14 / ($L$14+$H$14))),0) -> 2082 | L4: =ROUNDUP( SUMIF('Анализ'!$D$4:'Анализ'!$D9, "DELIVERY", 'Анализ'!E$4:'Анализ'!E9) + (SUMIF('Анализ'!$D$4:'Анализ'!$D9, "SPREAD", 'Анализ'!E$4:'Анализ'!E9) * ($L$14 / ($D$14+$H$14+$L$14))) + (SUMIF('Анализ'!$D$4:'Анализ'!$D9, "DEV & DEL", 'Анализ'!E$4:'Анализ'!E9) * ($L$14 / ($L$14+$H$14))),0) -> 4 | M4: =ROUNDUP( SUMIF('Анализ'!$D$4:'Анализ'!$D9, "DELIVERY", 'Анализ'!F$4:'Анализ'!F9) + (SUMIF('Анализ'!$D$4:'Анализ'!$D9, "SPREAD", 'Анализ'!F$4:'Анализ'!F9) * ($L$14 / ($D$14+$H$14+$L$14))) + (SUMIF('Анализ'!$D$4:'Анализ'!$D9, "DEV & DEL", 'Анализ'!F$4:'Анализ'!F9) * ($L$14 / ($L$14+$H$14))),0) -> 5 | N4: =ROUNDUP( SUMIF('Анализ'!$D$4:'Анализ'!$D9, "DELIVERY", 'Анализ'!G$4:'Анализ'!G9) + (SUMIF('Анализ'!$D$4:'Анализ'!$D9, "SPREAD", 'Анализ'!G$4:'Анализ'!G9) * ($L$14 / ($D$14+$H$14+$L$14))) + (SUMIF('Анализ'!$D$4:'Анализ'!$D9, "DEV & DEL", 'Анализ'!G$4:'Анализ'!G9) * ($L$14 / ($L$14+$H$14))),0) -> 133 | O4: =ROUNDUP( SUMIF('Анализ'!$D$4:'Анализ'!$D9, "DELIVERY", 'Анализ'!H$4:'Анализ'!H9) + (SUMIF('Анализ'!$D$4:'Анализ'!$D9, "SPREAD", 'Анализ'!H$4:'Анализ'!H9) * ($L$14 / ($D$14+$H$14+$L$14))) + (SUMIF('Анализ'!$D$4:'Анализ'!$D9, "DEV & DEL", 'Анализ'!H$4:'Анализ'!H9) * ($L$14 / ($L$14+$H$14))),0) -> 174
A5: 2 | B5: Дизайн | C5: 1 | D5: =ROUNDUP( SUMIF('Дизайн'!$D$4:'Дизайн'!$D26, "DISCOVERY", 'Дизайн'!E$4:'Дизайн'!E26) + (SUMIF('Дизайн'!$D$4:'Дизайн'!$D26, "SPREAD", 'Дизайн'!E$4:'Дизайн'!E26) * ($D$14 / ($D$14+$H$14+$L$14))) + (SUMIF('Дизайн'!$D$4:'Дизайн'!$D26, "DIS & DEV", 'Дизайн'!E$4:'Дизайн'!E26) * ($D$14 / ($D$14+$H$14))),0) -> 77 | E5: =ROUNDUP( SUMIF('Дизайн'!$D$4:'Дизайн'!$D26, "DISCOVERY", 'Дизайн'!F$4:'Дизайн'!F26) + (SUMIF('Дизайн'!$D$4:'Дизайн'!$D26, "SPREAD", 'Дизайн'!F$4:'Дизайн'!F26) * ($D$14 / ($D$14+$H$14+$L$14))) + (SUMIF('Дизайн'!$D$4:'Дизайн'!$D26, "DIS & DEV", 'Дизайн'!F$4:'Дизайн'!F26) * ($D$14 / ($D$14+$H$14))),0) -> 108 | F5: =ROUNDUP( SUMIF('Дизайн'!$D$4:'Дизайн'!$D26, "DISCOVERY", 'Дизайн'!G$4:'Дизайн'!G26) + (SUMIF('Дизайн'!$D$4:'Дизайн'!$D26, "SPREAD", 'Дизайн'!G$4:'Дизайн'!G26) * ($D$14 / ($D$14+$H$14+$L$14))) + (SUMIF('Дизайн'!$D$4:'Дизайн'!$D26, "DIS & DEV", 'Дизайн'!G$4:'Дизайн'!G26) * ($D$14 / ($D$14+$H$14))),0) -> 3450 | G5: =ROUNDUP( SUMIF('Дизайн'!$D$4:'Дизайн'!$D26, "DISCOVERY", 'Дизайн'!H$4:'Дизайн'!H26) + (SUMIF('Дизайн'!$D$4:'Дизайн'!$D26, "SPREAD", 'Дизайн'!H$4:'Дизайн'!H26) * ($D$14 / ($D$14+$H$14+$L$14))) + (SUMIF('Дизайн'!$D$4:'Дизайн'!$D26, "DIS & DEV", 'Дизайн'!H$4:'Дизайн'!H26) * ($D$14 / ($D$14+$H$14))),0) -> 4830 | H5: =ROUNDUP( SUMIF('Дизайн'!$D$4:'Дизайн'!$D26, "DEVELOPMENT", 'Дизайн'!E$4:'Дизайн'!E26) + (SUMIF('Дизайн'!$D$4:'Дизайн'!$D26, "SPREAD", 'Дизайн'!E$4:'Дизайн'!E26) * ($H$14 / ($D$14+$H$14+$L$14))) + (SUMIF('Дизайн'!$D$4:'Дизайн'!$D26, "DIS & DEV", 'Дизайн'!E$4:'Дизайн'!E26) * ($H$14 / ($D$14+$H$14))) + (SUMIF('Дизайн'!$D$4:'Дизайн'!$D26, "DEV & DEL", 'Дизайн'!E$4:'Дизайн'!E26) * ($H$14 / ($H$14+$L$14))),0) -> 104 | I5: =ROUNDUP( SUMIF('Дизайн'!$D$4:'Дизайн'!$D26, "DEVELOPMENT", 'Дизайн'!F$4:'Дизайн'!F26) + (SUMIF('Дизайн'!$D$4:'Дизайн'!$D26, "SPREAD", 'Дизайн'!F$4:'Дизайн'!F26) * ($H$14 / ($D$14+$H$14+$L$14))) + (SUMIF('Дизайн'!$D$4:'Дизайн'!$D26, "DIS & DEV", 'Дизайн'!F$4:'Дизайн'!F26) * ($H$14 / ($D$14+$H$14))) + (SUMIF('Дизайн'!$D$4:'Дизайн'!$D26, "DEV & DEL", 'Дизайн'!F$4:'Дизайн'!F26) * ($H$14 / ($H$14+$L$14))),0) -> 135 | J5: =ROUNDUP( SUMIF('Дизайн'!$D$4:'Дизайн'!$D26, "DEVELOPMENT", 'Дизайн'!G$4:'Дизайн'!G26) + (SUMIF('Дизайн'!$D$4:'Дизайн'!$D26, "SPREAD", 'Дизайн'!G$4:'Дизайн'!G26) * ($H$14 / ($D$14+$H$14+$L$14))) + (SUMIF('Дизайн'!$D$4:'Дизайн'!$D26, "DIS & DEV", 'Дизайн'!G$4:'Дизайн'!G26) * ($H$14 / ($D$14+$H$14))) + (SUMIF('Дизайн'!$D$4:'Дизайн'!$D26, "DEV & DEL", 'Дизайн'!G$4:'Дизайн'!G26) * ($H$14 / ($H$14+$L$14))),0) -> 4650 | K5: =ROUNDUP( SUMIF('Дизайн'!$D$4:'Дизайн'!$D26, "DEVELOPMENT", 'Дизайн'!H$4:'Дизайн'!H26) + (SUMIF('Дизайн'!$D$4:'Дизайн'!$D26, "SPREAD", 'Дизайн'!H$4:'Дизайн'!H26) * ($H$14 / ($D$14+$H$14+$L$14))) + (SUMIF('Дизайн'!$D$4:'Дизайн'!$D26, "DIS & DEV", 'Дизайн'!H$4:'Дизайн'!H26) * ($H$14 / ($D$14+$H$14))) + (SUMIF('Дизайн'!$D$4:'Дизайн'!$D26, "DEV & DEL", 'Дизайн'!H$4:'Дизайн'!H26) * ($H$14 / ($H$14+$L$14))),0) -> 6060 | L5: =ROUNDUP( SUMIF('Дизайн'!$D$4:'Дизайн'!$D26, "DELIVERY", 'Дизайн'!E$4:'Дизайн'!E26) + (SUMIF('Дизайн'!$D$4:'Дизайн'!$D26, "SPREAD", 'Дизайн'!E$4:'Дизайн'!E26) * ($L$14 / ($D$14+$H$14+$L$14))) + (SUMIF('Дизайн'!$D$4:'Дизайн'!$D26, "DEV & DEL", 'Дизайн'!E$4:'Дизайн'!E26) * ($L$14 / ($H$14+$L$14))),0) -> 0 | M5: =ROUNDUP( SUMIF('Дизайн'!$D$4:'Дизайн'!$D26, "DELIVERY", 'Дизайн'!F$4:'Дизайн'!F26) + (SUMIF('Дизайн'!$D$4:'Дизайн'!$D26, "SPREAD", 'Дизайн'!F$4:'Дизайн'!F26) * ($L$14 / ($D$14+$H$14+$L$14))) + (SUMIF('Дизайн'!$D$4:'Дизайн'!$D26, "DEV & DEL", 'Дизайн'!F$4:'Дизайн'!F26) * ($L$14 / ($H$14+$L$14))),0) -> 0 | N5: =ROUNDUP( SUMIF('Дизайн'!$D$4:'Дизайн'!$D26, "DELIVERY", 'Дизайн'!G$4:'Дизайн'!G26) + (SUMIF('Дизайн'!$D$4:'Дизайн'!$D26, "SPREAD", 'Дизайн'!G$4:'Дизайн'!G26) * ($L$14 / ($D$14+$H$14+$L$14))) + (SUMIF('Дизайн'!$D$4:'Дизайн'!$D26, "DEV & DEL", 'Дизайн'!G$4:'Дизайн'!G26) * ($L$14 / ($H$14+$L$14))),0) -> 0 | O5: =ROUNDUP( SUMIF('Дизайн'!$D$4:'Дизайн'!$D26, "DELIVERY", 'Дизайн'!H$4:'Дизайн'!H26) + (SUMIF('Дизайн'!$D$4:'Дизайн'!$D26, "SPREAD", 'Дизайн'!H$4:'Дизайн'!H26) * ($L$14 / ($D$14+$H$14+$L$14))) + (SUMIF('Дизайн'!$D$4:'Дизайн'!$D26, "DEV & DEL", 'Дизайн'!H$4:'Дизайн'!H26) * ($L$14 / ($H$14+$L$14))),0) -> 0
A6: 3 | B6: Фронтенд-разработка | C6: 2 | D6: =ROUNDUP( SUMIF('Фронтенд'!$D$4:'Фронтенд'!$D30, "DISCOVERY", 'Фронтенд'!E$4:'Фронтенд'!E30) + (SUMIF('Фронтенд'!$D$4:'Фронтенд'!$D30, "SPREAD", 'Фронтенд'!E$4:'Фронтенд'!E30) * ($D$14 / ($D$14+$H$14+$L$14))) + (SUMIF('Фронтенд'!$D$4:'Фронтенд'!$D30, "DIS & DEV", 'Фронтенд'!E$4:'Фронтенд'!E30) * ($D$14 / ($D$14+$H$14))),0) -> 4 | E6: =ROUNDUP( SUMIF('Фронтенд'!$D$4:'Фронтенд'!$D30, "DISCOVERY", 'Фронтенд'!F$4:'Фронтенд'!F30) + (SUMIF('Фронтенд'!$D$4:'Фронтенд'!$D30, "SPREAD", 'Фронтенд'!F$4:'Фронтенд'!F30) * ($D$14 / ($D$14+$H$14+$L$14))) + (SUMIF('Фронтенд'!$D$4:'Фронтенд'!$D30, "DIS & DEV", 'Фронтенд'!F$4:'Фронтенд'!F30) * ($D$14 / ($D$14+$H$14))),0) -> 6 | F6: =ROUNDUP( SUMIF('Фронтенд'!$D$4:'Фронтенд'!$D30, "DISCOVERY", 'Фронтенд'!G$4:'Фронтенд'!G30) + (SUMIF('Фронтенд'!$D$4:'Фронтенд'!$D30, "SPREAD", 'Фронтенд'!G$4:'Фронтенд'!G30) * ($D$14 / ($D$14+$H$14+$L$14))) + (SUMIF('Фронтенд'!$D$4:'Фронтенд'!$D30, "DIS & DEV", 'Фронтенд'!G$4:'Фронтенд'!G30) * ($D$14 / ($D$14+$H$14))),0) -> 200 | G6: =ROUNDUP( SUMIF('Фронтенд'!$D$4:'Фронтенд'!$D30, "DISCOVERY", 'Фронтенд'!H$4:'Фронтенд'!H30) + (SUMIF('Фронтенд'!$D$4:'Фронтенд'!$D30, "SPREAD", 'Фронтенд'!H$4:'Фронтенд'!H30) * ($D$14 / ($D$14+$H$14+$L$14))) + (SUMIF('Фронтенд'!$D$4:'Фронтенд'!$D30, "DIS & DEV", 'Фронтенд'!H$4:'Фронтенд'!H30) * ($D$14 / ($D$14+$H$14))),0) -> 300 | H6: =ROUNDUP( SUMIF('Фронтенд'!$D$4:'Фронтенд'!$D30, "DEVELOPMENT", 'Фронтенд'!E$4:'Фронтенд'!E30) + (SUMIF('Фронтенд'!$D$4:'Фронтенд'!$D30, "SPREAD", 'Фронтенд'!E$4:'Фронтенд'!E30) * ($H$14 / ($D$14+$H$14+$L$14))) + (SUMIF('Фронтенд'!$D$4:'Фронтенд'!$D30, "DIS & DEV", 'Фронтенд'!E$4:'Фронтенд'!E30) * ($H$14 / ($D$14+$H$14))) + (SUMIF('Фронтенд'!$D$4:'Фронтенд'!$D30, "DEV & DEL", 'Фронтенд'!E$4:'Фронтенд'!E30) * ($H$14 / ($H$14+$L$14))),0) -> 729 | I6: =ROUNDUP( SUMIF('Фронтенд'!$D$4:'Фронтенд'!$D30, "DEVELOPMENT", 'Фронтенд'!F$4:'Фронтенд'!F30) + (SUMIF('Фронтенд'!$D$4:'Фронтенд'!$D30, "SPREAD", 'Фронтенд'!F$4:'Фронтенд'!F30) * ($H$14 / ($D$14+$H$14+$L$14))) + (SUMIF('Фронтенд'!$D$4:'Фронтенд'!$D30, "DIS & DEV", 'Фронтенд'!F$4:'Фронтенд'!F30) * ($H$14 / ($D$14+$H$14))) + (SUMIF('Фронтенд'!$D$4:'Фронтенд'!$D30, "DEV & DEL", 'Фронтенд'!F$4:'Фронтенд'!F30) * ($H$14 / ($H$14+$L$14))),0) -> 870 | J6: =ROUNDUP( SUMIF('Фронтенд'!$D$4:'Фронтенд'!$D30, "DEVELOPMENT", 'Фронтенд'!G$4:'Фронтенд'!G30) + (SUMIF('Фронтенд'!$D$4:'Фронтенд'!$D30, "SPREAD", 'Фронтенд'!G$4:'Фронтенд'!G30) * ($H$14 / ($D$14+$H$14+$L$14))) + (SUMIF('Фронтенд'!$D$4:'Фронтенд'!$D30, "DIS & DEV", 'Фронтенд'!G$4:'Фронтенд'!G30) * ($H$14 / ($D$14+$H$14))) + (SUMIF('Фронтенд'!$D$4:'Фронтенд'!$D30, "DEV & DEL", 'Фронтенд'!G$4:'Фронтенд'!G30) * ($H$14 / ($H$14+$L$14))),0) -> 36431 | K6: =ROUNDUP( SUMIF('Фронтенд'!$D$4:'Фронтенд'!$D30, "DEVELOPMENT", 'Фронтенд'!H$4:'Фронтенд'!H30) + (SUMIF('Фронтенд'!$D$4:'Фронтенд'!$D30, "SPREAD", 'Фронтенд'!H$4:'Фронтенд'!H30) * ($H$14 / ($D$14+$H$14+$L$14))) + (SUMIF('Фронтенд'!$D$4:'Фронтенд'!$D30, "DIS & DEV", 'Фронтенд'!H$4:'Фронтенд'!H30) * ($H$14 / ($D$14+$H$14))) + (SUMIF('Фронтенд'!$D$4:'Фронтенд'!$D30, "DEV & DEL", 'Фронтенд'!H$4:'Фронтенд'!H30) * ($H$14 / ($H$14+$L$14))),0) -> 43500 | L6: =ROUNDUP( SUMIF('Фронтенд'!$D$4:'Фронтенд'!$D30, "DELIVERY", 'Фронтенд'!E$4:'Фронтенд'!E30) + (SUMIF('Фронтенд'!$D$4:'Фронтенд'!$D30, "SPREAD", 'Фронтенд'!E$4:'Фронтенд'!E30) * ($L$14 / ($D$14+$H$14+$L$14))) + (SUMIF('Фронтенд'!$D$4:'Фронтенд'!$D30, "DEV & DEL", 'Фронтенд'!E$4:'Фронтенд'!E30) * ($L$14 / ($H$14+$L$14))),0) -> 8 | M6: =ROUNDUP( SUMIF('Фронтенд'!$D$4:'Фронтенд'!$D30, "DELIVERY", 'Фронтенд'!F$4:'Фронтенд'!F30) + (SUMIF('Фронтенд'!$D$4:'Фронтенд'!$D30, "SPREAD", 'Фронтенд'!F$4:'Фронтенд'!F30) * ($L$14 / ($D$14+$H$14+$L$14))) + (SUMIF('Фронтенд'!$D$4:'Фронтенд'!$D30, "DEV & DEL", 'Фронтенд'!F$4:'Фронтенд'!F30) * ($L$14 / ($H$14+$L$14))),0) -> 8 | N6: =ROUNDUP( SUMIF('Фронтенд'!$D$4:'Фронтенд'!$D30, "DELIVERY", 'Фронтенд'!G$4:'Фронтенд'!G30) + (SUMIF('Фронтенд'!$D$4:'Фронтенд'!$D30, "SPREAD", 'Фронтенд'!G$4:'Фронтенд'!G30) * ($L$14 / ($D$14+$H$14+$L$14))) + (SUMIF('Фронтенд'!$D$4:'Фронтенд'!$D30, "DEV & DEL", 'Фронтенд'!G$4:'Фронтенд'!G30) * ($L$14 / ($H$14+$L$14))),0) -> 370 | O6: =ROUNDUP( SUMIF('Фронтенд'!$D$4:'Фронтенд'!$D30, "DELIVERY", 'Фронтенд'!H$4:'Фронтенд'!H30) + (SUMIF('Фронтенд'!$D$4:'Фронтенд'!$D30, "SPREAD", 'Фронтенд'!H$4:'Фронтенд'!H30) * ($L$14 / ($D$14+$H$14+$L$14))) + (SUMIF('Фронтенд'!$D$4:'Фронтенд'!$D30, "DEV & DEL", 'Фронтенд'!H$4:'Фронтенд'!H30) * ($L$14 / ($H$14+$L$14))),0) -> 400
A7: 4 | B7: Бэкенд-разработка | C7: 2 | D7: =ROUNDUP( SUMIF('Бэкенд'!$D$4:'Бэкенд'!$D24, "DISCOVERY", 'Бэкенд'!E$4:'Бэкенд'!E24) + (SUMIF('Бэкенд'!$D$4:'Бэкенд'!$D24, "SPREAD", 'Бэкенд'!E$4:'Бэкенд'!E24) * ($D$14 / ($D$14+$H$14+$L$14))) + (SUMIF('Бэкенд'!$D$4:'Бэкенд'!$D24, "DIS & DEV", 'Бэкенд'!E$4:'Бэкенд'!E24) * ($D$14 / ($D$14+$H$14))),0) -> 10 | E7: =ROUNDUP( SUMIF('Бэкенд'!$D$4:'Бэкенд'!$D24, "DISCOVERY", 'Бэкенд'!F$4:'Бэкенд'!F24) + (SUMIF('Бэкенд'!$D$4:'Бэкенд'!$D24, "SPREAD", 'Бэкенд'!F$4:'Бэкенд'!F24) * ($D$14 / ($D$14+$H$14+$L$14))) + (SUMIF('Бэкенд'!$D$4:'Бэкенд'!$D24, "DIS & DEV", 'Бэкенд'!F$4:'Бэкенд'!F24) * ($D$14 / ($D$14+$H$14))),0) -> 16 | F7: =ROUNDUP( SUMIF('Бэкенд'!$D$4:'Бэкенд'!$D24, "DISCOVERY", 'Бэкенд'!G$4:'Бэкенд'!G24) + (SUMIF('Бэкенд'!$D$4:'Бэкенд'!$D24, "SPREAD", 'Бэкенд'!G$4:'Бэкенд'!G24) * ($D$14 / ($D$14+$H$14+$L$14))) + (SUMIF('Бэкенд'!$D$4:'Бэкенд'!$D24, "DIS & DEV", 'Бэкенд'!G$4:'Бэкенд'!G24) * ($D$14 / ($D$14+$H$14))),0) -> 550 | G7: =ROUNDUP( SUMIF('Бэкенд'!$D$4:'Бэкенд'!$D24, "DISCOVERY", 'Бэкенд'!H$4:'Бэкенд'!H24) + (SUMIF('Бэкенд'!$D$4:'Бэкенд'!$D24, "SPREAD", 'Бэкенд'!H$4:'Бэкенд'!H24) * ($D$14 / ($D$14+$H$14+$L$14))) + (SUMIF('Бэкенд'!$D$4:'Бэкенд'!$D24, "DIS & DEV", 'Бэкенд'!H$4:'Бэкенд'!H24) * ($D$14 / ($D$14+$H$14))),0) -> 880 | H7: =ROUNDUP( SUMIF('Бэкенд'!$D$4:'Бэкенд'!$D24, "DEVELOPMENT", 'Бэкенд'!E$4:'Бэкенд'!E24) + (SUMIF('Бэкенд'!$D$4:'Бэкенд'!$D24, "SPREAD", 'Бэкенд'!E$4:'Бэкенд'!E24) * ($H$14 / ($D$14+$H$14+$L$14))) + (SUMIF('Бэкенд'!$D$4:'Бэкенд'!$D24, "DIS & DEV", 'Бэкенд'!E$4:'Бэкенд'!E24) * ($H$14 / ($D$14+$H$14))) + (SUMIF('Бэкенд'!$D$4:'Бэкенд'!$D24, "DEV & DEL", 'Бэкенд'!E$4:'Бэкенд'!E24) * ($H$14 / ($H$14+$L$14))),0) -> 962 | I7: =ROUNDUP( SUMIF('Бэкенд'!$D$4:'Бэкенд'!$D24, "DEVELOPMENT", 'Бэкенд'!F$4:'Бэкенд'!F24) + (SUMIF('Бэкенд'!$D$4:'Бэкенд'!$D24, "SPREAD", 'Бэкенд'!F$4:'Бэкенд'!F24) * ($H$14 / ($D$14+$H$14+$L$14))) + (SUMIF('Бэкенд'!$D$4:'Бэкенд'!$D24, "DIS & DEV", 'Бэкенд'!F$4:'Бэкенд'!F24) * ($H$14 / ($D$14+$H$14))) + (SUMIF('Бэкенд'!$D$4:'Бэкенд'!$D24, "DEV & DEL", 'Бэкенд'!F$4:'Бэкенд'!F24) * ($H$14 / ($H$14+$L$14))),0) -> 1289 | J7: =ROUNDUP( SUMIF('Бэкенд'!$D$4:'Бэкенд'!$D24, "DEVELOPMENT", 'Бэкенд'!G$4:'Бэкенд'!G24) + (SUMIF('Бэкенд'!$D$4:'Бэкенд'!$D24, "SPREAD", 'Бэкенд'!G$4:'Бэкенд'!G24) * ($H$14 / ($D$14+$H$14+$L$14))) + (SUMIF('Бэкенд'!$D$4:'Бэкенд'!$D24, "DIS & DEV", 'Бэкенд'!G$4:'Бэкенд'!G24) * ($H$14 / ($D$14+$H$14))) + (SUMIF('Бэкенд'!$D$4:'Бэкенд'!$D24, "DEV & DEL", 'Бэкенд'!G$4:'Бэкенд'!G24) * ($H$14 / ($H$14+$L$14))),0) -> 52889 | K7: =ROUNDUP( SUMIF('Бэкенд'!$D$4:'Бэкенд'!$D24, "DEVELOPMENT", 'Бэкенд'!H$4:'Бэкенд'!H24) + (SUMIF('Бэкенд'!$D$4:'Бэкенд'!$D24, "SPREAD", 'Бэкенд'!H$4:'Бэкенд'!H24) * ($H$14 / ($D$14+$H$14+$L$14))) + (SUMIF('Бэкенд'!$D$4:'Бэкенд'!$D24, "DIS & DEV", 'Бэкенд'!H$4:'Бэкенд'!H24) * ($H$14 / ($D$14+$H$14))) + (SUMIF('Бэкенд'!$D$4:'Бэкенд'!$D24, "DEV & DEL", 'Бэкенд'!H$4:'Бэкенд'!H24) * ($H$14 / ($H$14+$L$14))),0) -> 70891 | L7: =ROUNDUP( SUMIF('Бэкенд'!$D$4:'Бэкенд'!$D24, "DELIVERY", 'Бэкенд'!E$4:'Бэкенд'!E24) + (SUMIF('Бэкенд'!$D$4:'Бэкенд'!$D24, "SPREAD", 'Бэкенд'!E$4:'Бэкенд'!E24) * ($L$14 / ($D$14+$H$14+$L$14))) + (SUMIF('Бэкенд'!$D$4:'Бэкенд'!$D24, "DEV & DEL", 'Бэкенд'!E$4:'Бэкенд'!E24) * ($L$14 / ($H$14+$L$14))),0) -> 10 | M7: =ROUNDUP( SUMIF('Бэкенд'!$D$4:'Бэкенд'!$D24, "DELIVERY", 'Бэкенд'!F$4:'Бэкенд'!F24) + (SUMIF('Бэкенд'!$D$4:'Бэкенд'!$D24, "SPREAD", 'Бэкенд'!F$4:'Бэкенд'!F24) * ($L$14 / ($D$14+$H$14+$L$14))) + (SUMIF('Бэкенд'!$D$4:'Бэкенд'!$D24, "DEV & DEL", 'Бэкенд'!F$4:'Бэкенд'!F24) * ($L$14 / ($H$14+$L$14))),0) -> 16 | N7: =ROUNDUP( SUMIF('Бэкенд'!$D$4:'Бэкенд'!$D24, "DELIVERY", 'Бэкенд'!G$4:'Бэкенд'!G24) + (SUMIF('Бэкенд'!$D$4:'Бэкенд'!$D24, "SPREAD", 'Бэкенд'!G$4:'Бэкенд'!G24) * ($L$14 / ($D$14+$H$14+$L$14))) + (SUMIF('Бэкенд'!$D$4:'Бэкенд'!$D24, "DEV & DEL", 'Бэкенд'!G$4:'Бэкенд'!G24) * ($L$14 / ($H$14+$L$14))),0) -> 517 | O7: =ROUNDUP( SUMIF('Бэкенд'!$D$4:'Бэкенд'!$D24, "DELIVERY", 'Бэкенд'!H$4:'Бэкенд'!H24) + (SUMIF('Бэкенд'!$D$4:'Бэкенд'!$D24, "SPREAD", 'Бэкенд'!H$4:'Бэкенд'!H24) * ($L$14 / ($D$14+$H$14+$L$14))) + (SUMIF('Бэкенд'!$D$4:'Бэкенд'!$D24, "DEV & DEL", 'Бэкенд'!H$4:'Бэкенд'!H24) * ($L$14 / ($H$14+$L$14))),0) -> 830
A8: 5 | B8: Смарт-контракты | C8: 1 | D8: =ROUNDUP( SUMIF('Смарт контракты'!$D$4:'Смарт контракты'!$D9, "DISCOVERY", 'Смарт контракты'!E$4:'Смарт контракты'!E9) + (SUMIF('Смарт контракты'!$D$4:'Смарт контракты'!$D9, "SPREAD", 'Смарт контракты'!E$4:'Смарт контракты'!E9) * ($D$14 / ($D$14+$H$14+$L$14))) + (SUMIF('Смарт контракты'!$D$4:'Смарт контракты'!$D9, "DIS & DEV", 'Смарт контракты'!E$4:'Смарт контракты'!E9) * ($D$14 / ($D$14+$H$14))),0) -> 3 | E8: =ROUNDUP( SUMIF('Смарт контракты'!$D$4:'Смарт контракты'!$D9, "DISCOVERY", 'Смарт контракты'!F$4:'Смарт контракты'!F9) + (SUMIF('Смарт контракты'!$D$4:'Смарт контракты'!$D9, "SPREAD", 'Смарт контракты'!F$4:'Смарт контракты'!F9) * ($D$14 / ($D$14+$H$14+$L$14))) + (SUMIF('Смарт контракты'!$D$4:'Смарт контракты'!$D9, "DIS & DEV", 'Смарт контракты'!F$4:'Смарт контракты'!F9) * ($D$14 / ($D$14+$H$14))),0) -> 4 | F8: =ROUNDUP( SUMIF('Смарт контракты'!$D$4:'Смарт контракты'!$D9, "DISCOVERY", 'Смарт контракты'!G$4:'Смарт контракты'!G9) + (SUMIF('Смарт контракты'!$D$4:'Смарт контракты'!$D9, "SPREAD", 'Смарт контракты'!G$4:'Смарт контракты'!G9) * ($D$14 / ($D$14+$H$14+$L$14))) + (SUMIF('Смарт контракты'!$D$4:'Смарт контракты'!$D9, "DIS & DEV", 'Смарт контракты'!G$4:'Смарт контракты'!G9) * ($D$14 / ($D$14+$H$14))),0) -> 147 | G8: =ROUNDUP( SUMIF('Смарт контракты'!$D$4:'Смарт контракты'!$D9, "DISCOVERY", 'Смарт контракты'!H$4:'Смарт контракты'!H9) + (SUMIF('Смарт контракты'!$D$4:'Смарт контракты'!$D9, "SPREAD", 'Смарт контракты'!H$4:'Смарт контракты'!H9) * ($D$14 / ($D$14+$H$14+$L$14))) + (SUMIF('Смарт контракты'!$D$4:'Смарт контракты'!$D9, "DIS & DEV", 'Смарт контракты'!H$4:'Смарт контракты'!H9) * ($D$14 / ($D$14+$H$14))),0) -> 220 | H8: =ROUNDUP( SUMIF('Смарт контракты'!$D$4:'Смарт контракты'!$D9, "DEVELOPMENT", 'Смарт контракты'!E$4:'Смарт контракты'!E9) + (SUMIF('Смарт контракты'!$D$4:'Смарт контракты'!$D9, "SPREAD", 'Смарт контракты'!E$4:'Смарт контракты'!E9) * ($H$14 / ($D$14+$H$14+$L$14))) + (SUMIF('Смарт контракты'!$D$4:'Смарт контракты'!$D9, "DIS & DEV", 'Смарт контракты'!E$4:'Смарт контракты'!E9) * ($H$14 / ($D$14+$H$14))) + (SUMIF('Смарт контракты'!$D$4:'Смарт контракты'!$D9, "DEV & DEL", 'Смарт контракты'!E$4:'Смарт контракты'!E9) * ($H$14 / ($H$14+$L$14))),0) -> 201 | I8: =ROUNDUP( SUMIF('Смарт контракты'!$D$4:'Смарт контракты'!$D9, "DEVELOPMENT", 'Смарт контракты'!F$4:'Смарт контракты'!F9) + (SUMIF('Смарт контракты'!$D$4:'Смарт контракты'!$D9, "SPREAD", 'Смарт контракты'!F$4:'Смарт контракты'!F9) * ($H$14 / ($D$14+$H$14+$L$14))) + (SUMIF('Смарт контракты'!$D$4:'Смарт контракты'!$D9, "DIS & DEV", 'Смарт контракты'!F$4:'Смарт контракты'!F9) * ($H$14 / ($D$14+$H$14))) + (SUMIF('Смарт контракты'!$D$4:'Смарт контракты'!$D9, "DEV & DEL", 'Смарт контракты'!F$4:'Смарт контракты'!F9) * ($H$14 / ($H$14+$L$14))),0) -> 273 | J8: =ROUNDUP( SUMIF('Смарт контракты'!$D$4:'Смарт контракты'!$D9, "DEVELOPMENT", 'Смарт контракты'!G$4:'Смарт контракты'!G9) + (SUMIF('Смарт контракты'!$D$4:'Смарт контракты'!$D9, "SPREAD", 'Смарт контракты'!G$4:'Смарт контракты'!G9) * ($H$14 / ($D$14+$H$14+$L$14))) + (SUMIF('Смарт контракты'!$D$4:'Смарт контракты'!$D9, "DIS & DEV", 'Смарт контракты'!G$4:'Смарт контракты'!G9) * ($H$14 / ($D$14+$H$14))) + (SUMIF('Смарт контракты'!$D$4:'Смарт контракты'!$D9, "DEV & DEL", 'Смарт контракты'!G$4:'Смарт контракты'!G9) * ($H$14 / ($H$14+$L$14))),0) -> 11023 | K8: =ROUNDUP( SUMIF('Смарт контракты'!$D$4:'Смарт контракты'!$D9, "DEVELOPMENT", 'Смарт контракты'!H$4:'Смарт контракты'!H9) + (SUMIF('Смарт контракты'!$D$4:'Смарт контракты'!$D9, "SPREAD", 'Смарт контракты'!H$4:'Смарт контракты'!H9) * ($H$14 / ($D$14+$H$14+$L$14))) + (SUMIF('Смарт контракты'!$D$4:'Смарт контракты'!$D9, "DIS & DEV", 'Смарт контракты'!H$4:'Смарт контракты'!H9) * ($H$14 / ($D$14+$H$14))) + (SUMIF('Смарт контракты'!$D$4:'Смарт контракты'!$D9, "DEV & DEL", 'Смарт контракты'!H$4:'Смарт контракты'!H9) * ($H$14 / ($H$14+$L$14))),0) -> 14977 | L8: =ROUNDUP( SUMIF('Смарт контракты'!$D$4:'Смарт контракты'!$D9, "DELIVERY", 'Смарт контракты'!E$4:'Смарт контракты'!E9) + (SUMIF('Смарт контракты'!$D$4:'Смарт контракты'!$D9, "SPREAD", 'Смарт контракты'!E$4:'Смарт контракты'!E9) * ($L$14 / ($D$14+$H$14+$L$14))) + (SUMIF('Смарт контракты'!$D$4:'Смарт контракты'!$D9, "DEV & DEL", 'Смарт контракты'!E$4:'Смарт контракты'!E9) * ($L$14 / ($H$14+$L$14))),0) -> 3 | M8: =ROUNDUP( SUMIF('Смарт контракты'!$D$4:'Смарт контракты'!$D9, "DELIVERY", 'Смарт контракты'!F$4:'Смарт контракты'!F9) + (SUMIF('Смарт контракты'!$D$4:'Смарт контракты'!$D9, "SPREAD", 'Смарт контракты'!F$4:'Смарт контракты'!F9) * ($L$14 / ($D$14+$H$14+$L$14))) + (SUMIF('Смарт контракты'!$D$4:'Смарт контракты'!$D9, "DEV & DEL", 'Смарт контракты'!F$4:'Смарт контракты'!F9) * ($L$14 / ($H$14+$L$14))),0) -> 4 | N8: =ROUNDUP( SUMIF('Смарт контракты'!$D$4:'Смарт контракты'!$D9, "DELIVERY", 'Смарт контракты'!G$4:'Смарт контракты'!G9) + (SUMIF('Смарт контракты'!$D$4:'Смарт контракты'!$D9, "SPREAD", 'Смарт контракты'!G$4:'Смарт контракты'!G9) * ($L$14 / ($D$14+$H$14+$L$14))) + (SUMIF('Смарт контракты'!$D$4:'Смарт контракты'!$D9, "DEV & DEL", 'Смарт контракты'!G$4:'Смарт контракты'!G9) * ($L$14 / ($H$14+$L$14))),0) -> 161 | O8: =ROUNDUP( SUMIF('Смарт контракты'!$D$4:'Смарт контракты'!$D9, "DELIVERY", 'Смарт контракты'!H$4:'Смарт контракты'!H9) + (SUMIF('Смарт контракты'!$D$4:'Смарт контракты'!$D9, "SPREAD", 'Смарт контракты'!H$4:'Смарт контракты'!H9) * ($L$14 / ($D$14+$H$14+$L$14))) + (SUMIF('Смарт контракты'!$D$4:'Смарт контракты'!$D9, "DEV & DEL", 'Смарт контракты'!H$4:'Смарт контракты'!H9) * ($L$14 / ($H$14+$L$14))),0) -> 204
A9: 6 | B9: DevOps | C9: 1 | D9: =ROUNDUP( SUMIF(DevOps!$D$4:DevOps!$D9, "DISCOVERY", DevOps!E$4:DevOps!E9) + (SUMIF(DevOps!$D$4:DevOps!$D9, "SPREAD", DevOps!E$4:DevOps!E9) * ($D$14 / ($D$14+$H$14+$L$14))) + (SUMIF(DevOps!$D$4:DevOps!$D9, "DIS & DEV", DevOps!E$4:DevOps!E9) * ($D$14 / ($D$14+$H$14))),0) -> 0 | E9: =ROUNDUP( SUMIF(DevOps!$D$4:DevOps!$D9, "DISCOVERY", DevOps!F$4:DevOps!F9) + (SUMIF(DevOps!$D$4:DevOps!$D9, "SPREAD", DevOps!F$4:DevOps!F9) * ($D$14 / ($D$14+$H$14+$L$14))) + (SUMIF(DevOps!$D$4:DevOps!$D9, "DIS & DEV", DevOps!F$4:DevOps!F9) * ($D$14 / ($D$14+$H$14))),0) -> 0 | F9: =ROUNDUP( SUMIF(DevOps!$D$4:DevOps!$D9, "DISCOVERY", DevOps!G$4:DevOps!G9) + (SUMIF(DevOps!$D$4:DevOps!$D9, "SPREAD", DevOps!G$4:DevOps!G9) * ($D$14 / ($D$14+$H$14+$L$14))) + (SUMIF(DevOps!$D$4:DevOps!$D9, "DIS & DEV", DevOps!G$4:DevOps!G9) * ($D$14 / ($D$14+$H$14))),0) -> 0 | G9: =ROUNDUP( SUMIF(DevOps!$D$4:DevOps!$D9, "DISCOVERY", DevOps!H$4:DevOps!H9) + (SUMIF(DevOps!$D$4:DevOps!$D9, "SPREAD", DevOps!H$4:DevOps!H9) * ($D$14 / ($D$14+$H$14+$L$14))) + (SUMIF(DevOps!$D$4:DevOps!$D9, "DIS & DEV", DevOps!H$4:DevOps!H9) * ($D$14 / ($D$14+$H$14))),0) -> 0 | H9: =ROUNDUP( SUMIF(DevOps!$D$4:DevOps!$D9, "DEVELOPMENT", DevOps!E$4:DevOps!E9) + (SUMIF(DevOps!$D$4:DevOps!$D9, "SPREAD", DevOps!E$4:DevOps!E9) * ($H$14 / ($D$14+$H$14+$L$14))) + (SUMIF(DevOps!$D$4:DevOps!$D9, "DIS & DEV", DevOps!E$4:DevOps!E9) * ($H$14 / ($D$14+$H$14))) + (SUMIF(DevOps!$D$4:DevOps!$D9, "DEV & DEL", DevOps!E$4:DevOps!E9) * ($H$14 / ($H$14+$L$14))),0) -> 96 | I9: =ROUNDUP( SUMIF(DevOps!$D$4:DevOps!$D9, "DEVELOPMENT", DevOps!F$4:DevOps!F9) + (SUMIF(DevOps!$D$4:DevOps!$D9, "SPREAD", DevOps!F$4:DevOps!F9) * ($H$14 / ($D$14+$H$14+$L$14))) + (SUMIF(DevOps!$D$4:DevOps!$D9, "DIS & DEV", DevOps!F$4:DevOps!F9) * ($H$14 / ($D$14+$H$14))) + (SUMIF(DevOps!$D$4:DevOps!$D9, "DEV & DEL", DevOps!F$4:DevOps!F9) * ($H$14 / ($H$14+$L$14))),0) -> 124 | J9: =ROUNDUP( SUMIF(DevOps!$D$4:DevOps!$D9, "DEVELOPMENT", DevOps!G$4:DevOps!G9) + (SUMIF(DevOps!$D$4:DevOps!$D9, "SPREAD", DevOps!G$4:DevOps!G9) * ($H$14 / ($D$14+$H$14+$L$14))) + (SUMIF(DevOps!$D$4:DevOps!$D9, "DIS & DEV", DevOps!G$4:DevOps!G9) * ($H$14 / ($D$14+$H$14))) + (SUMIF(DevOps!$D$4:DevOps!$D9, "DEV & DEL", DevOps!G$4:DevOps!G9) * ($H$14 / ($H$14+$L$14))),0) -> 4320 | K9: =ROUNDUP( SUMIF(DevOps!$D$4:DevOps!$D9, "DEVELOPMENT", DevOps!H$4:DevOps!H9) + (SUMIF(DevOps!$D$4:DevOps!$D9, "SPREAD", DevOps!H$4:DevOps!H9) * ($H$14 / ($D$14+$H$14+$L$14))) + (SUMIF(DevOps!$D$4:DevOps!$D9, "DIS & DEV", DevOps!H$4:DevOps!H9) * ($H$14 / ($D$14+$H$14))) + (SUMIF(DevOps!$D$4:DevOps!$D9, "DEV & DEL", DevOps!H$4:DevOps!H9) * ($H$14 / ($H$14+$L$14))),0) -> 5580 | L9: =ROUNDUP( SUMIF(DevOps!$D$4:DevOps!$D9, "DELIVERY", DevOps!E$4:DevOps!E9) + (SUMIF(DevOps!$D$4:DevOps!$D9, "SPREAD", DevOps!E$4:DevOps!E9) * ($L$14 / ($D$14+$H$14+$L$14))) + (SUMIF(DevOps!$D$4:DevOps!$D9, "DEV & DEL", DevOps!E$4:DevOps!E9) * ($H$14 / ($H$14+$L$14))),0) -> 6 | M9: =ROUNDUP( SUMIF(DevOps!$D$4:DevOps!$D9, "DELIVERY", DevOps!F$4:DevOps!F9) + (SUMIF(DevOps!$D$4:DevOps!$D9, "SPREAD", DevOps!F$4:DevOps!F9) * ($L$14 / ($D$14+$H$14+$L$14))) + (SUMIF(DevOps!$D$4:DevOps!$D9, "DEV & DEL", DevOps!F$4:DevOps!F9) * ($H$14 / ($H$14+$L$14))),0) -> 8 | N9: =ROUNDUP( SUMIF(DevOps!$D$4:DevOps!$D9, "DELIVERY", DevOps!G$4:DevOps!G9) + (SUMIF(DevOps!$D$4:DevOps!$D9, "SPREAD", DevOps!G$4:DevOps!G9) * ($L$14 / ($D$14+$H$14+$L$14))) + (SUMIF(DevOps!$D$4:DevOps!$D9, "DEV & DEL", DevOps!G$4:DevOps!G9) * ($H$14 / ($H$14+$L$14))),0) -> 270 | O9: =ROUNDUP( SUMIF(DevOps!$D$4:DevOps!$D9, "DELIVERY", DevOps!H$4:DevOps!H9) + (SUMIF(DevOps!$D$4:DevOps!$D9, "SPREAD", DevOps!H$4:DevOps!H9) * ($L$14 / ($D$14+$H$14+$L$14))) + (SUMIF(DevOps!$D$4:DevOps!$D9, "DEV & DEL", DevOps!H$4:DevOps!H9) * ($H$14 / ($H$14+$L$14))),0) -> 360
A10: 7 | B10: Контроль качества (QA) | C10: 1 | D10: =ROUNDUP( SUMIF(QA!$D$4:QA!$D9, "DISCOVERY", QA!E$4:QA!E9) + (SUMIF(QA!$D$4:QA!$D9, "SPREAD", QA!E$4:QA!E9) * ($D$14 / ($D$14+$H$14+$L$14))) + (SUMIF(QA!$D$4:QA!$D9, "DIS & DEV", QA!E$4:QA!E9) * ($D$14 / ($D$14+$H$14))),0) -> 77 | E10: =ROUNDUP( SUMIF(QA!$D$4:QA!$D9, "DISCOVERY", QA!F$4:QA!F9) + (SUMIF(QA!$D$4:QA!$D9, "SPREAD", QA!F$4:QA!F9) * ($D$14 / ($D$14+$H$14+$L$14))) + (SUMIF(QA!$D$4:QA!$D9, "DIS & DEV", QA!F$4:QA!F9) * ($D$14 / ($D$14+$H$14))),0) -> 92 | F10: =ROUNDUP( SUMIF(QA!$D$4:QA!$D9, "DISCOVERY", QA!G$4:QA!G9) + (SUMIF(QA!$D$4:QA!$D9, "SPREAD", QA!G$4:QA!G9) * ($D$14 / ($D$14+$H$14+$L$14))) + (SUMIF(QA!$D$4:QA!$D9, "DIS & DEV", QA!G$4:QA!G9) * ($D$14 / ($D$14+$H$14))),0) -> 3450 | G10: =ROUNDUP( SUMIF(QA!$D$4:QA!$D9, "DISCOVERY", QA!H$4:QA!H9) + (SUMIF(QA!$D$4:QA!$D9, "SPREAD", QA!H$4:QA!H9) * ($D$14 / ($D$14+$H$14+$L$14))) + (SUMIF(QA!$D$4:QA!$D9, "DIS & DEV", QA!H$4:QA!H9) * ($D$14 / ($D$14+$H$14))),0) -> 4110 | H10: =ROUNDUP( SUMIF(QA!$D$4:QA!$D9, "DEVELOPMENT", QA!E$4:QA!E9) + (SUMIF(QA!$D$4:QA!$D9, "SPREAD", QA!E$4:QA!E9) * ($H$14 / ($D$14+$H$14+$L$14))) + (SUMIF(QA!$D$4:QA!$D9, "DIS & DEV", QA!E$4:QA!E9) * ($H$14 / ($D$14+$H$14))) + (SUMIF(QA!$D$4:QA!$D9, "DEV & DEL", QA!E$4:QA!E9) * ($H$14 / ($H$14+$L$14))),0) -> 600 | I10: =ROUNDUP( SUMIF(QA!$D$4:QA!$D9, "DEVELOPMENT", QA!F$4:QA!F9) + (SUMIF(QA!$D$4:QA!$D9, "SPREAD", QA!F$4:QA!F9) * ($H$14 / ($D$14+$H$14+$L$14))) + (SUMIF(QA!$D$4:QA!$D9, "DIS & DEV", QA!F$4:QA!F9) * ($H$14 / ($D$14+$H$14))) + (SUMIF(QA!$D$4:QA!$D9, "DEV & DEL", QA!F$4:QA!F9) * ($H$14 / ($H$14+$L$14))),0) -> 729 | J10: =ROUNDUP( SUMIF(QA!$D$4:QA!$D9, "DEVELOPMENT", QA!G$4:QA!G9) + (SUMIF(QA!$D$4:QA!$D9, "SPREAD", QA!G$4:QA!G9) * ($H$14 / ($D$14+$H$14+$L$14))) + (SUMIF(QA!$D$4:QA!$D9, "DIS & DEV", QA!G$4:QA!G9) * ($H$14 / ($D$14+$H$14))) + (SUMIF(QA!$D$4:QA!$D9, "DEV & DEL", QA!G$4:QA!G9) * ($H$14 / ($H$14+$L$14))),0) -> 26964 | K10: =ROUNDUP( SUMIF(QA!$D$4:QA!$D9, "DEVELOPMENT", QA!H$4:QA!H9) + (SUMIF(QA!$D$4:QA!$D9, "SPREAD", QA!H$4:QA!H9) * ($H$14 / ($D$14+$H$14+$L$14))) + (SUMIF(QA!$D$4:QA!$D9, "DIS & DEV", QA!H$4:QA!H9) * ($H$14 / ($D$14+$H$14))) + (SUMIF(QA!$D$4:QA!$D9, "DEV & DEL", QA!H$4:QA!H9) * ($H$14 / ($H$14+$L$14))),0) -> 32770 | L10: =ROUNDUP( SUMIF(QA!$D$4:QA!$D9, "DELIVERY", QA!E$4:QA!E9) + (SUMIF(QA!$D$4:QA!$D9, "SPREAD", QA!E$4:QA!E9) * ($L$14 / ($D$14+$H$14+$L$14))) + (SUMIF(QA!$D$4:QA!$D9, "DEV & DEL", QA!E$4:QA!E9) * ($L$14 / ($H$14+$L$14))),0) -> 47 | M10: =ROUNDUP( SUMIF(QA!$D$4:QA!$D9, "DELIVERY", QA!F$4:QA!F9) + (SUMIF(QA!$D$4:QA!$D9, "SPREAD", QA!F$4:QA!F9) * ($L$14 / ($D$14+$H$14+$L$14))) + (SUMIF(QA!$D$4:QA!$D9, "DEV & DEL", QA!F$4:QA!F9) * ($L$14 / ($H$14+$L$14))),0) -> 57 | N10: =ROUNDUP( SUMIF(QA!$D$4:QA!$D9, "DELIVERY", QA!G$4:QA!G9) + (SUMIF(QA!$D$4:QA!$D9, "SPREAD", QA!G$4:QA!G9) * ($L$14 / ($D$14+$H$14+$L$14))) + (SUMIF(QA!$D$4:QA!$D9, "DEV & DEL", QA!G$4:QA!G9) * ($L$14 / ($H$14+$L$14))),0) -> 2077 | O10: =ROUNDUP( SUMIF(QA!$D$4:QA!$D9, "DELIVERY", QA!H$4:QA!H9) + (SUMIF(QA!$D$4:QA!$D9, "SPREAD", QA!H$4:QA!H9) * ($L$14 / ($D$14+$H$14+$L$14))) + (SUMIF(QA!$D$4:QA!$D9, "DEV & DEL", QA!H$4:QA!H9) * ($L$14 / ($H$14+$L$14))),0) -> 2541
A11: 8 | B11: Менеджмент | C11: 1 | D11: =ROUNDUP( SUMIF('Менеджмент'!$D$4:'Менеджмент'!$D10, "DISCOVERY", 'Менеджмент'!E$4:'Менеджмент'!E10) + (SUMIF('Менеджмент'!$D$4:'Менеджмент'!$D10, "SPREAD", 'Менеджмент'!E$4:'Менеджмент'!E10) * ($D$14 / ($D$14+$H$14+$L$14))) + (SUMIF('Менеджмент'!$D$4:'Менеджмент'!$D10, "DIS & DEV", 'Менеджмент'!E$4:'Менеджмент'!E10) * ($D$14 / ($D$14+$H$14))),0) -> 118 | E11: =ROUNDUP( SUMIF('Менеджмент'!$D$4:'Менеджмент'!$D10, "DISCOVERY", 'Менеджмент'!F$4:'Менеджмент'!F10) + (SUMIF('Менеджмент'!$D$4:'Менеджмент'!$D10, "SPREAD", 'Менеджмент'!F$4:'Менеджмент'!F10) * ($D$14 / ($D$14+$H$14+$L$14))) + (SUMIF('Менеджмент'!$D$4:'Менеджмент'!$D10, "DIS & DEV", 'Менеджмент'!F$4:'Менеджмент'!F10) * ($D$14 / ($D$14+$H$14))),0) -> 134 | F11: =ROUNDUP( SUMIF('Менеджмент'!$D$4:'Менеджмент'!$D10, "DISCOVERY", 'Менеджмент'!G$4:'Менеджмент'!G10) + (SUMIF('Менеджмент'!$D$4:'Менеджмент'!$D10, "SPREAD", 'Менеджмент'!G$4:'Менеджмент'!G10) * ($D$14 / ($D$14+$H$14+$L$14))) + (SUMIF('Менеджмент'!$D$4:'Менеджмент'!$D10, "DIS & DEV", 'Менеджмент'!G$4:'Менеджмент'!G10) * ($D$14 / ($D$14+$H$14))),0) -> 5296 | G11: =ROUNDUP( SUMIF('Менеджмент'!$D$4:'Менеджмент'!$D10, "DISCOVERY", 'Менеджмент'!H$4:'Менеджмент'!H10) + (SUMIF('Менеджмент'!$D$4:'Менеджмент'!$D10, "SPREAD", 'Менеджмент'!H$4:'Менеджмент'!H10) * ($D$14 / ($D$14+$H$14+$L$14))) + (SUMIF('Менеджмент'!$D$4:'Менеджмент'!$D10, "DIS & DEV", 'Менеджмент'!H$4:'Менеджмент'!H10) * ($D$14 / ($D$14+$H$14))),0) -> 5994 | H11: =ROUNDUP( SUMIF('Менеджмент'!$D$4:'Менеджмент'!$D10, "DEVELOPMENT", 'Менеджмент'!E$4:'Менеджмент'!E10) + (SUMIF('Менеджмент'!$D$4:'Менеджмент'!$D10, "SPREAD", 'Менеджмент'!E$4:'Менеджмент'!E10) * ($H$14 / ($D$14+$H$14+$L$14))) + (SUMIF('Менеджмент'!$D$4:'Менеджмент'!$D10, "DIS & DEV", 'Менеджмент'!E$4:'Менеджмент'!E10) * ($H$14 / ($D$14+$H$14))) + (SUMIF('Менеджмент'!$D$4:'Менеджмент'!$D10, "DEV & DEL", 'Менеджмент'!E$4:'Менеджмент'!E10) * ($H$14 / ($H$14+$L$14))),0) -> 228 | I11: =ROUNDUP( SUMIF('Менеджмент'!$D$4:'Менеджмент'!$D10, "DEVELOPMENT", 'Менеджмент'!F$4:'Менеджмент'!F10) + (SUMIF('Менеджмент'!$D$4:'Менеджмент'!$D10, "SPREAD", 'Менеджмент'!F$4:'Менеджмент'!F10) * ($H$14 / ($D$14+$H$14+$L$14))) + (SUMIF('Менеджмент'!$D$4:'Менеджмент'!$D10, "DIS & DEV", 'Менеджмент'!F$4:'Менеджмент'!F10) * ($H$14 / ($D$14+$H$14))) + (SUMIF('Менеджмент'!$D$4:'Менеджмент'!$D10, "DEV & DEL", 'Менеджмент'!F$4:'Менеджмент'!F10) * ($H$14 / ($H$14+$L$14))),0) -> 251 | J11: =ROUNDUP( SUMIF('Менеджмент'!$D$4:'Менеджмент'!$D10, "DEVELOPMENT", 'Менеджмент'!G$4:'Менеджмент'!G10) + (SUMIF('Менеджмент'!$D$4:'Менеджмент'!$D10, "SPREAD", 'Менеджмент'!G$4:'Менеджмент'!G10) * ($H$14 / ($D$14+$H$14+$L$14))) + (SUMIF('Менеджмент'!$D$4:'Менеджмент'!$D10, "DIS & DEV", 'Менеджмент'!G$4:'Менеджмент'!G10) * ($H$14 / ($D$14+$H$14))) + (SUMIF('Менеджмент'!$D$4:'Менеджмент'!$D10, "DEV & DEL", 'Менеджмент'!G$4:'Менеджмент'!G10) * ($H$14 / ($H$14+$L$14))),0) -> 10232 | K11: =ROUNDUP( SUMIF('Менеджмент'!$D$4:'Менеджмент'!$D10, "DEVELOPMENT", 'Менеджмент'!H$4:'Менеджмент'!H10) + (SUMIF('Менеджмент'!$D$4:'Менеджмент'!$D10, "SPREAD", 'Менеджмент'!H$4:'Менеджмент'!H10) * ($H$14 / ($D$14+$H$14+$L$14))) + (SUMIF('Менеджмент'!$D$4:'Менеджмент'!$D10, "DIS & DEV", 'Менеджмент'!H$4:'Менеджмент'!H10) * ($H$14 / ($D$14+$H$14))) + (SUMIF('Менеджмент'!$D$4:'Менеджмент'!$D10, "DEV & DEL", 'Менеджмент'!H$4:'Менеджмент'!H10) * ($H$14 / ($H$14+$L$14))),0) -> 11268 | L11: =ROUNDUP( SUMIF('Менеджмент'!$D$4:'Менеджмент'!$D10, "DELIVERY", 'Менеджмент'!E$4:'Менеджмент'!E10) + (SUMIF('Менеджмент'!$D$4:'Менеджмент'!$D10, "SPREAD", 'Менеджмент'!E$4:'Менеджмент'!E10) * ($L$14 / ($D$14+$H$14+$L$14))) + (SUMIF('Менеджмент'!$D$4:'Менеджмент'!$D10, "DEV & DEL", 'Менеджмент'!E$4:'Менеджмент'!E10) * ($L$14 / ($H$14+$L$14))),0) -> 29 | M11: =ROUNDUP( SUMIF('Менеджмент'!$D$4:'Менеджмент'!$D10, "DELIVERY", 'Менеджмент'!F$4:'Менеджмент'!F10) + (SUMIF('Менеджмент'!$D$4:'Менеджмент'!$D10, "SPREAD", 'Менеджмент'!F$4:'Менеджмент'!F10) * ($L$14 / ($D$14+$H$14+$L$14))) + (SUMIF('Менеджмент'!$D$4:'Менеджмент'!$D10, "DEV & DEL", 'Менеджмент'!F$4:'Менеджмент'!F10) * ($L$14 / ($H$14+$L$14))),0) -> 37 | N11: =ROUNDUP( SUMIF('Менеджмент'!$D$4:'Менеджмент'!$D10, "DELIVERY", 'Менеджмент'!G$4:'Менеджмент'!G10) + (SUMIF('Менеджмент'!$D$4:'Менеджмент'!$D10, "SPREAD", 'Менеджмент'!G$4:'Менеджмент'!G10) * ($L$14 / ($D$14+$H$14+$L$14))) + (SUMIF('Менеджмент'!$D$4:'Менеджмент'!$D10, "DEV & DEL", 'Менеджмент'!G$4:'Менеджмент'!G10) * ($L$14 / ($H$14+$L$14))),0) -> 1303 | O11: =ROUNDUP( SUMIF('Менеджмент'!$D$4:'Менеджмент'!$D10, "DELIVERY", 'Менеджмент'!H$4:'Менеджмент'!H10) + (SUMIF('Менеджмент'!$D$4:'Менеджмент'!$D10, "SPREAD", 'Менеджмент'!H$4:'Менеджмент'!H10) * ($L$14 / ($D$14+$H$14+$L$14))) + (SUMIF('Менеджмент'!$D$4:'Менеджмент'!$D10, "DEV & DEL", 'Менеджмент'!H$4:'Менеджмент'!H10) * ($L$14 / ($H$14+$L$14))),0) -> 1639
A13: СТОИМОСТЬ РАБОТ | D13: =CONCATENATE(SUM(F4:F11)&"$ - "&SUM(G4:G11)&"$") -> 16330$ - 20296$ | H13: =CONCATENATE(SUM(J4:J11)&"$ - "&SUM(K4:K11)&"$") -> 148097$ - 187128$ | L13: =CONCATENATE(SUM(N4:N11)&"$ - "&SUM(O4:O11)&"$") -> 4831$ - 6148$
A14: СРОКИ | D14: 6 | F14: Н | H14: 12 | J14: Н | L14: 1 | N14: Н
B16: Оценка действительна в течение 30 дней (до 01-05-2025). | J16: ПРИБЛ. СРОК: | K16: =CONCATENATE(D14+H14+L14&" - "&D14+H14+L14+2) -> 19 - 21 | L16: НЕДЕЛЬ
J17: ПРИБЛ. ЦЕНА: | K17: =SUM(F4:F12,J4:J12,N4:N12) -> 169258 | M17: - | N17: =SUM(G4:G12,K4:K12,O4:O12) -> 213572

Sheet Анализ
A1: ='Общая смета'!B1 -> ПРЕДВАРИТЕЛЬНАЯ ОЦЕНКА ТРУДОЗАТРАТ НА АГРЕГАТОР DEX В ТЕЛЕГРАМЕ
A2: # | B2: СПИСОК ЗАДАЧ | C2: Рейт ($/Ч) | D2: Фаза | E2: О. Часы | F2: П. Часы | G2: О. Цена | H2: П. Цена
A3: 1 | B3: Анализ | C3: 42 | E3: =SUM(E4:E9) -> 118 | F3: =SUM(F4:F9) -> 148 | G3: =SUM(G4:G9)-G9 -> 4956 | H3: =SUM(H4:H9)-H9 -> 6216
A4: 1.1 | B4: Сбор требований - Определение требований в соответствии с Borders & Scope - Анализ и ранжирование требований - Переговоры о требованиях со стейкхолдерами продукта - Составление чек-листа по задачам и списка функционала будущего продукта | D4: DISCOVERY | E4: 16 | F4: 20 | G4: =E4*$C$3 -> 672 | H4: =F4*$C$3 -> 840
A5: 1.2 | B5: Составление функциональных диаграмм и разработка Пользовательских сценариев - Перенос требований в диаграммы - Подготовка позитивных и негативных сценариев - Разработка Пользовательских сценариев и вариантов использования | D5: DISCOVERY | E5: 16 | F5: 20 | G5: =E5*$C$3 -> 672 | H5: =F5*$C$3 -> 840
A6: 1.3 | B6: Разработка требований к программному обеспечению (SRS) - Описание бизнес-логики - Справочное исследование - Подготовка описания страниц/экранов | D6: DISCOVERY | E6: 40 | F6: 48 | G6: =E6*$C$3 -> 1680 | H6: =F6*$C$3 -> 2016
A7: 1.4 | B7: Поддержка команды разработки по продуктовым вопросам - Консультирование команды в процессе разработки - Анализ и ранжирование новых требований и соответствующие переоценки трудозатрат | D7: DEV & DEL | E7: 30 | F7: 40 | G7: =E7*$C$3 -> 1260 | H7: =F7*$C$3 -> 1680
A8: 1.5 | B8: Работа с документами - Проверка качества документации - Ручное тестирование соответствия документа - Проверка полноты выполнения - Проверка соответствия целям проекта - Работа над постоянным улучшением документации и исправление ошибок | D8: SPREAD | E8: 16 | F8: 20 | G8: =E8*$C$3 -> 672 | H8: =F8*$C$3 -> 840
D9: SPREAD

Sheet Дизайн
A1: ='Общая смета'!B1 -> ПРЕДВАРИТЕЛЬНАЯ ОЦЕНКА ТРУДОЗАТРАТ НА АГРЕГАТОР DEX В ТЕЛЕГРАМЕ
A2: # | B2: СПИСОК ЗАДАЧ | C2: Рейт ($/Ч) | D2: Фаза | E2: О. Часы | F2: П. Часы | G2: О. Цена | H2: П. Цена
A3: 2 | B3: Дизайн | C3: 45 | E3: =SUM(E4:E26) -> 180 | F3: =SUM(F4:F26) -> 242 | G3: =SUM(G4:G26) -> 8100 | H3: =SUM(H4:H26) -> 10890
A4: 2.1 | B4: Исследование референсных решений - Анализ конкурентных решений - Создание мудбордов | D4: DISCOVERY | E4: 4 | F4: 6 | G4: =E4*$C$3 -> 180 | H4: =F4*$C$3 -> 270
A5: 2.2 | B5: ОБЩИЕ СТРАНИЦЫ
A6: 2.2.1 | B6: Домашняя страница. Дизайн макета. - Общая и регуляторная информация - Меню - Помощь и FAQ - Переход к подключению web3-кошелька | D6: DIS & DEV | E6: 20 | F6: 24 | G6: =E6*$C$3 -> 900 | H6: =F6*$C$3 -> 1080
A7: 2.2.2 | B7: Страница с антибот-верификацией. Дизайн макета - Интерфейс защиты от ботов | D7: DIS & DEV | E7: 6 | F7: 8 | G7: =E7*$C$3 -> 270 | H7: =F7*$C$3 -> 360
A8: 2.3 | B8: ПЛАТФОРМА
A9: 2.3.1 | B9: Профиль пользователя. Дизайн макета - Настройка личного кабинета и персональной информации | D9: DISCOVERY | E9: 10 | F9: 16 | G9: =E9*$C$3 -> 450 | H9: =F9*$C$3 -> 720
A10: 2.3.2 | B10: Страница подключения Web3-кошелька. Дизайн макета - Согласие с условиями - Выбор кошелька - Переход на сторонние ресурсы | D10: DISCOVERY | E10: 2 | F10: 4 | G10: =E10*$C$3 -> 90 | H10: =F10*$C$3 -> 180
A11: 2.3.3 | B11: Страница трейдинга. Дизайн макета - Выбор сетей (TON, SOL) - Отображение кошельков платформы - Выбор ордера (3 вида - рыночный ордер, лимитный ордер, стоп-ордер) - Таблица продаж/покупок (транзакции, ордера, мои активы, топ-200 держателей выбранного токена) - Информация по торговой паре - Блок покупки/продажи ордеров | D11: DISCOVERY | E11: 18 | F11: 24 | G11: =E11*$C$3 -> 810 | H11: =F11*$C$3 -> 1080
A12: 2.3.4 | B12: Модальное окно вывода средств. Дизайн макета - Выбор кошелька, валюты - Ввод адреса кошелька - Согласие с включением газа в сумму перевода | D12: DISCOVERY | E12: 1 | F12: 2 | G12: =E12*$C$3 -> 45 | H12: =F12*$C$3 -> 90
A13: 2.3.5 | B13: Модальное окно пополнения средств. Дизайн макета - Выбор кошелька - QR-код | D13: DISCOVERY | E13: 1 | F13: 2 | G13: =E13*$C$3 -> 45 | H13: =F13*$C$3 -> 90
A14: 2.3.6 | B14: Страница "Мои кошельки" - Таблица кошельков - Переход к выбору кошельков - Переход к настройке пресета кошельков - Таблица активов в кошельке - Переход к импорту, генерации изменения имени кошелька | D14: DIS & DEV | E14: 6 | F14: 8 | G14: =E14*$C$3 -> 270 | H14: =F14*$C$3 -> 360
A15: 2.3.7 | B15: Страница транзакций - Выбор типа транзакций - Фильтры для выбранного типа транзакций - Таблица транзакций для выбранного типа | D15: DIS & DEV | E15: 6 | F15: 8 | G15: =E15*$C$3 -> 270 | H15: =F15*$C$3 -> 360
A16: 2.3.8 | B16: Страница реферальной программы - Отображение статуса и текущего оборота - Список приглашенных Пользователей - Отображение ссылки для приглашения | D16: DIS & DEV | E16: 2 | F16: 4 | G16: =E16*$C$3 -> 90 | H16: =F16*$C$3 -> 180
A17: 2.4 | B17: ПАНЕЛЬ АДМИНИСТРАТОРА
A18: 2.4.1 | B18: Аутентификация администратора. Дизайн макета - Возможность входа на платформу для администраторов | D18: DIS & DEV | E18: 2 | F18: 4 | G18: =E18*$C$3 -> 90 | H18: =F18*$C$3 -> 180
A19: 2.4.2 | B19: Управление администраторами. Дизайн макета - Список администраторов. - Интерфейс добавления нового администратора. - Просмотр логов действий администраторов. - Блокировка/разблокировка администратора. | D19: DIS & DEV | E19: 12 | F19: 16 | G19: =E19*$C$3 -> 540 | H19: =F19*$C$3 -> 720
A20: 2.4.3 | B20: Управление пользователями. Дизайн макета - Список пользователей - Общая информация об активности пользователей - Блокировка/разблокировка пользователей - Блокировка/разблокировка различных действий для пользователей | D20: DIS & DEV | E20: 12 | F20: 16 | G20: =E20*$C$3 -> 540 | H20: =F20*$C$3 -> 720
A21: 2.4.4 | B21: Управление платформой. Дизайн макета - Настройка комиссий - Управление пополнением/выводом средств | D21: DIS & DEV | E21: 12 | F21: 16 | G21: =E21*$C$3 -> 540 | H21: =F21*$C$3 -> 720
A22: 2.4.5 | B22: Управление криптовалютным шлюзом. Дизайн макета - Управление транзакциями (мониторинг, подтверждение) - Создание и кастомизация кошельков | D22: DIS & DEV | E22: 12 | F22: 16 | G22: =E22*$C$3 -> 540 | H22: =F22*$C$3 -> 720
A23: 2.5 | B23: Разработка дизайн-системы - Разработка UI-кита - Подготовка цветовой палитры - Подбор и настройка шрифтов | D23: DIS & DEV | E23: 16 | F23: 20 | G23: =E23*$C$3 -> 720 | H23: =F23*$C$3 -> 900
A24: 2.6 | B24: Адаптивный дизайн - Настройки для различных разрешений горизонтальных экранов - Регулировки для различных разрешений вертикальных экранов - Разработка принципа переходов | D24: DEVELOPMENT | E24: 22 | F24: 28 | G24: =E24*$C$3 -> 990 | H24: =F24*$C$3 -> 1260
A25: 2.7 | B25: Ревью дизайна - Ревью мудбордов - Ревью UI-кита - Изучение дизайна на наличие ошибок и несоответствий UX-стандартам | D25: DIS & DEV | E25: 16 | F25: 20 | G25: =E25*$C$3 -> 720 | H25: =F25*$C$3 -> 900

Sheet Фронтенд
A1: ='Общая смета'!B1 -> ПРЕДВАРИТЕЛЬНАЯ ОЦЕНКА ТРУДОЗАТРАТ НА АГРЕГАТОР DEX В ТЕЛЕГРАМЕ
A2: # | B2: СПИСОК ЗАДАЧ | C2: Рейт ($/Ч) | D2: Фаза | E2: О. Часы | F2: П. Часы | G2: О. Цена | H2: П. Цена
A3: 3 | B3: Фронтенд-разработка | C3: 50 | E3: =SUM(E4:E30) -> 740 | F3: =SUM(F4:F30) -> 884 | G3: =SUM(G4:G30) -> 37000 | H3: =SUM(H4:H30) -> 44200
A4: 3.1 | B4: Первичная консультация команды - Консультации команды дизайна - Обзор начальных спецификаций по проекту | D4: DISCOVERY | E4: 4 | F4: 6 | G4: =E4*$C$3 -> 200 | H4: =F4*$C$3 -> 300
A5: 3.2 | B5: Инициализация проекта - Выбор наиболее подходящих библиотек и фреймворков - Инициализация директории проекта | D5: DEVELOPMENT | E5: 8 | F5: 10 | G5: =E5*$C$3 -> 400 | H5: =F5*$C$3 -> 500
A6: 3.3 | B6: Разработка базовых компонентов - Разработка компонентов на основе дизайна Figma - Базовые компоненты включают кнопки, входы, дропдауны и другие многоразовые компоненты будущего приложения. - Инициализация хедера и футера | D6: DEVELOPMENT | E6: 88 | F6: 104 | G6: =E6*$C$3 -> 4400 | H6: =F6*$C$3 -> 5200
A7: 3.4 | B7: Разработка модальных окон, алертов и нотификаций - Шаблоны кода модальных окон и разработка базового функционала. - Шаблоны кода алертов и разработка базового функционала. - Шаблоны кода уведомлений и разработка базового функционала. | D7: DEVELOPMENT | E7: 32 | F7: 40 | G7: =E7*$C$3 -> 1600 | H7: =F7*$C$3 -> 2000
A8: 3.5 | B8: Адаптивный дизайн - Поддержка горизонтальных разрешений на основе Figma (1025px+ для персонального компьютера) - Поддержка вертикальных разрешений на основе Figma (от 320px до 767px для мобильных устройств и от 768px до 1024px планшетов) | D8: DEVELOPMENT | E8: 32 | F8: 40 | G8: =E8*$C$3 -> 1600 | H8: =F8*$C$3 -> 2000
A9: 3.6 | B9: Разработка архитектуры интеграций - Обзор документации API. - Обзор функциональности смарт-контрактов. - Проверка параметров WebSocket. - Настройки axios / других инструментов. | D9: DEVELOPMENT | E9: 80 | F9: 96 | G9: =E9*$C$3 -> 4000 | H9: =F9*$C$3 -> 4800
A10: 3.7 | B10: ОБЩИЕ СТРАНИЦЫ
A11: 3.7.1 | B11: Домашняя страница. Верстка и интеграция. - Общая и регуляторная информация - Меню - Помощь и FAQ - Переход к подключению web3-кошелька | D11: DEVELOPMENT | E11: 32 | F11: 40 | G11: =E11*$C$3 -> 1600 | H11: =F11*$C$3 -> 2000
A12: 3.7.2 | B12: Страница с антибот-верификацией. Верстка и интеграция. - Интерфейс защиты от ботов | D12: DEVELOPMENT | E12: 6 | F12: 8 | G12: =E12*$C$3 -> 300 | H12: =F12*$C$3 -> 400
A13: 3.8 | B13: ПЛАТФОРМА
A14: 3.8.1 | B14: Профиль пользователя. Верстка и интеграция. - Настройка личного кабинета и персональной информации | D14: DEVELOPMENT | E14: 32 | F14: 40 | G14: =E14*$C$3 -> 1600 | H14: =F14*$C$3 -> 2000
A15: 3.8.2 | B15: Страница подключения Web3-кошелька - Форма подключения web3 кошелька - Переход к подключению web3 кошелька - Переход к авторизации | D15: DEVELOPMENT | E15: 16 | F15: 24 | G15: =E15*$C$3 -> 800 | H15: =F15*$C$3 -> 1200
A16: 3.8.3 | B16: Страница трейдинга. Верстка и интеграция. - Выбор сетей (TON, SOL) - Отображение кошельков платформы - Выбор ордера (3 вида - рыночный ордер, лимитный ордер, стоп-ордер) - Таблица продаж/покупок (транзакции, ордера, мои активы, топ-200 держателей выбранного токена) - Информация по торговой паре - Блок покупки/продажи ордеров | D16: DEVELOPMENT | E16: 72 | F16: 88 | G16: =E16*$C$3 -> 3600 | H16: =F16*$C$3 -> 4400
A17: 3.8.4 | B17: Модальное окно вывода средств. Верстка и интеграция. - Выбор кошелька, валюты - Ввод адреса кошелька - Согласие с включением газа в сумму перевода | D17: DEVELOPMENT | E17: 16 | F17: 20 | G17: =E17*$C$3 -> 800 | H17: =F17*$C$3 -> 1000
A18: 3.8.5 | B18: Модальное окно пополнения средств. Верстка и интеграция. - Выбор кошелька - QR-код | D18: DEVELOPMENT | E18: 12 | F18: 16 | G18: =E18*$C$3 -> 600 | H18: =F18*$C$3 -> 800
A19: 3.8.6 | B19: Страница "Мои кошельки", подключение библиотеки web3-кошельков. Верстка и интеграция - Таблица кошельков - Переход к выбору кошельков - Переход к настройке пресета кошельков - Таблица активов в кошельке - Переход к импорту, генерации изменения имени кошелька | D19: DEVELOPMENT | E19: 28 | F19: 32 | G19: =E19*$C$3 -> 1400 | H19: =F19*$C$3 -> 1600
A20: 3.8.7 | B20: Страница транзакций - Выбор типа транзакций - Фильтры для выбранного типа транзакций - Таблица транзакций для выбранного типа | D20: DEVELOPMENT | E20: 32 | F20: 36 | G20: =E20*$C$3 -> 1600 | H20: =F20*$C$3 -> 1800
A21: 3.8.8 | B21: Страница реферальной программы - Отображение статуса и текущего оборота - Список приглашенных Пользователей - Отображение ссылки для приглашения | D21: DEVELOPMENT | E21: 16 | F21: 20 | G21: =E21*$C$3 -> 800 | H21: =F21*$C$3 -> 1000
A22: 3.9 | B22: ПАНЕЛЬ АДМИНИСТРАТОРА
A23: 3.9.1 | B23: Аутентификация администратора. Верстка и интеграция. - Возможность входа на платформу для администраторов | D23: DEVELOPMENT | E23: 12 | F23: 16 | G23: =E23*$C$3 -> 600 | H23: =F23*$C$3 -> 800
A24: 3.9.2 | B24: Управление администраторами. Верстка и интеграция. - Список администраторов. - Интерфейс добавления нового администратора. - Просмотр логов действий администраторов. - Блокировка/разблокировка администратора. | D24: DEVELOPMENT | E24: 36 | F24: 40 | G24: =E24*$C$3 -> 1800 | H24: =F24*$C$3 -> 2000
A25: 3.9.3 | B25: Управление пользователями. Верстка и интеграция. - Список пользователей - Общая информация об активности пользователей - Блокировка/разблокировка пользователей - Блокировка/разблокировка различных действий для пользователей | D25: DEVELOPMENT | E25: 36 | F25: 40 | G25: =E25*$C$3 -> 1800 | H25: =F25*$C$3 -> 2000
A26: 3.9.4 | B26: Управление платформой. Верстка и интеграция. - Настройка комиссий - Управление пополнением/выводом средств | D26: DEVELOPMENT | E26: 20 | F26: 24 | G26: =E26*$C$3 -> 1000 | H26: =F26*$C$3 -> 1200
A27: 3.9.5 | B27: Управление криптовалютным шлюзом. Верстка и интеграция. - Управление транзакциями (мониторинг, подтверждение) - Создание и кастомизация кошельков | D27: DEVELOPMENT | E27: 28 | F27: 32 | G27: =E27*$C$3 -> 1400 | H27: =F27*$C$3 -> 1600
A28: 3.10 | B28: Интернационализация/локализация - Поддержка английского/русского языков | D28: DEVELOPMENT | E28: 6 | F28: 8 | G28: =E28*$C$3 -> 300 | H28: =F28*$C$3 -> 400
A29: 3.11 | B29: Консультация технического лида - Обзор логики в технической реализации - Проверка кода на предмет чистоты кода. - Просмотр текста коммитов согласно утвержденному формату - Написание комментариев и отзывов по PR - Консультирование команды по техническим вопросам. - Звонки заказчику для уточнения требований и обсуждения технической реализации | D29: DEV & DEL | E29: 96 | F29: 104 | G29: =E29*$C$3 -> 4800 | H29: =F29*$C$3 -> 5200
D30: DEV & DEL

Sheet Бэкенд
A1: ='Общая смета'!B1 -> ПРЕДВАРИТЕЛЬНАЯ ОЦЕНКА ТРУДОЗАТРАТ НА АГРЕГАТОР DEX В ТЕЛЕГРАМЕ
A2: # | B2: СПИСОК ЗАДАЧ | C2: Рейт ($/Ч) | D2: Фаза | E2: О. Часы | F2: П. Часы | G2: О. Цена | H2: П. Цена
A3: 4 | B3: Бэкенд-разработка | C3: 55 | E3: =SUM(E4:E24) -> 981 | F3: =SUM(F4:F24) -> 1320 | G3: =SUM(G4:G24) -> 53955 | H3: =SUM(H4:H24) -> 72600
A4: 4.1 | B4: Дизайн архитектуры бэкенда - Разработка архитектурных схем приложений и сервисов. - Разработка схем баз данных и связей между данными. - Обзор способов интеграции со сторонними сервисами - Выбор технологического стека и инструментов для реализации приложения - Разработка схемы безопасного масштабирования системы. | D4: DISCOVERY | E4: 10 | F4: 16 | G4: =E4*$C$3 -> 550 | H4: =F4*$C$3 -> 880
A5: 4.2 | B5: Разработка архитектуры бэкенда - Разработка структуры каталогов проекта. - Настройка линтеров и конфигурационных файлов. - Настройка конфигурации менеджера пакетов и реализация сторонних зависимостей. - Настройка хуков коммитов | D5: DEVELOPMENT | E5: 10 | F5: 16 | G5: =E5*$C$3 -> 550 | H5: =F5*$C$3 -> 880
A6: 4.3 | B6: Модуль Web3-авторизации - Импорт кошелька - Выгрузка приватных ключей пользователя по кошельку - Подпись через кошелек стандарта EIP-712(WEB3 Аутентификация пользователя) - Управление сессиями - Создание и управление аккаунтом пользователя - Создание платежных паролей/пинкодов | D6: DEVELOPMENT | E6: 42 | F6: 52 | G6: =E6*$C$3 -> 2310 | H6: =F6*$C$3 -> 2860
A7: 4.4 | B7: Модуль реферальной программы - Разработка логики ступенчато-обрезной стратегии для распределения награды за участие - Проектирование логики обновления данных по распределению награды и передачи информации смарт-контракту - Расчет оборота всей/1-линии структуры - Расчет уровня пользователя | D7: DEVELOPMENT | E7: 40 | F7: 48 | G7: =E7*$C$3 -> 2200 | H7: =F7*$C$3 -> 2640
A8: 4.5 | B8: Модуль Jupiter/STON.fi - Интеграция со смарт-контрактами Jupiter/STON.fi (через прокси-контракты) - Проектирование и разработка логики выявления новых листингов и передачи информации системе - Парсинг транзакций смарт-контракта на вывод/пополнение ликвидности из пула - Парсинг транзакций смарт-контракта на продажу токена платформы - Получение списка токенов | D8: DEVELOPMENT | E8: 60 | F8: 80 | G8: =E8*$C$3 -> 3300 | H8: =F8*$C$3 -> 4400
A9: 4.6 | B9: Модуль blockchain - Проектирование и разработка логики работы с mempool - Разработка логики переподключения провайдера | D9: DEVELOPMENT | E9: 32 | F9: 40 | G9: =E9*$C$3 -> 1760 | H9: =F9*$C$3 -> 2200
A10: 4.7 | B10: Модуль Anti Frontrun - Ресерч закрытых пулов - Интеграция с закрытыми пулами | D10: DEVELOPMENT | E10: 60 | F10: 80 | G10: =E10*$C$3 -> 3300 | H10: =F10*$C$3 -> 4400
A11: 4.8 | B11: Модуль Anti-Blacklist - Парсинг транзакций на добавление кошелька в черный список и перевод средств на резервный кошелек | D11: DEVELOPMENT | E11: 60 | F11: 70 | G11: =E11*$C$3 -> 3300 | H11: =F11*$C$3 -> 3850
A12: 4.9 | B12: Модуль Tokens info сервис - Интеграция с сервисом CoinMarketCap/DexTools для получения информации о токене/паре | D12: DEVELOPMENT | E12: 32 | F12: 40 | G12: =E12*$C$3 -> 1760 | H12: =F12*$C$3 -> 2200
A13: 4.10 | B13: Модуль Auto router - Логика нахождения путей покупки токенов | D13: DEVELOPMENT | E13: 70 | F13: 90 | G13: =E13*$C$3 -> 3850 | H13: =F13*$C$3 -> 4950
A14: 4.11 | B14: Модуль Orders - Проектирование и разработка логики работы market/limit ордеров - Страница транзакций - Страница ордеров - Страница My-holdings + обновление позиций - Функция share позиции - Фильтрации, сортировки | D14: DEVELOPMENT | E14: 100 | F14: 120 | G14: =E14*$C$3 -> 5500 | H14: =F14*$C$3 -> 6600
A15: 4.12 | B15: Модуль Notification - Разработка логики создание типов нотификации - Разработка Server-sent-event(SSE) для отправки нотификаций - Разработка логики управление нотификациями | D15: DEVELOPMENT | E15: 60 | F15: 80 | G15: =E15*$C$3 -> 3300 | H15: =F15*$C$3 -> 4400
... A23: 4.20 | B23: Разработка документации - Комментирование кода. - Разработка README-файла с инструкциями по настройке и запуску проекта, а также его архитектурой. - Схемы архитектуры сервисов/баз данных | D23: DEV & DEL | E23: 12 | F23: 16 | G23: =E23*$C$3 -> 660 | H23: =F23*$C$3 -> 880

Sheet Смарт контракты
A1: ='Общая смета'!B1 -> ПРЕДВАРИТЕЛЬНАЯ ОЦЕНКА ТРУДОЗАТРАТ НА АГРЕГАТОР DEX В ТЕЛЕГРАМЕ
A2: # | B2: СПИСОК ЗАДАЧ | C2: Рейт ($/Ч) | D2: Фаза | E2: О. Часы | F2: П. Часы | G2: О. Цена | H2: П. Цена
B3: Смарт контракты | C3: 55 | E3: =SUM(E4:E9) -> 206 | F3: =SUM(F4:F9) -> 280 | G3: =SUM(G4:G9) -> 11330 | H3: =SUM(H4:H9) -> 15400
B4: Проектирование архитектуры смарт-контрактов - Обзор технических характеристик продукта - Общий обзор проекта - Определение основных переменных/функций/эвентов - Идентификация рисков | D4: DIS & DEV | E4: 8 | F4: 12 | G4: =E4*$C$3 -> 440 | H4: =F4*$C$3 -> 660
B5: Router Smart Contract - Разработка логики взимания комиссии с Пользователей - Интеграция c STON.fi и Jupiter для проведения обменов | D5: DEVELOPMENT | E5: 160 | F5: 220 | G5: =E5*$C$3 -> 8800 | H5: =F5*$C$3 -> 12100
B6: Тестирование - Реализация Юнит-тестов потенциально уязвимой логики - Реализация e2e-тестирования для описания положительных и отрицательных случаев при работе с клиентом. - Подготовка и описание сценариев тестирования кода. | D6: DEV & DEL | E6: 12 | F6: 16 | G6: =E6*$C$3 -> 660 | H6: =F6*$C$3 -> 880
B7: Консультации Техлида - Обзор логики в технической реализации - Проверьте код на предмет чистоты кода. - Помощь в разработке микроархитектуры отдельной функции - Консультирование команды по техническим вопросам. - Звонки заказчику для уточнения требований и обсуждения технической реализации | D7: DEV & DEL | E7: 20 | F7: 24 | G7: =E7*$C$3 -> 1100 | H7: =F7*$C$3 -> 1320
B8: Разработка документации - Комментирование кода - Разработка README-файла | D8: DEV & DEL | E8: 6 | F8: 8 | G8: =E8*$C$3 -> 330 | H8: =F8*$C$3 -> 440

Sheet DevOps
A1: ='Общая смета'!B1 -> ПРЕДВАРИТЕЛЬНАЯ ОЦЕНКА ТРУДОЗАТРАТ НА АГРЕГАТОР DEX В ТЕЛЕГРАМЕ
A2: # | B2: СПИСОК ЗАДАЧ | C2: Рейт ($/Ч) | D2: Фаза | E2: О. Часы | F2: П. Часы | G2: О. Цена | H2: П. Цена
B3: DevOps | C3: 45 | E3: =SUM(E4:E9) -> 102 | F3: =SUM(F4:F9) -> 132 | G3: =SUM(G4:G9) -> 4590 | H3: =SUM(H4:H9) -> 5940
B4: Настройка инфраструктуры - Настройка репозитория - Настройка секретов репозитория - Настройка инструментов/библиотек/фреймворков - Настройки сети - Настройка безопасности сервера - Настройка резервного копирования баз данных | D4: DEVELOPMENT | E4: 16 | F4: 20 | G4: =E4*$C$3 -> 720 | H4: =F4*$C$3 -> 900
B5: Мониторинг - Настройка систем мониторинга - Конфигурация систем мониторинга - Настройка бота уведомлений - Настройка систем логгинга - Трассировка логов | D5: DEVELOPMENT | E5: 32 | F5: 40 | G5: =E5*$C$3 -> 1440 | H5: =F5*$C$3 -> 1800
B6: Настройка CI/CD - Инициализация инструментов CI/CD - Разработка CI/CD-скриптов - Инфраструктура сервисов CI/CD | D6: DEVELOPMENT | E6: 32 | F6: 40 | G6: =E6*$C$3 -> 1440 | H6: =F6*$C$3 -> 1800
B7: Настройка узла блокчейна | D7: DEVELOPMENT | E7: 16 | F7: 24 | G7: =E7*$C$3 -> 720 | H7: =F7*$C$3 -> 1080
B8: Разработка документации по развертыванию - Инфраструктурная документация - Документация CI/CD - Документация по мониторингу | D8: DELIVERY | E8: 6 | F8: 8 | G8: =E8*$C$3 -> 270 | H8: =F8*$C$3 -> 360

Sheet QA
A1: ='Общая смета'!B1 -> ПРЕДВАРИТЕЛЬНАЯ ОЦЕНКА ТРУДОЗАТРАТ НА АГРЕГАТОР DEX В ТЕЛЕГРАМЕ
A2: # | B2: СПИСОК ЗАДАЧ | C2: Рейт ($/Ч) | D2: Фаза | E2: О. Часы | F2: П. Часы | G2: О. Цена | H2: П. Цена
B3: Контроль качества (QA) | C3: 45 | E3: =SUM(E4:E9) -> 722 | F3: =SUM(F4:F9) -> 876 | G3: =SUM(G4:G9) -> 32490 | H3: =SUM(H4:H9) -> 39420
B4: Анализ требований и планирование тестирования - Статическое тестирование требований - Обзор требований - Обзор дорожной карты проекта - Обзор проектной документации - Разработка плана тестирования - Распределение ресурсов | D4: DISCOVERY | E4: 54 | F4: 66 | G4: =E4*$C$3 -> 2430 | H4: =F4*$C$3 -> 2970
B5: Дизайн тест-кейсов - Разработка детальных тестовых кейсов - Тестовые сценарии высокого уровня | D5: DIS & DEV | E5: 68 | F5: 76 | G5: =E5*$C$3 -> 3060 | H5: =F5*$C$3 -> 3420
B6: Менеджмент дефектов и отчетность - Локализация ошибок - Описание ошибок - Обновления статуса ошибок | D6: DEV & DEL | E6: 96 | F6: 134 | G6: =E6*$C$3 -> 4320 | H6: =F6*$C$3 -> 6030
B7: Функциональное и нефункциональное тестирование - Тестирование API - UI-тестирование - UX-тестирование - Регресионное тестирование - Приемочное, повторное и smoke-тестирование | D7: DEV & DEL | E7: 480 | F7: 560 | G7: =E7*$C$3 -> 21600 | H7: =F7*$C$3 -> 25200
B8: Консультации по вопросам тестирования - Консультирование группы тестирования. - Анализ тестовой документации и проведенных испытаний. - Переоценка (при необходимости) | D8: DEV & DEL | E8: 24 | F8: 40 | G8: =E8*$C$3 -> 1080 | H8: =F8*$C$3 -> 1800

Sheet Менеджмент
A1: ='Общая смета'!B1 -> ПРЕДВАРИТЕЛЬНАЯ ОЦЕНКА ТРУДОЗАТРАТ НА АГРЕГАТОР DEX В ТЕЛЕГРАМЕ
A2: # | B2: СПИСОК ЗАДАЧ | C2: Рейт ($/Ч) | D2: Фаза | E2: О. Часы | F2: П. Часы | G2: О. Цена | H2: П. Цена
B3: Менеджмент | C3: 45 | E3: =SUM(E4:E10) -> 374 | F3: =SUM(F4:F10) -> 420 | G3: =SUM(G4:G10) -> 16830 | H3: =SUM(H4:H10) -> 18900
B4: Планирование и проведение Kick-off: - Внутреннее планирование kick-off с командой; - Планирование рабочего процесса на первом этапе; - kick-off встреча с клиентом. | D4: DISCOVERY | E4: 4 | F4: 8 | G4: =E4*$C$3 -> 180 | H4: =F4*$C$3 -> 360
B5: Корректировка задач, распределение и контроль: - Актуализация задач для команды; - Назначение исполнителей;; - Актуализация задач и ежедневный контроль. | D5: SPREAD | E5: 144 | F5: 152 | G5: =E5*$C$3 -> 6480 | H5: =F5*$C$3 -> 6840
B6: Управление спринтом: - Планирование спринта; - Ежедневные стендапы; - Уход за отставанием; - Демонстрация промежуточного результата (Демо); - Ретроспектива. | D6: DIS & DEV | E6: 144 | F6: 152 | G6: =E6*$C$3 -> 6480 | H6: =F6*$C$3 -> 6840
B7: Подготовка и обмен отчетами: - Формирование отчетов для клиентов; - Передача отчета и обсуждение. | D7: SPREAD | E7: 24 | F7: 32 | G7: =E7*$C$3 -> 1080 | H7: =F7*$C$3 -> 1440
B8: Общение с клиентом: - Сотрудничество с клиентом во время звонков для обмена обновлениями и обсуждения планов. - Ежедневное общение с клиентами по электронной почте/чатам. | D8: SPREAD | E8: 40 | F8: 52 | G8: =E8*$C$3 -> 1800 | H8: =F8*$C$3 -> 2340
B9: Завершение и передача проекта: - Подготовка документов к сдаче; - предоставление результатов разработки; - Контроль доступа к среде Prod; - Закрытие юридических вопросов. | D9: DELIVERY | E9: 18 | F9: 24 | G9: =E9*$C$3 -> 810 | H9: =F9*$C$3 -> 1080

Sheet #
A1: O. Часы | B1: П. Часы | C1: O. Цена | D1: П. Цена | E1: O. Часы | F1: П. Часы | G1: O. Цена | H1: П. Цена | I1: O. Часы | J1: П. Часы | K1: O. Цена | L1: П. Цена
